Workbook

Sheet JELineItems
A1: JENumber | B1: GLAccountNumber | C1: BusinessUnitID | D1: PreparerID | E1: SourceID | F1: EffectiveDate | G1: JEDescription | H1: Debit | I1: Credit | J1: Amount
A2: 2033520 | B2: 76930 | C2: 1 | D2: 101 | E2: 1002 | F2: 44002 | G2: TELECOM GTA JUN 2016 | H2: 36.9 | J2: 36.9
A3: 2033520 | B3: 11845 | C3: 1 | D3: 101 | E3: 1002 | F3: 44002 | G3: TELECOM GTA JUN 2016 | I3: -36.9 | J3: -36.9
A4: 2033521 | B4: 11845 | C4: 3 | D4: 102 | E4: 1001 | F4: 44002 | G4: CASH RECEIPTS | H4: 63.1 | J4: 63.1
A5: 2033521 | B5: 43440 | C5: 3 | D5: 102 | E5: 1001 | F5: 44002 | G5: CASH RECEIPTS | I5: -63.1 | J5: -63.1
A6: 2033522 | B6: 11845 | C6: 1 | D6: 102 | E6: 1003 | F6: 44002 | G6: CREDIT CARD RECEIPTS | H6: 68.28 | J6: 68.28
A7: 2033522 | B7: 43310 | C7: 1 | D7: 102 | E7: 1003 | F7: 44002 | G7: CREDIT CARD RECEIPTS | I7: -68.28 | J7: -68.28
A8: 2033523 | B8: 11845 | C8: 2 | D8: 106 | E8: 1003 | F8: 44002 | G8: CONFERENCE - HOTEL | H8: 99 | J8: 99
A9: 2033523 | B9: 43180 | C9: 2 | D9: 106 | E9: 1003 | F9: 44002 | G9: CONFERENCE - HOTEL | I9: -99 | J9: -99
A10: 2033524 | B10: 11845 | C10: 3 | D10: 102 | E10: 1003 | F10: 44002 | G10: CREDIT CARD RECEIPTS | H10: 107.21 | J10: 107.21
A11: 2033524 | B11: 43440 | C11: 3 | D11: 102 | E11: 1003 | F11: 44002 | G11: CREDIT CARD RECEIPTS | I11: -107.21 | J11: -107.21
A12: 2033525 | B12: 11845 | C12: 2 | D12: 104 | E12: 1003 | F12: 44002 | G12: HENDERSON,KENNY | H12: 129 | J12: 129
A13: 2033525 | B13: 43180 | C13: 2 | D13: 104 | E13: 1003 | F13: 44002 | G13: HENDERSON,KENNY | I13: -129 | J13: -129
A14: 2033526 | B14: 11845 | C14: 2 | D14: 104 | E14: 1003 | F14: 44002 | G14: GENTRY,NIA | H14: 258 | J14: 258
A15: 2033526 | B15: 43180 | C15: 2 | D15: 104 | E15: 1003 | F15: 44002 | G15: GENTRY,NIA | I15: -258 | J15: -258
A16: 2033527 | B16: 11845 | C16: 2 | D16: 104 | E16: 1003 | F16: 44002 | G16: HODGES,CHAYA | H16: 418 | J16: 418
A17: 2033527 | B17: 43180 | C17: 2 | D17: 104 | E17: 1003 | F17: 44002 | G17: HODGES,CHAYA | I17: -418 | J17: -418
A18: 2033528 | B18: 71900 | C18: 1 | D18: 102 | E18: 1002 | F18: 44002 | G18: ALSCO INC | H18: 431.8 | J18: 431.8
A19: 2033528 | B19: 11845 | C19: 1 | D19: 102 | E19: 1002 | F19: 44002 | G19: ALSCO INC | I19: -431.8 | J19: -431.8
A20: 2033529 | B20: 11845 | C20: 1 | D20: 102 | E20: 1001 | F20: 44002 | G20: CASH RECEIPTS | H20: 612.54 | J20: 612.54
A21: 2033529 | B21: 43310 | C21: 1 | D21: 102 | E21: 1001 | F21: 44002 | G21: CASH RECEIPTS | I21: -612.54 | J21: -612.54
A22: 2033530 | B22: 76930 | C22: 2 | D22: 101 | E22: 1002 | F22: 44002 | G22: TELECOM GTA JUN 2016 | H22: 1015.21 | J22: 1015.21
A23: 2033530 | B23: 11845 | C23: 2 | D23: 101 | E23: 1002 | F23: 44002 | G23: TELECOM GTA JUN 2016 | I23: -1015.21 | J23: -1015.21
A24: 2033531 | B24: 11845 | C24: 1 | D24: 102 | E24: 1003 | F24: 44002 | G24: CREDIT CARD RECEIPTS | H24: 2157.22 | J24: 2157.22
A25: 2033531 | B25: 43310 | C25: 1 | D25: 102 | E25: 1003 | F25: 44002 | G25: CREDIT CARD RECEIPTS | I25: -2157.22 | J25: -2157.22
A26: 2033532 | B26: 11845 | C26: 1 | D26: 106 | E26: 1003 | F26: 44002 | G26: CONFERENCE - FOOD SERVICE | H26: 4503.3 | J26: 4503.3
A27: 2033532 | B27: 43310 | C27: 1 | D27: 106 | E27: 1003 | F27: 44002 | G27: CONFERENCE - FOOD SERVICE | I27: -4503.3 | J27: -4503.3
A28: 2033533 | B28: 11845 | C28: 2 | D28: 104 | E28: 1003 | F28: 44002 | G28: CREDIT CARD RECEIPTS | H28: 6197 | J28: 6197
A29: 2033533 | B29: 43180 | C29: 2 | D29: 104 | E29: 1003 | F29: 44002 | G29: CREDIT CARD RECEIPTS | I29: -6197 | J29: -6197
A30: 2033534 | B30: 71400 | C30: 2 | D30: 101 | E30: 1002 | F30: 44002 | G30: PARKING SERVICES OF AMERICA | H30: 26770 | J30: 26770
A31: 2033534 | B31: 11845 | C31: 2 | D31: 101 | E31: 1002 | F31: 44002 | G31: PARKING SERVICES OF AMERICA | I31: -26770 | J31: -26770
A32: 2033535 | B32: 11845 | C32: 3 | D32: 102 | E32: 1001 | F32: 44003 | G32: CASH RECEIPTS | H32: 38.29 | J32: 38.29
A33: 2033535 | B33: 43440 | C33: 3 | D33: 102 | E33: 1001 | F33: 44003 | G33: CASH RECEIPTS | I33: -38.29 | J33: -38.29
A34: 2033536 | B34: 11845 | C34: 3 | D34: 102 | E34: 1003 | F34: 44003 | G34: CREDIT CARD RECEIPTS | H34: 47.96 | J34: 47.96
A35: 2033536 | B35: 43440 | C35: 3 | D35: 102 | E35: 1003 | F35: 44003 | G35: CREDIT CARD RECEIPTS | I35: -47.96 | J35: -47.96
A36: 2033537 | B36: 14250 | C36: 3 | D36: 102 | E36: 1002 | F36: 44003 | G36: TROPICAL NUT & FRUIT | H36: 197.08 | J36: 197.08
A37: 2033537 | B37: 11845 | C37: 3 | D37: 102 | E37: 1002 | F37: 44003 | G37: TROPICAL NUT & FRUIT | I37: -197.08 | J37: -197.08
A38: 2033538 | B38: 72760 | C38: 6 | D38: 101 | E38: 1002 | F38: 44003 | G38: DYNAMIC SECU64605456 | H38: 236.32 | J38: 236.32
A39: 2033538 | B39: 11845 | C39: 6 | D39: 101 | E39: 1002 | F39: 44003 | G39: DYNAMIC SECU64605456 | I39: -236.32 | J39: -236.32
A40: 2033539 | B40: 72760 | C40: 6 | D40: 101 | E40: 1002 | F40: 44003 | G40: DYNAMIC SECU64605456 | H40: 236.32 | J40: 236.32
...

Sheet BusinessUnits
A1: BusinessUnitID | B1: BusinessUnit | C1: Description
A2: 1 | B2: FOOD SERVICE | C2: Transactions related to food and beverage service. Includes all guest transactions in the hotel restaurants, catering-related transactions and food service payroll.
A3: 2 | B3: HOTEL | C3: Transactions related to guest rooms and overall hotel operations. Includes payroll for administrative staff, clerks and interns.
A4: 3 | B4: HOTEL PANTRY | C4: Transactions related to the hotel convenience store, including some food and beverage costs.
A5: 4 | B5: HOUSEKEEPING | C5: Transactions related to the Housekeeping Department. Primarily includes payroll for housekeepers and housekeeping supplies.
A6: 5 | B6: INTEREST | C6: Interest from the cash operations account.
A7: 6 | B7: MAINTENANCE | C7: Transactions related to the hotel Maintenance Department. Primarily includes payroll for maintenance, grounds keepers and related supplies.
A8: 7 | B8: OPER - GENERAL | C8: Transactions related to corporate accounting functions, e.g., monthly depreciation entries.
A9: 8 | B9: PAYROLL S/B JV | C9: Transactions related to payroll for employees.

Sheet ChartOfAccounts
A1: GLAccountNumber | B1: GLAccountName | C1: GLAccountNumber | D1: AccountType | E1: GLAccountNumber | F1: AccountClass
A2: 11200 | B2: Petty Cash | C2: 11200 | D2: Assets | E2: 11200 | F2: Cash
A3: 11845 | B3: Operating Bank Account | C3: 11845 | D3: Assets | E3: 11845 | F3: Cash
A4: 12987 | B4: Food Service Conference Accounts Receivable | C4: 12987 | D4: Assets | E4: 12987 | F4: Accounts Receivable
A5: 13100 | B5: Prepaid Expenses | C5: 13100 | D5: Assets | E5: 13100 | F5: Prepaid Expenses
A6: 14250 | B6: Hotel Pantry Inventory | C6: 14250 | D6: Assets | E6: 14250 | F6: Inventory
A7: 14260 | B7: Food Service Inventory | C7: 14260 | D7: Assets | E7: 14260 | F7: Inventory
A8: 15100 | B8: Short-term Investments | C8: 15100 | D8: Assets | E8: 15100 | F8: Other ST Assets
A9: 16100 | B9: Land and Improvements | C9: 16100 | D9: Assets | E9: 16100 | F9: Plant, Property and Equipment
A10: 16200 | B10: Buildings & Building Improvements | C10: 16200 | D10: Assets | E10: 16200 | F10: Plant, Property and Equipment
A11: 16290 | B11: Accumulated Depreciation - Building & Improvements | C11: 16290 | D11: Assets | E11: 16290 | F11: Plant, Property and Equipment
A12: 16500 | B12: Equipment | C12: 16500 | D12: Assets | E12: 16500 | F12: Plant, Property and Equipment
A13: 16590 | B13: Accumulated Depreciation - Equipment | C13: 16590 | D13: Assets | E13: 16590 | F13: Plant, Property and Equipment
... A84: 86200 | B84: Depreciation Expense - Equipment | C84: 86200 | D84: Expenses | E84: 86200 | F84: Depreciation Expense
A85: 70300-FS | B85: Cost of Goods Sold | C85: 70300-FS | D85: Expenses | E85: 70300-FS | F85: COGS-Food
A86: 70300-HP | B86: Cost of Goods Sold | C86: 70300-HP | D86: Expenses | E86: 70300-HP | F86: COGS-Hotel Pantry

Sheet PreparerInfo
A1: PreparerID | B1: PreparerName | C1: BusinessUnitID
A2: 101 | B2: Carolyn Slater|Food Operations Manager | C2: 1
A3: 101 | B3: Alexander Knox|Assistant Manager | C3: 2
A4: 101 | B4: Gavin McGrath|Dining Commons Manager | C4: 3
A5: 101 | B5: Trevor Roberts|Housekeeping Supervisor | C5: 4
A6: 101 | B6: Rodney Wilkins|Maintenance Supervisor | C6: 6
A7: 102 | B7: Elizabeth Rees|Food Operations Manager | C7: 1
A8: 102 | B8: Brian Gibson|Assistant Manager | C8: 2
A9: 102 | B9: POS | C9: 3
A10: 103 | B10: David Brown|Accounting Manager | C10: 2
A11: 104 | B11: GUESTSYS | C11: 2
A12: 105 | B12: Victoria Simpson|Accounting Manager | C12: 2
A13: 106 | B13: Yvonne Chapman|Catering Manager | C13: 2

Sheet Source
A1: SourceID | B1: Source
A2: 1001 | B2: CASH RECEIPT
A3: 1002 | B3: CHECK
A4: 1003 | B4: CREDIT CARD RECEIPT
A5: 1004 | B5: PAYROLL JV
A6: 1005 | B6: PAYROLL MANUAL JV
A7: 1006 | B7: PAYROLL S/B JV
A8: 1007 | B8: PURCHASE CARD
A9: 1008 | B9: REGULAR JV

Sheet Case 4 solution
A1: JENumber | B1: GLAccountNumber | C1: BusinessUnitID | D1: PreparerID | E1: SourceID | F1: EffectiveDate | G1: JEDescription | H1: Debit | I1: Credit | J1: Amount | K1: BusinessUnit | L1: BUDescription | M1: GLAccountName | N1: AccountType | O1: AccountClass | P1: PreparerName | Q1: Source
A2: 2033520 | B2: 76930 | C2: 1 | D2: 101 | E2: 1002 | F2: 44002 | G2: TELECOM GTA JUN 2016 | H2: 36.9 | J2: 36.9 | K2: =IFERROR(INDEX(BusinessUnits!$B:$B,MATCH($C2,BusinessUnits!$A:$A,0)),"") -> FOOD SERVICE | L2: =IFERROR(INDEX(Table1[[#All],[Description]],MATCH($C2,BusinessUnits!$A:$A,0)),"") -> Transactions related to food and beverage service. Includes all guest transactions in the hotel restaurants, catering-related transactions and food service payroll. | M2: =IFERROR(INDEX(ChartOfAccounts!B1:B86,MATCH($B2,ChartOfAccounts!A1:A86,0)),"") -> Telecommunications - Other | N2: =IFERROR(INDEX(ChartOfAccounts!D:D,MATCH($B2,ChartOfAccounts!A1:A86,0)),"") -> Expenses | O2: =IFERROR(INDEX(ChartOfAccounts!F:F,MATCH($B2,ChartOfAccounts!A1:A86,0)),"") -> SG&A | P2: {=IFERROR(INDEX(PreparerInfo!B1:B13,MATCH($D2&$C2,PreparerInfo!A1:A13&PreparerInfo!C1:C13,0)),"")} -> Carolyn Slater|Food Operations Manager | Q2: =IFERROR(INDEX(Source!B1:B9,MATCH('Case 4 solution'!E2,Source!A1:A9,0)),"") -> CHECK
A3: 2033520 | B3: 11845 | C3: 1 | D3: 101 | E3: 1002 | F3: 44002 | G3: TELECOM GTA JUN 2016 | I3: -36.9 | J3: -36.9 | K3: =IFERROR(INDEX(BusinessUnits!$B:$B,MATCH($C3,BusinessUnits!$A:$A,0)),"") -> FOOD SERVICE | L3: =IFERROR(INDEX(Table1[[#All],[Description]],MATCH($C3,BusinessUnits!$A:$A,0)),"") -> Transactions related to food and beverage service. Includes all guest transactions in the hotel restaurants, catering-related transactions and food service payroll. | M3: =IFERROR(INDEX(ChartOfAccounts!B2:B87,MATCH($B3,ChartOfAccounts!A2:A87,0)),"") -> Operating Bank Account | N3: =IFERROR(INDEX(ChartOfAccounts!D:D,MATCH($B3,ChartOfAccounts!A2:A87,0)),"") -> Assets | O3: =IFERROR(INDEX(ChartOfAccounts!F:F,MATCH($B3,ChartOfAccounts!A2:A87,0)),"") -> Cash | P3: {=IFERROR(INDEX(PreparerInfo!B2:B14,MATCH($D3&$C3,PreparerInfo!A2:A14&PreparerInfo!C2:C14,0)),"")} -> Carolyn Slater|Food Operations Manager | Q3: =IFERROR(INDEX(Source!B2:B10,MATCH('Case 4 solution'!E3,Source!A2:A10,0)),"") -> CHECK
A4: 2033521 | B4: 11845 | C4: 3 | D4: 102 | E4: 1001 | F4: 44002 | G4: CASH RECEIPTS | H4: 63.1 | J4: 63.1 | K4: =IFERROR(INDEX(BusinessUnits!$B:$B,MATCH($C4,BusinessUnits!$A:$A,0)),"") -> HOTEL PANTRY | L4: =IFERROR(INDEX(Table1[[#All],[Description]],MATCH($C4,BusinessUnits!$A:$A,0)),"") -> Transactions related to the hotel convenience store, including some food and beverage costs. | M4: =IFERROR(INDEX(ChartOfAccounts!B3:B88,MATCH($B4,ChartOfAccounts!A3:A88,0)),"") -> Operating Bank Account | N4: =IFERROR(INDEX(ChartOfAccounts!D:D,MATCH($B4,ChartOfAccounts!A3:A88,0)),"") -> AccountType | O4: =IFERROR(INDEX(ChartOfAccounts!F:F,MATCH($B4,ChartOfAccounts!A3:A88,0)),"") -> AccountClass | P4: {=IFERROR(INDEX(PreparerInfo!B3:B15,MATCH($D4&$C4,PreparerInfo!A3:A15&PreparerInfo!C3:C15,0)),"")} -> POS | Q4: =IFERROR(INDEX(Source!B3:B11,MATCH('Case 4 solution'!E4,Source!A3:A11,0)),"")
A5: 2033521 | B5: 43440 | C5: 3 | D5: 102 | E5: 1001 | F5: 44002 | G5: CASH RECEIPTS | I5: -63.1 | J5: -63.1 | K5: =IFERROR(INDEX(BusinessUnits!$B:$B,MATCH($C5,BusinessUnits!$A:$A,0)),"") -> HOTEL PANTRY | L5: =IFERROR(INDEX(Table1[[#All],[Description]],MATCH($C5,BusinessUnits!$A:$A,0)),"") -> Transactions related to the hotel convenience store, including some food and beverage costs. | M5: =IFERROR(INDEX(ChartOfAccounts!B4:B89,MATCH($B5,ChartOfAccounts!A4:A89,0)),"") -> Sales - Other | N5: =IFERROR(INDEX(ChartOfAccounts!D:D,MATCH($B5,ChartOfAccounts!A4:A89,0)),"") -> Revenue | O5: =IFERROR(INDEX(ChartOfAccounts!F:F,MATCH($B5,ChartOfAccounts!A4:A89,0)),"") -> Other Income | P5: {=IFERROR(INDEX(PreparerInfo!B4:B16,MATCH($D5&$C5,PreparerInfo!A4:A16&PreparerInfo!C4:C16,0)),"")} -> POS | Q5: =IFERROR(INDEX(Source!B4:B12,MATCH('Case 4 solution'!E5,Source!A4:A12,0)),"")
A6: 2033522 | B6: 11845 | C6: 1 | D6: 102 | E6: 1003 | F6: 44002 | G6: CREDIT CARD RECEIPTS | H6: 68.28 | J6: 68.28 | K6: =IFERROR(INDEX(BusinessUnits!$B:$B,MATCH($C6,BusinessUnits!$A:$A,0)),"") -> FOOD SERVICE | L6: =IFERROR(INDEX(Table1[[#All],[Description]],MATCH($C6,BusinessUnits!$A:$A,0)),"") -> Transactions related to food and beverage service. Includes all guest transactions in the hotel restaurants, catering-related transactions and food service payroll. | M6: =IFERROR(INDEX(ChartOfAccounts!B5:B90,MATCH($B6,ChartOfAccounts!A5:A90,0)),"") | N6: =IFERROR(INDEX(ChartOfAccounts!D:D,MATCH($B6,ChartOfAccounts!A5:A90,0)),"") | O6: =IFERROR(INDEX(ChartOfAccounts!F:F,MATCH($B6,ChartOfAccounts!A5:A90,0)),"") | P6: {=IFERROR(INDEX(PreparerInfo!B5:B17,MATCH($D6&$C6,PreparerInfo!A5:A17&PreparerInfo!C5:C17,0)),"")} -> Elizabeth Rees|Food Operations Manager | Q6: =IFERROR(INDEX(Source!B5:B13,MATCH('Case 4 solution'!E6,Source!A5:A13,0)),"")
A7: 2033522 | B7: 43310 | C7: 1 | D7: 102 | E7: 1003 | F7: 44002 | G7: CREDIT CARD RECEIPTS | I7: -68.28 | J7: -68.28 | K7: =IFERROR(INDEX(BusinessUnits!$B:$B,MATCH($C7,BusinessUnits!$A:$A,0)),"") -> FOOD SERVICE | L7: =IFERROR(INDEX(Table1[[#All],[Description]],MATCH($C7,BusinessUnits!$A:$A,0)),"") -> Transactions related to food and beverage service. Includes all guest transactions in the hotel restaurants, catering-related transactions and food service payroll. | M7: =IFERROR(INDEX(ChartOfAccounts!B6:B91,MATCH($B7,ChartOfAccounts!A6:A91,0)),"") -> Sales - Dining Halls | N7: =IFERROR(INDEX(ChartOfAccounts!D:D,MATCH($B7,ChartOfAccounts!A6:A91,0)),"") -> Liabilities | O7: =IFERROR(INDEX(ChartOfAccounts!F:F,MATCH($B7,ChartOfAccounts!A6:A91,0)),"") -> Other LT Liabilities | P7: {=IFERROR(INDEX(PreparerInfo!B6:B18,MATCH($D7&$C7,PreparerInfo!A6:A18&PreparerInfo!C6:C18,0)),"")} -> Elizabeth Rees|Food Operations Manager | Q7: =IFERROR(INDEX(Source!B6:B14,MATCH('Case 4 solution'!E7,Source!A6:A14,0)),"")
A8: 2033523 | B8: 11845 | C8: 2 | D8: 106 | E8: 1003 | F8: 44002 | G8: CONFERENCE - HOTEL | H8: 99 | J8: 99 | K8: =IFERROR(INDEX(BusinessUnits!$B:$B,MATCH($C8,BusinessUnits!$A:$A,0)),"") -> HOTEL | L8: =IFERROR(INDEX(Table1[[#All],[Description]],MATCH($C8,BusinessUnits!$A:$A,0)),"") -> Transactions related to guest rooms and overall hotel operations. Includes payroll for administrative staff, clerks and interns. | M8: =IFERROR(INDEX(ChartOfAccounts!B7:B92,MATCH($B8,ChartOfAccounts!A7:A92,0)),"") | N8: =IFERROR(INDEX(ChartOfAccounts!D:D,MATCH($B8,ChartOfAccounts!A7:A92,0)),"") | O8: =IFERROR(INDEX(ChartOfAccounts!F:F,MATCH($B8,ChartOfAccounts!A7:A92,0)),"") | P8: {=IFERROR(INDEX(PreparerInfo!B7:B19,MATCH($D8&$C8,PreparerInfo!A7:A19&PreparerInfo!C7:C19,0)),"")} -> Yvonne Chapman|Catering Manager | Q8: =IFERROR(INDEX(Source!B7:B15,MATCH('Case 4 solution'!E8,Source!A7:A15,0)),"")
A9: 2033523 | B9: 43180 | C9: 2 | D9: 106 | E9: 1003 | F9: 44002 | G9: CONFERENCE - HOTEL | I9: -99 | J9: -99 | K9: =IFERROR(INDEX(BusinessUnits!$B:$B,MATCH($C9,BusinessUnits!$A:$A,0)),"") -> HOTEL | L9: =IFERROR(INDEX(Table1[[#All],[Description]],MATCH($C9,BusinessUnits!$A:$A,0)),"") -> Transactions related to guest rooms and overall hotel operations. Includes payroll for administrative staff, clerks and interns. | M9: =IFERROR(INDEX(ChartOfAccounts!B8:B93,MATCH($B9,ChartOfAccounts!A8:A93,0)),"") -> Rents - Hotels | N9: =IFERROR(INDEX(ChartOfAccounts!D:D,MATCH($B9,ChartOfAccounts!A8:A93,0)),"") -> Liabilities | O9: =IFERROR(INDEX(ChartOfAccounts!F:F,MATCH($B9,ChartOfAccounts!A8:A93,0)),"") -> Other ST Liabilities | P9: {=IFERROR(INDEX(PreparerInfo!B8:B20,MATCH($D9&$C9,PreparerInfo!A8:A20&PreparerInfo!C8:C20,0)),"")} -> Yvonne Chapman|Catering Manager | Q9: =IFERROR(INDEX(Source!B8:B16,MATCH('Case 4 solution'!E9,Source!A8:A16,0)),"")
A10: 2033524 | B10: 11845 | C10: 3 | D10: 102 | E10: 1003 | F10: 44002 | G10: CREDIT CARD RECEIPTS | H10: 107.21 | J10: 107.21 | K10: =IFERROR(INDEX(BusinessUnits!$B:$B,MATCH($C10,BusinessUnits!$A:$A,0)),"") -> HOTEL PANTRY | L10: =IFERROR(INDEX(Table1[[#All],[Description]],MATCH($C10,BusinessUnits!$A:$A,0)),"") -> Transactions related to the hotel convenience store, including some food and beverage costs. | M10: =IFERROR(INDEX(ChartOfAccounts!B9:B94,MATCH($B10,ChartOfAccounts!A9:A94,0)),"") | N10: =IFERROR(INDEX(ChartOfAccounts!D:D,MATCH($B10,ChartOfAccounts!A9:A94,0)),"") | O10: =IFERROR(INDEX(ChartOfAccounts!F:F,MATCH($B10,ChartOfAccounts!A9:A94,0)),"") | P10: {=IFERROR(INDEX(PreparerInfo!B9:B21,MATCH($D10&$C10,PreparerInfo!A9:A21&PreparerInfo!C9:C21,0)),"")} -> POS | Q10: =IFERROR(INDEX(Source!B9:B17,MATCH('Case 4 solution'!E10,Source!A9:A17,0)),"")
A11: 2033524 | B11: 43440 | C11: 3 | D11: 102 | E11: 1003 | F11: 44002 | G11: CREDIT CARD RECEIPTS | I11: -107.21 | J11: -107.21 | K11: =IFERROR(INDEX(BusinessUnits!$B:$B,MATCH($C11,BusinessUnits!$A:$A,0)),"") -> HOTEL PANTRY | L11: =IFERROR(INDEX(Table1[[#All],[Description]],MATCH($C11,BusinessUnits!$A:$A,0)),"") -> Transactions related to the hotel convenience store, including some food and beverage costs. | M11: =IFERROR(INDEX(ChartOfAccounts!B10:B95,MATCH($B11,ChartOfAccounts!A10:A95,0)),"") -> Sales - Other | N11: =IFERROR(INDEX(ChartOfAccounts!D:D,MATCH($B11,ChartOfAccounts!A10:A95,0)),"") -> Liabilities | O11: =IFERROR(INDEX(ChartOfAccounts!F:F,MATCH($B11,ChartOfAccounts!A10:A95,0)),"") -> Other ST Liabilities | P11: {=IFERROR(INDEX(PreparerInfo!B10:B22,MATCH($D11&$C11,PreparerInfo!A10:A22&PreparerInfo!C10:C22,0)),"")} | Q11: =IFERROR(INDEX(Source!B10:B18,MATCH('Case 4 solution'!E11,Source!A10:A18,0)),"")
A12: 2033525 | B12: 11845 | C12: 2 | D12: 104 | E12: 1003 | F12: 44002 | G12: HENDERSON,KENNY | H12: 129 | J12: 129 | K12: =IFERROR(INDEX(BusinessUnits!$B:$B,MATCH($C12,BusinessUnits!$A:$A,0)),"") -> HOTEL | L12: =IFERROR(INDEX(Table1[[#All],[Description]],MATCH($C12,BusinessUnits!$A:$A,0)),"") -> Transactions related to guest rooms and overall hotel operations. Includes payroll for administrative staff, clerks and interns. | M12: =IFERROR(INDEX(ChartOfAccounts!B11:B96,MATCH($B12,ChartOfAccounts!A11:A96,0)),"") | N12: =IFERROR(INDEX(ChartOfAccounts!D:D,MATCH($B12,ChartOfAccounts!A11:A96,0)),"") | O12: =IFERROR(INDEX(ChartOfAccounts!F:F,MATCH($B12,ChartOfAccounts!A11:A96,0)),"") | P12: {=IFERROR(INDEX(PreparerInfo!B11:B23,MATCH($D12&$C12,PreparerInfo!A11:A23&PreparerInfo!C11:C23,0)),"")} -> GUESTSYS | Q12: =IFERROR(INDEX(Source!B11:B19,MATCH('Case 4 solution'!E12,Source!A11:A19,0)),"")
A13: 2033525 | B13: 43180 | C13: 2 | D13: 104 | E13: 1003 | F13: 44002 | G13: HENDERSON,KENNY | I13: -129 | J13: -129 | K13: =IFERROR(INDEX(BusinessUnits!$B:$B,MATCH($C13,BusinessUnits!$A:$A,0)),"") -> HOTEL | L13: =IFERROR(INDEX(Table1[[#All],[Description]],MATCH($C13,BusinessUnits!$A:$A,0)),"") -> Transactions related to guest rooms and overall hotel operations. Includes payroll for administrative staff, clerks and interns. | M13: =IFERROR(INDEX(ChartOfAccounts!B12:B97,MATCH($B13,ChartOfAccounts!A12:A97,0)),"") -> Rents - Hotels | N13: =IFERROR(INDEX(ChartOfAccounts!D:D,MATCH($B13,ChartOfAccounts!A12:A97,0)),"") -> Assets | O13: =IFERROR(INDEX(ChartOfAccounts!F:F,MATCH($B13,ChartOfAccounts!A12:A97,0)),"") -> Plant, Property and Equipment | P13: {=IFERROR(INDEX(PreparerInfo!B12:B24,MATCH($D13&$C13,PreparerInfo!A12:A24&PreparerInfo!C12:C24,0)),"")} | Q13: =IFERROR(INDEX(Source!B12:B20,MATCH('Case 4 solution'!E13,Source!A12:A20,0)),"")
A14: 2033526 | B14: 11845 | C14: 2 | D14: 104 | E14: 1003 | F14: 44002 | G14: GENTRY,NIA | H14: 258 | J14: 258 | K14: =IFERROR(INDEX(BusinessUnits!$B:$B,MATCH($C14,BusinessUnits!$A:$A,0)),"") -> HOTEL | L14: =IFERROR(INDEX(Table1[[#All],[Description]],MATCH($C14,BusinessUnits!$A:$A,0)),"") -> Transactions related to guest rooms and overall hotel operations. Includes payroll for administrative staff, clerks and interns. | M14: =IFERROR(INDEX(ChartOfAccounts!B13:B98,MATCH($B14,ChartOfAccounts!A13:A98,0)),"") | N14: =IFERROR(INDEX(ChartOfAccounts!D:D,MATCH($B14,ChartOfAccounts!A13:A98,0)),"") | O14: =IFERROR(INDEX(ChartOfAccounts!F:F,MATCH($B14,ChartOfAccounts!A13:A98,0)),"") | P14: {=IFERROR(INDEX(PreparerInfo!B13:B25,MATCH($D14&$C14,PreparerInfo!A13:A25&PreparerInfo!C13:C25,0)),"")} | Q14: =IFERROR(INDEX(Source!B13:B21,MATCH('Case 4 solution'!E14,Source!A13:A21,0)),"")
A15: 2033526 | B15: 43180 | C15: 2 | D15: 104 | E15: 1003 | F15: 44002 | G15: GENTRY,NIA | I15: -258 | J15: -258 | K15: =IFERROR(INDEX(BusinessUnits!$B:$B,MATCH($C15,BusinessUnits!$A:$A,0)),"") -> HOTEL | L15: =IFERROR(INDEX(Table1[[#All],[Description]],MATCH($C15,BusinessUnits!$A:$A,0)),"") -> Transactions related to guest rooms and overall hotel operations. Includes payroll for administrative staff, clerks and interns. | M15: =IFERROR(INDEX(ChartOfAccounts!B14:B99,MATCH($B15,ChartOfAccounts!A14:A99,0)),"") -> Rents - Hotels | N15: =IFERROR(INDEX(ChartOfAccounts!D:D,MATCH($B15,ChartOfAccounts!A14:A99,0)),"") -> Assets | O15: =IFERROR(INDEX(ChartOfAccounts!F:F,MATCH($B15,ChartOfAccounts!A14:A99,0)),"") -> Plant, Property and Equipment | P15: {=IFERROR(INDEX(PreparerInfo!B14:B26,MATCH($D15&$C15,PreparerInfo!A14:A26&PreparerInfo!C14:C26,0)),"")} | Q15: =IFERROR(INDEX(Source!B14:B22,MATCH('Case 4 solution'!E15,Source!A14:A22,0)),"")
A16: 2033527 | B16: 11845 | C16: 2 | D16: 104 | E16: 1003 | F16: 44002 | G16: HODGES,CHAYA | H16: 418 | J16: 418 | K16: =IFERROR(INDEX(BusinessUnits!$B:$B,MATCH($C16,BusinessUnits!$A:$A,0)),"") -> HOTEL | L16: =IFERROR(INDEX(Table1[[#All],[Description]],MATCH($C16,BusinessUnits!$A:$A,0)),"") -> Transactions related to guest rooms and overall hotel operations. Includes payroll for administrative staff, clerks and interns. | M16: =IFERROR(INDEX(ChartOfAccounts!B15:B100,MATCH($B16,ChartOfAccounts!A15:A100,0)),"") | N16: =IFERROR(INDEX(ChartOfAccounts!D:D,MATCH($B16,ChartOfAccounts!A15:A100,0)),"") | O16: =IFERROR(INDEX(ChartOfAccounts!F:F,MATCH($B16,ChartOfAccounts!A15:A100,0)),"") | P16: {=IFERROR(INDEX(PreparerInfo!B15:B27,MATCH($D16&$C16,PreparerInfo!A15:A27&PreparerInfo!C15:C27,0)),"")} | Q16: =IFERROR(INDEX(Source!B15:B23,MATCH('Case 4 solution'!E16,Source!A15:A23,0)),"")
A17: 2033527 | B17: 43180 | C17: 2 | D17: 104 | E17: 1003 | F17: 44002 | G17: HODGES,CHAYA | I17: -418 | J17: -418 | K17: =IFERROR(INDEX(BusinessUnits!$B:$B,MATCH($C17,BusinessUnits!$A:$A,0)),"") -> HOTEL | L17: =IFERROR(INDEX(Table1[[#All],[Description]],MATCH($C17,BusinessUnits!$A:$A,0)),"") -> Transactions related to guest rooms and overall hotel operations. Includes payroll for administrative staff, clerks and interns. | M17: =IFERROR(INDEX(ChartOfAccounts!B16:B101,MATCH($B17,ChartOfAccounts!A16:A101,0)),"") -> Rents - Hotels | N17: =IFERROR(INDEX(ChartOfAccounts!D:D,MATCH($B17,ChartOfAccounts!A16:A101,0)),"") -> Assets | O17: =IFERROR(INDEX(ChartOfAccounts!F:F,MATCH($B17,ChartOfAccounts!A16:A101,0)),"") -> Inventory | P17: {=IFERROR(INDEX(PreparerInfo!B16:B28,MATCH($D17&$C17,PreparerInfo!A16:A28&PreparerInfo!C16:C28,0)),"")} | Q17: =IFERROR(INDEX(Source!B16:B24,MATCH('Case 4 solution'!E17,Source!A16:A24,0)),"")
A18: 2033528 | B18: 71900 | C18: 1 | D18: 102 | E18: 1002 | F18: 44002 | G18: ALSCO INC | H18: 431.8 | J18: 431.8 | K18: =IFERROR(INDEX(BusinessUnits!$B:$B,MATCH($C18,BusinessUnits!$A:$A,0)),"") -> FOOD SERVICE | L18: =IFERROR(INDEX(Table1[[#All],[Description]],MATCH($C18,BusinessUnits!$A:$A,0)),"") -> Transactions related to food and beverage service. Includes all guest transactions in the hotel restaurants, catering-related transactions and food service payroll. | M18: =IFERROR(INDEX(ChartOfAccounts!B17:B102,MATCH($B18,ChartOfAccounts!A17:A102,0)),"") -> Rents - Other Than Real Estate | N18: =IFERROR(INDEX(ChartOfAccounts!D:D,MATCH($B18,ChartOfAccounts!A17:A102,0)),"") -> Expenses | O18: =IFERROR(INDEX(ChartOfAccounts!F:F,MATCH($B18,ChartOfAccounts!A17:A102,0)),"") -> Payroll Taxes | P18: {=IFERROR(INDEX(PreparerInfo!B17:B29,MATCH($D18&$C18,PreparerInfo!A17:A29&PreparerInfo!C17:C29,0)),"")} | Q18: =IFERROR(INDEX(Source!B17:B25,MATCH('Case 4 solution'!E18,Source!A17:A25,0)),"")
A19: 2033528 | B19: 11845 | C19: 1 | D19: 102 | E19: 1002 | F19: 44002 | G19: ALSCO INC | I19: -431.8 | J19: -431.8 | K19: =IFERROR(INDEX(BusinessUnits!$B:$B,MATCH($C19,BusinessUnits!$A:$A,0)),"") -> FOOD SERVICE | L19: =IFERROR(INDEX(Table1[[#All],[Description]],MATCH($C19,BusinessUnits!$A:$A,0)),"") -> Transactions related to food and beverage service. Includes all guest transactions in the hotel restaurants, catering-related transactions and food service payroll. | M19: =IFERROR(INDEX(ChartOfAccounts!B18:B103,MATCH($B19,ChartOfAccounts!A18:A103,0)),"") | N19: =IFERROR(INDEX(ChartOfAccounts!D:D,MATCH($B19,ChartOfAccounts!A18:A103,0)),"") | O19: =IFERROR(INDEX(ChartOfAccounts!F:F,MATCH($B19,ChartOfAccounts!A18:A103,0)),"") | P19: {=IFERROR(INDEX(PreparerInfo!B18:B30,MATCH($D19&$C19,PreparerInfo!A18:A30&PreparerInfo!C18:C30,0)),"")} | Q19: =IFERROR(INDEX(Source!B18:B26,MATCH('Case 4 solution'!E19,Source!A18:A26,0)),"")
A20: 2033529 | B20: 11845 | C20: 1 | D20: 102 | E20: 1001 | F20: 44002 | G20: CASH RECEIPTS | H20: 612.54 | J20: 612.54 | K20: =IFERROR(INDEX(BusinessUnits!$B:$B,MATCH($C20,BusinessUnits!$A:$A,0)),"") -> FOOD SERVICE | L20: =IFERROR(INDEX(Table1[[#All],[Description]],MATCH($C20,BusinessUnits!$A:$A,0)),"") -> Transactions related to food and beverage service. Includes all guest transactions in the hotel restaurants, catering-related transactions and food service payroll. | M20: =IFERROR(INDEX(ChartOfAccounts!B19:B104,MATCH($B20,ChartOfAccounts!A19:A104,0)),"") | N20: =IFERROR(INDEX(ChartOfAccounts!D:D,MATCH($B20,ChartOfAccounts!A19:A104,0)),"") | O20: =IFERROR(INDEX(ChartOfAccounts!F:F,MATCH($B20,ChartOfAccounts!A19:A104,0)),"") | P20: {=IFERROR(INDEX(PreparerInfo!B19:B31,MATCH($D20&$C20,PreparerInfo!A19:A31&PreparerInfo!C19:C31,0)),"")} | Q20: =IFERROR(INDEX(Source!B19:B27,MATCH('Case 4 solution'!E20,Source!A19:A27,0)),"")
A21: 2033529 | B21: 43310 | C21: 1 | D21: 102 | E21: 1001 | F21: 44002 | G21: CASH RECEIPTS | I21: -612.54 | J21: -612.54 | K21: =IFERROR(INDEX(BusinessUnits!$B:$B,MATCH($C21,BusinessUnits!$A:$A,0)),"") -> FOOD SERVICE | L21: =IFERROR(INDEX(Table1[[#All],[Description]],MATCH($C21,BusinessUnits!$A:$A,0)),"") -> Transactions related to food and beverage service. Includes all guest transactions in the hotel restaurants, catering-related transactions and food service payroll. | M21: =IFERROR(INDEX(ChartOfAccounts!B20:B105,MATCH($B21,ChartOfAccounts!A20:A105,0)),"") -> Sales - Dining Halls | N21: =IFERROR(INDEX(ChartOfAccounts!D:D,MATCH($B21,ChartOfAccounts!A20:A105,0)),"") -> Assets | O21: =IFERROR(INDEX(ChartOfAccounts!F:F,MATCH($B21,ChartOfAccounts!A20:A105,0)),"") -> Accounts Receivable | P21: {=IFERROR(INDEX(PreparerInfo!B20:B32,MATCH($D21&$C21,PreparerInfo!A20:A32&PreparerInfo!C20:C32,0)),"")} | Q21: =IFERROR(INDEX(Source!B20:B28,MATCH('Case 4 solution'!E21,Source!A20:A28,0)),"")
A22: 2033530 | B22: 76930 | C22: 2 | D22: 101 | E22: 1002 | F22: 44002 | G22: TELECOM GTA JUN 2016 | H22: 1015.21 | J22: 1015.21 | K22: =IFERROR(INDEX(BusinessUnits!$B:$B,MATCH($C22,BusinessUnits!$A:$A,0)),"") -> HOTEL | L22: =IFERROR(INDEX(Table1[[#All],[Description]],MATCH($C22,BusinessUnits!$A:$A,0)),"") -> Transactions related to guest rooms and overall hotel operations. Includes payroll for administrative staff, clerks and interns. | M22: =IFERROR(INDEX(ChartOfAccounts!B21:B106,MATCH($B22,ChartOfAccounts!A21:A106,0)),"") -> Telecommunications - Other | N22: =IFERROR(INDEX(ChartOfAccounts!D:D,MATCH($B22,ChartOfAccounts!A21:A106,0)),"") -> Expenses | O22: =IFERROR(INDEX(ChartOfAccounts!F:F,MATCH($B22,ChartOfAccounts!A21:A106,0)),"") -> SG&A | P22: {=IFERROR(INDEX(PreparerInfo!B21:B33,MATCH($D22&$C22,PreparerInfo!A21:A33&PreparerInfo!C21:C33,0)),"")} | Q22: =IFERROR(INDEX(Source!B21:B29,MATCH('Case 4 solution'!E22,Source!A21:A29,0)),"")
A23: 2033530 | B23: 11845 | C23: 2 | D23: 101 | E23: 1002 | F23: 44002 | G23: TELECOM GTA JUN 2016 | I23: -1015.21 | J23: -1015.21 | K23: =IFERROR(INDEX(BusinessUnits!$B:$B,MATCH($C23,BusinessUnits!$A:$A,0)),"") -> HOTEL | L23: =IFERROR(INDEX(Table1[[#All],[Description]],MATCH($C23,BusinessUnits!$A:$A,0)),"") -> Transactions related to guest rooms and overall hotel operations. Includes payroll for administrative staff, clerks and interns. | M23: =IFERROR(INDEX(ChartOfAccounts!B22:B107,MATCH($B23,ChartOfAccounts!A22:A107,0)),"") | N23: =IFERROR(INDEX(ChartOfAccounts!D:D,MATCH($B23,ChartOfAccounts!A22:A107,0)),"") | O23: =IFERROR(INDEX(ChartOfAccounts!F:F,MATCH($B23,ChartOfAccounts!A22:A107,0)),"") | P23: {=IFERROR(INDEX(PreparerInfo!B22:B34,MATCH($D23&$C23,PreparerInfo!A22:A34&PreparerInfo!C22:C34,0)),"")} | Q23: =IFERROR(INDEX(Source!B22:B30,MATCH('Case 4 solution'!E23,Source!A22:A30,0)),"")
A24: 2033531 | B24: 11845 | C24: 1 | D24: 102 | E24: 1003 | F24: 44002 | G24: CREDIT CARD RECEIPTS | H24: 2157.22 | J24: 2157.22 | K24: =IFERROR(INDEX(BusinessUnits!$B:$B,MATCH($C24,BusinessUnits!$A:$A,0)),"") -> FOOD SERVICE | L24: =IFERROR(INDEX(Table1[[#All],[Description]],MATCH($C24,BusinessUnits!$A:$A,0)),"") -> Transactions related to food and beverage service. Includes all guest transactions in the hotel restaurants, catering-related transactions and food service payroll. | M24: =IFERROR(INDEX(ChartOfAccounts!B23:B108,MATCH($B24,ChartOfAccounts!A23:A108,0)),"") | N24: =IFERROR(INDEX(ChartOfAccounts!D:D,MATCH($B24,ChartOfAccounts!A23:A108,0)),"") | O24: =IFERROR(INDEX(ChartOfAccounts!F:F,MATCH($B24,ChartOfAccounts!A23:A108,0)),"") | P24: {=IFERROR(INDEX(PreparerInfo!B23:B35,MATCH($D24&$C24,PreparerInfo!A23:A35&PreparerInfo!C23:C35,0)),"")} | Q24: =IFERROR(INDEX(Source!B23:B31,MATCH('Case 4 solution'!E24,Source!A23:A31,0)),"")
A25: 2033531 | B25: 43310 | C25: 1 | D25: 102 | E25: 1003 | F25: 44002 | G25: CREDIT CARD RECEIPTS | I25: -2157.22 | J25: -2157.22 | K25: =IFERROR(INDEX(BusinessUnits!$B:$B,MATCH($C25,BusinessUnits!$A:$A,0)),"") -> FOOD SERVICE | L25: =IFERROR(INDEX(Table1[[#All],[Description]],MATCH($C25,BusinessUnits!$A:$A,0)),"") -> Transactions related to food and beverage service. Includes all guest transactions in the hotel restaurants, catering-related transactions and food service payroll. | M25: =IFERROR(INDEX(ChartOfAccounts!B24:B109,MATCH($B25,ChartOfAccounts!A24:A109,0)),"") | N25: =IFERROR(INDEX(ChartOfAccounts!D:D,MATCH($B25,ChartOfAccounts!A24:A109,0)),"") | O25: =IFERROR(INDEX(ChartOfAccounts!F:F,MATCH($B25,ChartOfAccounts!A24:A109,0)),"") | P25: {=IFERROR(INDEX(PreparerInfo!B24:B36,MATCH($D25&$C25,PreparerInfo!A24:A36&PreparerInfo!C24:C36,0)),"")} | Q25: =IFERROR(INDEX(Source!B24:B32,MATCH('Case 4 solution'!E25,Source!A24:A32,0)),"")
A26: 2033532 | B26: 11845 | C26: 1 | D26: 106 | E26: 1003 | F26: 44002 | G26: CONFERENCE - FOOD SERVICE | H26: 4503.3 | J26: 4503.3 | K26: =IFERROR(INDEX(BusinessUnits!$B:$B,MATCH($C26,BusinessUnits!$A:$A,0)),"") -> FOOD SERVICE | L26: =IFERROR(INDEX(Table1[[#All],[Description]],MATCH($C26,BusinessUnits!$A:$A,0)),"") -> Transactions related to food and beverage service. Includes all guest transactions in the hotel restaurants, catering-related transactions and food service payroll. | M26: =IFERROR(INDEX(ChartOfAccounts!B25:B110,MATCH($B26,ChartOfAccounts!A25:A110,0)),"") | N26: =IFERROR(INDEX(ChartOfAccounts!D:D,MATCH($B26,ChartOfAccounts!A25:A110,0)),"") | O26: =IFERROR(INDEX(ChartOfAccounts!F:F,MATCH($B26,ChartOfAccounts!A25:A110,0)),"") | P26: {=IFERROR(INDEX(PreparerInfo!B25:B37,MATCH($D26&$C26,PreparerInfo!A25:A37&PreparerInfo!C25:C37,0)),"")} | Q26: =IFERROR(INDEX(Source!B25:B33,MATCH('Case 4 solution'!E26,Source!A25:A33,0)),"")
A27: 2033532 | B27: 43310 | C27: 1 | D27: 106 | E27: 1003 | F27: 44002 | G27: CONFERENCE - FOOD SERVICE | I27: -4503.3 | J27: -4503.3 | K27: =IFERROR(INDEX(BusinessUnits!$B:$B,MATCH($C27,BusinessUnits!$A:$A,0)),"") -> FOOD SERVICE | L27: =IFERROR(INDEX(Table1[[#All],[Description]],MATCH($C27,BusinessUnits!$A:$A,0)),"") -> Transactions related to food and beverage service. Includes all guest transactions in the hotel restaurants, catering-related transactions and food service payroll. | M27: =IFERROR(INDEX(ChartOfAccounts!B26:B111,MATCH($B27,ChartOfAccounts!A26:A111,0)),"") | N27: =IFERROR(INDEX(ChartOfAccounts!D:D,MATCH($B27,ChartOfAccounts!A26:A111,0)),"") | O27: =IFERROR(INDEX(ChartOfAccounts!F:F,MATCH($B27,ChartOfAccounts!A26:A111,0)),"") | P27: {=IFERROR(INDEX(PreparerInfo!B26:B38,MATCH($D27&$C27,PreparerInfo!A26:A38&PreparerInfo!C26:C38,0)),"")} | Q27: =IFERROR(INDEX(Source!B26:B34,MATCH('Case 4 solution'!E27,Source!A26:A34,0)),"")
A28: 2033533 | B28: 11845 | C28: 2 | D28: 104 | E28: 1003 | F28: 44002 | G28: CREDIT CARD RECEIPTS | H28: 6197 | J28: 6197 | K28: =IFERROR(INDEX(BusinessUnits!$B:$B,MATCH($C28,BusinessUnits!$A:$A,0)),"") -> HOTEL | L28: =IFERROR(INDEX(Table1[[#All],[Description]],MATCH($C28,BusinessUnits!$A:$A,0)),"") -> Transactions related to guest rooms and overall hotel operations. Includes payroll for administrative staff, clerks and interns. | M28: =IFERROR(INDEX(ChartOfAccounts!B27:B112,MATCH($B28,ChartOfAccounts!A27:A112,0)),"") | N28: =IFERROR(INDEX(ChartOfAccounts!D:D,MATCH($B28,ChartOfAccounts!A27:A112,0)),"") | O28: =IFERROR(INDEX(ChartOfAccounts!F:F,MATCH($B28,ChartOfAccounts!A27:A112,0)),"") | P28: {=IFERROR(INDEX(PreparerInfo!B27:B39,MATCH($D28&$C28,PreparerInfo!A27:A39&PreparerInfo!C27:C39,0)),"")} | Q28: =IFERROR(INDEX(Source!B27:B35,MATCH('Case 4 solution'!E28,Source!A27:A35,0)),"")
A29: 2033533 | B29: 43180 | C29: 2 | D29: 104 | E29: 1003 | F29: 44002 | G29: CREDIT CARD RECEIPTS | I29: -6197 | J29: -6197 | K29: =IFERROR(INDEX(BusinessUnits!$B:$B,MATCH($C29,BusinessUnits!$A:$A,0)),"") -> HOTEL | L29: =IFERROR(INDEX(Table1[[#All],[Description]],MATCH($C29,BusinessUnits!$A:$A,0)),"") -> Transactions related to guest rooms and overall hotel operations. Includes payroll for administrative staff, clerks and interns. | M29: =IFERROR(INDEX(ChartOfAccounts!B28:B113,MATCH($B29,ChartOfAccounts!A28:A113,0)),"") | N29: =IFERROR(INDEX(ChartOfAccounts!D:D,MATCH($B29,ChartOfAccounts!A28:A113,0)),"") | O29: =IFERROR(INDEX(ChartOfAccounts!F:F,MATCH($B29,ChartOfAccounts!A28:A113,0)),"") | P29: {=IFERROR(INDEX(PreparerInfo!B28:B40,MATCH($D29&$C29,PreparerInfo!A28:A40&PreparerInfo!C28:C40,0)),"")} | Q29: =IFERROR(INDEX(Source!B28:B36,MATCH('Case 4 solution'!E29,Source!A28:A36,0)),"")
A30: 2033534 | B30: 71400 | C30: 2 | D30: 101 | E30: 1002 | F30: 44002 | G30: PARKING SERVICES OF AMERICA | H30: 26770 | J30: 26770 | K30: =IFERROR(INDEX(BusinessUnits!$B:$B,MATCH($C30,BusinessUnits!$A:$A,0)),"") -> HOTEL | L30: =IFERROR(INDEX(Table1[[#All],[Description]],MATCH($C30,BusinessUnits!$A:$A,0)),"") -> Transactions related to guest rooms and overall hotel operations. Includes payroll for administrative staff, clerks and interns. | M30: =IFERROR(INDEX(ChartOfAccounts!B29:B114,MATCH($B30,ChartOfAccounts!A29:A114,0)),"") -> Supplies and Materials | N30: =IFERROR(INDEX(ChartOfAccounts!D:D,MATCH($B30,ChartOfAccounts!A29:A114,0)),"") -> Liabilities | O30: =IFERROR(INDEX(ChartOfAccounts!F:F,MATCH($B30,ChartOfAccounts!A29:A114,0)),"") -> Accrued Payroll | P30: {=IFERROR(INDEX(PreparerInfo!B29:B41,MATCH($D30&$C30,PreparerInfo!A29:A41&PreparerInfo!C29:C41,0)),"")} | Q30: =IFERROR(INDEX(Source!B29:B37,MATCH('Case 4 solution'!E30,Source!A29:A37,0)),"")
A31: 2033534 | B31: 11845 | C31: 2 | D31: 101 | E31: 1002 | F31: 44002 | G31: PARKING SERVICES OF AMERICA | I31: -26770 | J31: -26770 | K31: =IFERROR(INDEX(BusinessUnits!$B:$B,MATCH($C31,BusinessUnits!$A:$A,0)),"") -> HOTEL | L31: =IFERROR(INDEX(Table1[[#All],[Description]],MATCH($C31,BusinessUnits!$A:$A,0)),"") -> Transactions related to guest rooms and overall hotel operations. Includes payroll for administrative staff, clerks and interns. | M31: =IFERROR(INDEX(ChartOfAccounts!B30:B115,MATCH($B31,ChartOfAccounts!A30:A115,0)),"") | N31: =IFERROR(INDEX(ChartOfAccounts!D:D,MATCH($B31,ChartOfAccounts!A30:A115,0)),"") | O31: =IFERROR(INDEX(ChartOfAccounts!F:F,MATCH($B31,ChartOfAccounts!A30:A115,0)),"") | P31: {=IFERROR(INDEX(PreparerInfo!B30:B42,MATCH($D31&$C31,PreparerInfo!A30:A42&PreparerInfo!C30:C42,0)),"")} | Q31: =IFERROR(INDEX(Source!B30:B38,MATCH('Case 4 solution'!E31,Source!A30:A38,0)),"")
A32: 2033535 | B32: 11845 | C32: 3 | D32: 102 | E32: 1001 | F32: 44003 | G32: CASH RECEIPTS | H32: 38.29 | J32: 38.29 | K32: =IFERROR(INDEX(BusinessUnits!$B:$B,MATCH($C32,BusinessUnits!$A:$A,0)),"") -> HOTEL PANTRY | L32: =IFERROR(INDEX(Table1[[#All],[Description]],MATCH($C32,BusinessUnits!$A:$A,0)),"") -> Transactions related to the hotel convenience store, including some food and beverage costs. | M32: =IFERROR(INDEX(ChartOfAccounts!B31:B116,MATCH($B32,ChartOfAccounts!A31:A116,0)),"") | N32: =IFERROR(INDEX(ChartOfAccounts!D:D,MATCH($B32,ChartOfAccounts!A31:A116,0)),"") | O32: =IFERROR(INDEX(ChartOfAccounts!F:F,MATCH($B32,ChartOfAccounts!A31:A116,0)),"") | P32: {=IFERROR(INDEX(PreparerInfo!B31:B43,MATCH($D32&$C32,PreparerInfo!A31:A43&PreparerInfo!C31:C43,0)),"")} | Q32: =IFERROR(INDEX(Source!B31:B39,MATCH('Case 4 solution'!E32,Source!A31:A39,0)),"")
A33: 2033535 | B33: 43440 | C33: 3 | D33: 102 | E33: 1001 | F33: 44003 | G33: CASH RECEIPTS | I33: -38.29 | J33: -38.29 | K33: =IFERROR(INDEX(BusinessUnits!$B:$B,MATCH($C33,BusinessUnits!$A:$A,0)),"") -> HOTEL PANTRY | L33: =IFERROR(INDEX(Table1[[#All],[Description]],MATCH($C33,BusinessUnits!$A:$A,0)),"") -> Transactions related to the hotel convenience store, including some food and beverage costs. | M33: =IFERROR(INDEX(ChartOfAccounts!B32:B117,MATCH($B33,ChartOfAccounts!A32:A117,0)),"") | N33: =IFERROR(INDEX(ChartOfAccounts!D:D,MATCH($B33,ChartOfAccounts!A32:A117,0)),"") | O33: =IFERROR(INDEX(ChartOfAccounts!F:F,MATCH($B33,ChartOfAccounts!A32:A117,0)),"") | P33: {=IFERROR(INDEX(PreparerInfo!B32:B44,MATCH($D33&$C33,PreparerInfo!A32:A44&PreparerInfo!C32:C44,0)),"")} | Q33: =IFERROR(INDEX(Source!B32:B40,MATCH('Case 4 solution'!E33,Source!A32:A40,0)),"")
A34: 2033536 | B34: 11845 | C34: 3 | D34: 102 | E34: 1003 | F34: 44003 | G34: CREDIT CARD RECEIPTS | H34: 47.96 | J34: 47.96 | K34: =IFERROR(INDEX(BusinessUnits!$B:$B,MATCH($C34,BusinessUnits!$A:$A,0)),"") -> HOTEL PANTRY | L34: =IFERROR(INDEX(Table1[[#All],[Description]],MATCH($C34,BusinessUnits!$A:$A,0)),"") -> Transactions related to the hotel convenience store, including some food and beverage costs. | M34: =IFERROR(INDEX(ChartOfAccounts!B33:B118,MATCH($B34,ChartOfAccounts!A33:A118,0)),"") | N34: =IFERROR(INDEX(ChartOfAccounts!D:D,MATCH($B34,ChartOfAccounts!A33:A118,0)),"") | O34: =IFERROR(INDEX(ChartOfAccounts!F:F,MATCH($B34,ChartOfAccounts!A33:A118,0)),"") | P34: {=IFERROR(INDEX(PreparerInfo!B33:B45,MATCH($D34&$C34,PreparerInfo!A33:A45&PreparerInfo!C33:C45,0)),"")} | Q34: =IFERROR(INDEX(Source!B33:B41,MATCH('Case 4 solution'!E34,Source!A33:A41,0)),"")
A35: 2033536 | B35: 43440 | C35: 3 | D35: 102 | E35: 1003 | F35: 44003 | G35: CREDIT CARD RECEIPTS | I35: -47.96 | J35: -47.96 | K35: =IFERROR(INDEX(BusinessUnits!$B:$B,MATCH($C35,BusinessUnits!$A:$A,0)),"") -> HOTEL PANTRY | L35: =IFERROR(INDEX(Table1[[#All],[Description]],MATCH($C35,BusinessUnits!$A:$A,0)),"") -> Transactions related to the hotel convenience store, including some food and beverage costs. | M35: =IFERROR(INDEX(ChartOfAccounts!B34:B119,MATCH($B35,ChartOfAccounts!A34:A119,0)),"") | N35: =IFERROR(INDEX(ChartOfAccounts!D:D,MATCH($B35,ChartOfAccounts!A34:A119,0)),"") | O35: =IFERROR(INDEX(ChartOfAccounts!F:F,MATCH($B35,ChartOfAccounts!A34:A119,0)),"") | P35: {=IFERROR(INDEX(PreparerInfo!B34:B46,MATCH($D35&$C35,PreparerInfo!A34:A46&PreparerInfo!C34:C46,0)),"")} | Q35: =IFERROR(INDEX(Source!B34:B42,MATCH('Case 4 solution'!E35,Source!A34:A42,0)),"")
A36: 2033537 | B36: 14250 | C36: 3 | D36: 102 | E36: 1002 | F36: 44003 | G36: TROPICAL NUT & FRUIT | H36: 197.08 | J36: 197.08 | K36: =IFERROR(INDEX(BusinessUnits!$B:$B,MATCH($C36,BusinessUnits!$A:$A,0)),"") -> HOTEL PANTRY | L36: =IFERROR(INDEX(Table1[[#All],[Description]],MATCH($C36,BusinessUnits!$A:$A,0)),"") -> Transactions related to the hotel convenience store, including some food and beverage costs. | M36: =IFERROR(INDEX(ChartOfAccounts!B35:B120,MATCH($B36,ChartOfAccounts!A35:A120,0)),"") | N36: =IFERROR(INDEX(ChartOfAccounts!D:D,MATCH($B36,ChartOfAccounts!A35:A120,0)),"") | O36: =IFERROR(INDEX(ChartOfAccounts!F:F,MATCH($B36,ChartOfAccounts!A35:A120,0)),"") | P36: {=IFERROR(INDEX(PreparerInfo!B35:B47,MATCH($D36&$C36,PreparerInfo!A35:A47&PreparerInfo!C35:C47,0)),"")} | Q36: =IFERROR(INDEX(Source!B35:B43,MATCH('Case 4 solution'!E36,Source!A35:A43,0)),"")
A37: 2033537 | B37: 11845 | C37: 3 | D37: 102 | E37: 1002 | F37: 44003 | G37: TROPICAL NUT & FRUIT | I37: -197.08 | J37: -197.08 | K37: =IFERROR(INDEX(BusinessUnits!$B:$B,MATCH($C37,BusinessUnits!$A:$A,0)),"") -> HOTEL PANTRY | L37: =IFERROR(INDEX(Table1[[#All],[Description]],MATCH($C37,BusinessUnits!$A:$A,0)),"") -> Transactions related to the hotel convenience store, including some food and beverage costs. | M37: =IFERROR(INDEX(ChartOfAccounts!B36:B121,MATCH($B37,ChartOfAccounts!A36:A121,0)),"") | N37: =IFERROR(INDEX(ChartOfAccounts!D:D,MATCH($B37,ChartOfAccounts!A36:A121,0)),"") | O37: =IFERROR(INDEX(ChartOfAccounts!F:F,MATCH($B37,ChartOfAccounts!A36:A121,0)),"") | P37: {=IFERROR(INDEX(PreparerInfo!B36:B48,MATCH($D37&$C37,PreparerInfo!A36:A48&PreparerInfo!C36:C48,0)),"")} | Q37: =IFERROR(INDEX(Source!B36:B44,MATCH('Case 4 solution'!E37,Source!A36:A44,0)),"")
A38: 2033538 | B38: 72760 | C38: 6 | D38: 101 | E38: 1002 | F38: 44003 | G38: DYNAMIC SECU64605456 | H38: 236.32 | J38: 236.32 | K38: =IFERROR(INDEX(BusinessUnits!$B:$B,MATCH($C38,BusinessUnits!$A:$A,0)),"") -> MAINTENANCE | L38: =IFERROR(INDEX(Table1[[#All],[Description]],MATCH($C38,BusinessUnits!$A:$A,0)),"") -> Transactions related to the hotel Maintenance Department. Primarily includes payroll for maintenance, grounds keepers and related supplies. | M38: =IFERROR(INDEX(ChartOfAccounts!B37:B122,MATCH($B38,ChartOfAccounts!A37:A122,0)),"") -> Other Services | N38: =IFERROR(INDEX(ChartOfAccounts!D:D,MATCH($B38,ChartOfAccounts!A37:A122,0)),"") -> Revenue | O38: =IFERROR(INDEX(ChartOfAccounts!F:F,MATCH($B38,ChartOfAccounts!A37:A122,0)),"") -> Sales-Other | P38: {=IFERROR(INDEX(PreparerInfo!B37:B49,MATCH($D38&$C38,PreparerInfo!A37:A49&PreparerInfo!C37:C49,0)),"")} | Q38: =IFERROR(INDEX(Source!B37:B45,MATCH('Case 4 solution'!E38,Source!A37:A45,0)),"")
A39: 2033538 | B39: 11845 | C39: 6 | D39: 101 | E39: 1002 | F39: 44003 | G39: DYNAMIC SECU64605456 | I39: -236.32 | J39: -236.32 | K39: =IFERROR(INDEX(BusinessUnits!$B:$B,MATCH($C39,BusinessUnits!$A:$A,0)),"") -> MAINTENANCE | L39: =IFERROR(INDEX(Table1[[#All],[Description]],MATCH($C39,BusinessUnits!$A:$A,0)),"") -> Transactions related to the hotel Maintenance Department. Primarily includes payroll for maintenance, grounds keepers and related supplies. | M39: =IFERROR(INDEX(ChartOfAccounts!B38:B123,MATCH($B39,ChartOfAccounts!A38:A123,0)),"") | N39: =IFERROR(INDEX(ChartOfAccounts!D:D,MATCH($B39,ChartOfAccounts!A38:A123,0)),"") | O39: =IFERROR(INDEX(ChartOfAccounts!F:F,MATCH($B39,ChartOfAccounts!A38:A123,0)),"") | P39: {=IFERROR(INDEX(PreparerInfo!B38:B50,MATCH($D39&$C39,PreparerInfo!A38:A50&PreparerInfo!C38:C50,0)),"")} | Q39: =IFERROR(INDEX(Source!B38:B46,MATCH('Case 4 solution'!E39,Source!A38:A46,0)),"")
A40: 2033539 | B40: 72760 | C40: 6 | D40: 101 | E40: 1002 | F40: 44003 | G40: DYNAMIC SECU64605456 | H40: 236.32 | J40: 236.32 | K40: =IFERROR(INDEX(BusinessUnits!$B:$B,MATCH($C40,BusinessUnits!$A:$A,0)),"") -> MAINTENANCE | L40: =IFERROR(INDEX(Table1[[#All],[Description]],MATCH($C40,BusinessUnits!$A:$A,0)),"") -> Transactions related to the hotel Maintenance Department. Primarily includes payroll for maintenance, grounds keepers and related supplies. | M40: =IFERROR(INDEX(ChartOfAccounts!B39:B124,MATCH($B40,ChartOfAccounts!A39:A124,0)),"") -> Other Services | N40: =IFERROR(INDEX(ChartOfAccounts!D:D,MATCH($B40,ChartOfAccounts!A39:A124,0)),"") -> Revenue | O40: =IFERROR(INDEX(ChartOfAccounts!F:F,MATCH($B40,ChartOfAccounts!A39:A124,0)),"") -> Sales-Dining | P40: {=IFERROR(INDEX(PreparerInfo!B39:B51,MATCH($D40&$C40,PreparerInfo!A39:A51&PreparerInfo!C39:C51,0)),"")} | Q40: =IFERROR(INDEX(Source!B39:B47,MATCH('Case 4 solution'!E40,Source!A39:A47,0)),"")
...

Sheet use Xloopup
A1: JENumber | B1: GLAccountNumber | C1: BusinessUnitID | D1: PreparerID | E1: SourceID | F1: EffectiveDate | G1: JEDescription | H1: Debit | I1: Credit | J1: Amount | K1: BusinessUnit | L1: BUDescription | M1: GLAccountName | N1: AccountType | O1: AccountClass | P1: PreparerName | Q1: Source
A2: 2033520 | B2: 76930 | C2: 1 | D2: 101 | E2: 1002 | F2: 44002 | G2: TELECOM GTA JUN 2016 | H2: 36.9 | J2: 36.9 | K2: =_xlfn.XLOOKUP($C2,Table1[BusinessUnitID],Table1[BusinessUnit],"",0) -> FOOD SERVICE | L2: {=_xlfn.XLOOKUP($C2,Table1[[#All],[BusinessUnitID]],Table1[[#All],[Description]],"",0,1)} -> Transactions related to food and beverage service. Includes all guest transactions in the hotel restaurants, catering-related transactions and food service payroll. | M2: =_xlfn.XLOOKUP($B2,ChartOfAccounts!A1:A86,ChartOfAccounts!B1:B86,"",0,1) -> Telecommunications - Other | N2: =_xlfn.XLOOKUP($B2,ChartOfAccounts!A1:A86,ChartOfAccounts!D1:D86,0,1) -> Expenses | O2: =_xlfn.XLOOKUP($B2,ChartOfAccounts!A1:A86,ChartOfAccounts!F1:F86,"",0,1) -> SG&A | P2: {=_xlfn.XLOOKUP($D2&$C2,PreparerInfo!A1:A13&PreparerInfo!C1:C13,PreparerInfo!B1:B13,"",0,1)} -> Carolyn Slater|Food Operations Manager | Q2: =_xlfn.XLOOKUP($E2,Source!A1:A9,Source!B1:B9,"",0,1) -> CHECK
A3: 2033520 | B3: 11845 | C3: 1 | D3: 101 | E3: 1002 | F3: 44002 | G3: TELECOM GTA JUN 2016 | I3: -36.9 | J3: -36.9 | K3: =_xlfn.XLOOKUP($C3,Table1[BusinessUnitID],Table1[BusinessUnit],"",0) -> FOOD SERVICE | L3: {=_xlfn.XLOOKUP($C3,Table1[[#All],[BusinessUnitID]],Table1[[#All],[Description]],"",0,1)} -> Transactions related to food and beverage service. Includes all guest transactions in the hotel restaurants, catering-related transactions and food service payroll. | M3: =_xlfn.XLOOKUP($B3,ChartOfAccounts!A2:A87,ChartOfAccounts!B2:B87,"",0,1) -> Operating Bank Account | N3: =_xlfn.XLOOKUP($B3,ChartOfAccounts!A2:A87,ChartOfAccounts!D2:D87,0,1) -> Assets | O3: =_xlfn.XLOOKUP($B3,ChartOfAccounts!A2:A87,ChartOfAccounts!F2:F87,"",0,1) -> Cash | P3: {=_xlfn.XLOOKUP($D3&$C3,PreparerInfo!A2:A14&PreparerInfo!C2:C14,PreparerInfo!B2:B14,"",0,1)} -> Carolyn Slater|Food Operations Manager | Q3: =_xlfn.XLOOKUP($E3,Source!A2:A10,Source!B2:B10,"",0,1) -> CHECK
A4: 2033521 | B4: 11845 | C4: 3 | D4: 102 | E4: 1001 | F4: 44002 | G4: CASH RECEIPTS | H4: 63.1 | J4: 63.1 | K4: =_xlfn.XLOOKUP($C4,Table1[BusinessUnitID],Table1[BusinessUnit],"",0) -> HOTEL PANTRY | L4: {=_xlfn.XLOOKUP($C4,Table1[[#All],[BusinessUnitID]],Table1[[#All],[Description]],"",0,1)} -> Transactions related to the hotel convenience store, including some food and beverage costs. | M4: =_xlfn.XLOOKUP($B4,ChartOfAccounts!A3:A88,ChartOfAccounts!B3:B88,"",0,1) -> Operating Bank Account | N4: =_xlfn.XLOOKUP($B4,ChartOfAccounts!A3:A88,ChartOfAccounts!D3:D88,0,1) -> Assets | O4: =_xlfn.XLOOKUP($B4,ChartOfAccounts!A3:A88,ChartOfAccounts!F3:F88,"",0,1) -> Cash | P4: {=_xlfn.XLOOKUP($D4&$C4,PreparerInfo!A3:A15&PreparerInfo!C3:C15,PreparerInfo!B3:B15,"",0,1)} -> POS | Q4: =_xlfn.XLOOKUP($E4,Source!A3:A11,Source!B3:B11,"",0,1)
A5: 2033521 | B5: 43440 | C5: 3 | D5: 102 | E5: 1001 | F5: 44002 | G5: CASH RECEIPTS | I5: -63.1 | J5: -63.1 | K5: =_xlfn.XLOOKUP($C5,Table1[BusinessUnitID],Table1[BusinessUnit],"",0) -> HOTEL PANTRY | L5: {=_xlfn.XLOOKUP($C5,Table1[[#All],[BusinessUnitID]],Table1[[#All],[Description]],"",0,1)} -> Transactions related to the hotel convenience store, including some food and beverage costs. | M5: =_xlfn.XLOOKUP($B5,ChartOfAccounts!A4:A89,ChartOfAccounts!B4:B89,"",0,1) -> Sales - Other | N5: =_xlfn.XLOOKUP($B5,ChartOfAccounts!A4:A89,ChartOfAccounts!D4:D89,0,1) -> Revenue | O5: =_xlfn.XLOOKUP($B5,ChartOfAccounts!A4:A89,ChartOfAccounts!F4:F89,"",0,1) -> Sales-Other | P5: {=_xlfn.XLOOKUP($D5&$C5,PreparerInfo!A4:A16&PreparerInfo!C4:C16,PreparerInfo!B4:B16,"",0,1)} -> POS | Q5: =_xlfn.XLOOKUP($E5,Source!A4:A12,Source!B4:B12,"",0,1)
A6: 2033522 | B6: 11845 | C6: 1 | D6: 102 | E6: 1003 | F6: 44002 | G6: CREDIT CARD RECEIPTS | H6: 68.28 | J6: 68.28 | K6: =_xlfn.XLOOKUP($C6,Table1[BusinessUnitID],Table1[BusinessUnit],"",0) -> FOOD SERVICE | L6: {=_xlfn.XLOOKUP($C6,Table1[[#All],[BusinessUnitID]],Table1[[#All],[Description]],"",0,1)} -> Transactions related to food and beverage service. Includes all guest transactions in the hotel restaurants, catering-related transactions and food service payroll. | M6: =_xlfn.XLOOKUP($B6,ChartOfAccounts!A5:A90,ChartOfAccounts!B5:B90,"",0,1) | N6: =_xlfn.XLOOKUP($B6,ChartOfAccounts!A5:A90,ChartOfAccounts!D5:D90,0,1) -> Assets | O6: =_xlfn.XLOOKUP($B6,ChartOfAccounts!A5:A90,ChartOfAccounts!F5:F90,"",0,1) | P6: {=_xlfn.XLOOKUP($D6&$C6,PreparerInfo!A5:A17&PreparerInfo!C5:C17,PreparerInfo!B5:B17,"",0,1)} -> Elizabeth Rees|Food Operations Manager | Q6: =_xlfn.XLOOKUP($E6,Source!A5:A13,Source!B5:B13,"",0,1)
A7: 2033522 | B7: 43310 | C7: 1 | D7: 102 | E7: 1003 | F7: 44002 | G7: CREDIT CARD RECEIPTS | I7: -68.28 | J7: -68.28 | K7: =_xlfn.XLOOKUP($C7,Table1[BusinessUnitID],Table1[BusinessUnit],"",0) -> FOOD SERVICE | L7: {=_xlfn.XLOOKUP($C7,Table1[[#All],[BusinessUnitID]],Table1[[#All],[Description]],"",0,1)} -> Transactions related to food and beverage service. Includes all guest transactions in the hotel restaurants, catering-related transactions and food service payroll. | M7: =_xlfn.XLOOKUP($B7,ChartOfAccounts!A6:A91,ChartOfAccounts!B6:B91,"",0,1) -> Sales - Dining Halls | N7: =_xlfn.XLOOKUP($B7,ChartOfAccounts!A6:A91,ChartOfAccounts!D6:D91,0,1) -> Revenue | O7: =_xlfn.XLOOKUP($B7,ChartOfAccounts!A6:A91,ChartOfAccounts!F6:F91,"",0,1) -> Sales-Dining | P7: {=_xlfn.XLOOKUP($D7&$C7,PreparerInfo!A6:A18&PreparerInfo!C6:C18,PreparerInfo!B6:B18,"",0,1)} -> Elizabeth Rees|Food Operations Manager | Q7: =_xlfn.XLOOKUP($E7,Source!A6:A14,Source!B6:B14,"",0,1)
A8: 2033523 | B8: 11845 | C8: 2 | D8: 106 | E8: 1003 | F8: 44002 | G8: CONFERENCE - HOTEL | H8: 99 | J8: 99 | K8: =_xlfn.XLOOKUP($C8,Table1[BusinessUnitID],Table1[BusinessUnit],"",0) -> HOTEL | L8: {=_xlfn.XLOOKUP($C8,Table1[[#All],[BusinessUnitID]],Table1[[#All],[Description]],"",0,1)} -> Transactions related to guest rooms and overall hotel operations. Includes payroll for administrative staff, clerks and interns. | M8: =_xlfn.XLOOKUP($B8,ChartOfAccounts!A7:A92,ChartOfAccounts!B7:B92,"",0,1) | N8: =_xlfn.XLOOKUP($B8,ChartOfAccounts!A7:A92,ChartOfAccounts!D7:D92,0,1) -> Assets | O8: =_xlfn.XLOOKUP($B8,ChartOfAccounts!A7:A92,ChartOfAccounts!F7:F92,"",0,1) | P8: {=_xlfn.XLOOKUP($D8&$C8,PreparerInfo!A7:A19&PreparerInfo!C7:C19,PreparerInfo!B7:B19,"",0,1)} -> Yvonne Chapman|Catering Manager | Q8: =_xlfn.XLOOKUP($E8,Source!A7:A15,Source!B7:B15,"",0,1)
A9: 2033523 | B9: 43180 | C9: 2 | D9: 106 | E9: 1003 | F9: 44002 | G9: CONFERENCE - HOTEL | I9: -99 | J9: -99 | K9: =_xlfn.XLOOKUP($C9,Table1[BusinessUnitID],Table1[BusinessUnit],"",0) -> HOTEL | L9: {=_xlfn.XLOOKUP($C9,Table1[[#All],[BusinessUnitID]],Table1[[#All],[Description]],"",0,1)} -> Transactions related to guest rooms and overall hotel operations. Includes payroll for administrative staff, clerks and interns. | M9: =_xlfn.XLOOKUP($B9,ChartOfAccounts!A8:A93,ChartOfAccounts!B8:B93,"",0,1) -> Rents - Hotels | N9: =_xlfn.XLOOKUP($B9,ChartOfAccounts!A8:A93,ChartOfAccounts!D8:D93,0,1) -> Revenue | O9: =_xlfn.XLOOKUP($B9,ChartOfAccounts!A8:A93,ChartOfAccounts!F8:F93,"",0,1) -> Sales-Hotel | P9: {=_xlfn.XLOOKUP($D9&$C9,PreparerInfo!A8:A20&PreparerInfo!C8:C20,PreparerInfo!B8:B20,"",0,1)} -> Yvonne Chapman|Catering Manager | Q9: =_xlfn.XLOOKUP($E9,Source!A8:A16,Source!B8:B16,"",0,1)
A10: 2033524 | B10: 11845 | C10: 3 | D10: 102 | E10: 1003 | F10: 44002 | G10: CREDIT CARD RECEIPTS | H10: 107.21 | J10: 107.21 | K10: =_xlfn.XLOOKUP($C10,Table1[BusinessUnitID],Table1[BusinessUnit],"",0) -> HOTEL PANTRY | L10: {=_xlfn.XLOOKUP($C10,Table1[[#All],[BusinessUnitID]],Table1[[#All],[Description]],"",0,1)} -> Transactions related to the hotel convenience store, including some food and beverage costs. | M10: =_xlfn.XLOOKUP($B10,ChartOfAccounts!A9:A94,ChartOfAccounts!B9:B94,"",0,1) | N10: =_xlfn.XLOOKUP($B10,ChartOfAccounts!A9:A94,ChartOfAccounts!D9:D94,0,1) -> Assets | O10: =_xlfn.XLOOKUP($B10,ChartOfAccounts!A9:A94,ChartOfAccounts!F9:F94,"",0,1) | P10: {=_xlfn.XLOOKUP($D10&$C10,PreparerInfo!A9:A21&PreparerInfo!C9:C21,PreparerInfo!B9:B21,"",0,1)} -> POS | Q10: =_xlfn.XLOOKUP($E10,Source!A9:A17,Source!B9:B17,"",0,1)
A11: 2033524 | B11: 43440 | C11: 3 | D11: 102 | E11: 1003 | F11: 44002 | G11: CREDIT CARD RECEIPTS | I11: -107.21 | J11: -107.21 | K11: =_xlfn.XLOOKUP($C11,Table1[BusinessUnitID],Table1[BusinessUnit],"",0) -> HOTEL PANTRY | L11: {=_xlfn.XLOOKUP($C11,Table1[[#All],[BusinessUnitID]],Table1[[#All],[Description]],"",0,1)} -> Transactions related to the hotel convenience store, including some food and beverage costs. | M11: =_xlfn.XLOOKUP($B11,ChartOfAccounts!A10:A95,ChartOfAccounts!B10:B95,"",0,1) -> Sales - Other | N11: =_xlfn.XLOOKUP($B11,ChartOfAccounts!A10:A95,ChartOfAccounts!D10:D95,0,1) -> Revenue | O11: =_xlfn.XLOOKUP($B11,ChartOfAccounts!A10:A95,ChartOfAccounts!F10:F95,"",0,1) -> Sales-Other | P11: {=_xlfn.XLOOKUP($D11&$C11,PreparerInfo!A10:A22&PreparerInfo!C10:C22,PreparerInfo!B10:B22,"",0,1)} | Q11: =_xlfn.XLOOKUP($E11,Source!A10:A18,Source!B10:B18,"",0,1)
A12: 2033525 | B12: 11845 | C12: 2 | D12: 104 | E12: 1003 | F12: 44002 | G12: HENDERSON,KENNY | H12: 129 | J12: 129 | K12: =_xlfn.XLOOKUP($C12,Table1[BusinessUnitID],Table1[BusinessUnit],"",0) -> HOTEL | L12: {=_xlfn.XLOOKUP($C12,Table1[[#All],[BusinessUnitID]],Table1[[#All],[Description]],"",0,1)} -> Transactions related to guest rooms and overall hotel operations. Includes payroll for administrative staff, clerks and interns. | M12: =_xlfn.XLOOKUP($B12,ChartOfAccounts!A11:A96,ChartOfAccounts!B11:B96,"",0,1) | N12: =_xlfn.XLOOKUP($B12,ChartOfAccounts!A11:A96,ChartOfAccounts!D11:D96,0,1) -> Assets | O12: =_xlfn.XLOOKUP($B12,ChartOfAccounts!A11:A96,ChartOfAccounts!F11:F96,"",0,1) | P12: {=_xlfn.XLOOKUP($D12&$C12,PreparerInfo!A11:A23&PreparerInfo!C11:C23,PreparerInfo!B11:B23,"",0,1)} -> GUESTSYS | Q12: =_xlfn.XLOOKUP($E12,Source!A11:A19,Source!B11:B19,"",0,1)
A13: 2033525 | B13: 43180 | C13: 2 | D13: 104 | E13: 1003 | F13: 44002 | G13: HENDERSON,KENNY | I13: -129 | J13: -129 | K13: =_xlfn.XLOOKUP($C13,Table1[BusinessUnitID],Table1[BusinessUnit],"",0) -> HOTEL | L13: {=_xlfn.XLOOKUP($C13,Table1[[#All],[BusinessUnitID]],Table1[[#All],[Description]],"",0,1)} -> Transactions related to guest rooms and overall hotel operations. Includes payroll for administrative staff, clerks and interns. | M13: =_xlfn.XLOOKUP($B13,ChartOfAccounts!A12:A97,ChartOfAccounts!B12:B97,"",0,1) -> Rents - Hotels | N13: =_xlfn.XLOOKUP($B13,ChartOfAccounts!A12:A97,ChartOfAccounts!D12:D97,0,1) -> Revenue | O13: =_xlfn.XLOOKUP($B13,ChartOfAccounts!A12:A97,ChartOfAccounts!F12:F97,"",0,1) -> Sales-Hotel | P13: {=_xlfn.XLOOKUP($D13&$C13,PreparerInfo!A12:A24&PreparerInfo!C12:C24,PreparerInfo!B12:B24,"",0,1)} | Q13: =_xlfn.XLOOKUP($E13,Source!A12:A20,Source!B12:B20,"",0,1)
A14: 2033526 | B14: 11845 | C14: 2 | D14: 104 | E14: 1003 | F14: 44002 | G14: GENTRY,NIA | H14: 258 | J14: 258 | K14: =_xlfn.XLOOKUP($C14,Table1[BusinessUnitID],Table1[BusinessUnit],"",0) -> HOTEL | L14: {=_xlfn.XLOOKUP($C14,Table1[[#All],[BusinessUnitID]],Table1[[#All],[Description]],"",0,1)} -> Transactions related to guest rooms and overall hotel operations. Includes payroll for administrative staff, clerks and interns. | M14: =_xlfn.XLOOKUP($B14,ChartOfAccounts!A13:A98,ChartOfAccounts!B13:B98,"",0,1) | N14: =_xlfn.XLOOKUP($B14,ChartOfAccounts!A13:A98,ChartOfAccounts!D13:D98,0,1) -> Assets | O14: =_xlfn.XLOOKUP($B14,ChartOfAccounts!A13:A98,ChartOfAccounts!F13:F98,"",0,1) | P14: {=_xlfn.XLOOKUP($D14&$C14,PreparerInfo!A13:A25&PreparerInfo!C13:C25,PreparerInfo!B13:B25,"",0,1)} | Q14: =_xlfn.XLOOKUP($E14,Source!A13:A21,Source!B13:B21,"",0,1)
A15: 2033526 | B15: 43180 | C15: 2 | D15: 104 | E15: 1003 | F15: 44002 | G15: GENTRY,NIA | I15: -258 | J15: -258 | K15: =_xlfn.XLOOKUP($C15,Table1[BusinessUnitID],Table1[BusinessUnit],"",0) -> HOTEL | L15: {=_xlfn.XLOOKUP($C15,Table1[[#All],[BusinessUnitID]],Table1[[#All],[Description]],"",0,1)} -> Transactions related to guest rooms and overall hotel operations. Includes payroll for administrative staff, clerks and interns. | M15: =_xlfn.XLOOKUP($B15,ChartOfAccounts!A14:A99,ChartOfAccounts!B14:B99,"",0,1) -> Rents - Hotels | N15: =_xlfn.XLOOKUP($B15,ChartOfAccounts!A14:A99,ChartOfAccounts!D14:D99,0,1) -> Revenue | O15: =_xlfn.XLOOKUP($B15,ChartOfAccounts!A14:A99,ChartOfAccounts!F14:F99,"",0,1) -> Sales-Hotel | P15: {=_xlfn.XLOOKUP($D15&$C15,PreparerInfo!A14:A26&PreparerInfo!C14:C26,PreparerInfo!B14:B26,"",0,1)} | Q15: =_xlfn.XLOOKUP($E15,Source!A14:A22,Source!B14:B22,"",0,1)
A16: 2033527 | B16: 11845 | C16: 2 | D16: 104 | E16: 1003 | F16: 44002 | G16: HODGES,CHAYA | H16: 418 | J16: 418 | K16: =_xlfn.XLOOKUP($C16,Table1[BusinessUnitID],Table1[BusinessUnit],"",0) -> HOTEL | L16: {=_xlfn.XLOOKUP($C16,Table1[[#All],[BusinessUnitID]],Table1[[#All],[Description]],"",0,1)} -> Transactions related to guest rooms and overall hotel operations. Includes payroll for administrative staff, clerks and interns. | M16: =_xlfn.XLOOKUP($B16,ChartOfAccounts!A15:A100,ChartOfAccounts!B15:B100,"",0,1) | N16: =_xlfn.XLOOKUP($B16,ChartOfAccounts!A15:A100,ChartOfAccounts!D15:D100,0,1) -> Liabilities | O16: =_xlfn.XLOOKUP($B16,ChartOfAccounts!A15:A100,ChartOfAccounts!F15:F100,"",0,1) | P16: {=_xlfn.XLOOKUP($D16&$C16,PreparerInfo!A15:A27&PreparerInfo!C15:C27,PreparerInfo!B15:B27,"",0,1)} | Q16: =_xlfn.XLOOKUP($E16,Source!A15:A23,Source!B15:B23,"",0,1)
A17: 2033527 | B17: 43180 | C17: 2 | D17: 104 | E17: 1003 | F17: 44002 | G17: HODGES,CHAYA | I17: -418 | J17: -418 | K17: =_xlfn.XLOOKUP($C17,Table1[BusinessUnitID],Table1[BusinessUnit],"",0) -> HOTEL | L17: {=_xlfn.XLOOKUP($C17,Table1[[#All],[BusinessUnitID]],Table1[[#All],[Description]],"",0,1)} -> Transactions related to guest rooms and overall hotel operations. Includes payroll for administrative staff, clerks and interns. | M17: =_xlfn.XLOOKUP($B17,ChartOfAccounts!A16:A101,ChartOfAccounts!B16:B101,"",0,1) -> Rents - Hotels | N17: =_xlfn.XLOOKUP($B17,ChartOfAccounts!A16:A101,ChartOfAccounts!D16:D101,0,1) -> Revenue | O17: =_xlfn.XLOOKUP($B17,ChartOfAccounts!A16:A101,ChartOfAccounts!F16:F101,"",0,1) -> Sales-Hotel | P17: {=_xlfn.XLOOKUP($D17&$C17,PreparerInfo!A16:A28&PreparerInfo!C16:C28,PreparerInfo!B16:B28,"",0,1)} | Q17: =_xlfn.XLOOKUP($E17,Source!A16:A24,Source!B16:B24,"",0,1)
