Workbook

Sheet Case 3 solution
D1: Solution using formulas | K1: Solution using FlashFill, TYPE MANUALLY FOR THE FIRST 2 SAMPLES , CTRL+E
A2: EmployeeCode | B2: FirstName | C2: LastName | D2: Location | E2: EmpID | F2: Plant ID | G2: Pay Period | H2: LocationPlantID | J2: EmployeeCode | K2: Location | L2: EmpID | M2: Plant ID | N2: Pay Period | O2: LocationPlantID
A3: ='Case 3 data'!A2 -> Japan177-3Mo | B3: ='Case 3 data'!B2 -> Carl | C3: ='Case 3 data'!C2 -> Rodriguez | D3: {=LEFT($A3,MIN(FIND({0;1;2;3;4;5;6;7;8;9},$A3&"0123456789"))-1)} -> Japan | E3: {=MID($A3,MIN(FIND({0;1;2;3;4;5;6;7;8;9},$A3&"0123456789")),FIND("-",$A3)-MIN(FIND({0;1;2;3;4;5;6;7;8;9},$A3&"0123456789")))} -> 177 | F3: =MID($A3,FIND("-",$A3)+1,LEN($A3)-FIND("-",$A3)-LEN($G3)) -> 3 | G3: =IF(RIGHT($A3,2)="Mo","Mo",RIGHT($A3,1)) -> Mo | H3: =D3&"-"&F3 -> Japan-3 | J3: Japan177-3Mo | K3: Japan | L3: 177 | M3: 3 | N3: Mo | O3: Japan-3
A4: ='Case 3 data'!A3 -> AUS551-2Mo | B4: ='Case 3 data'!B3 -> Anne | C4: ='Case 3 data'!C3 -> Wright | D4: {=LEFT($A4,MIN(FIND({0;1;2;3;4;5;6;7;8;9},$A4&"0123456789"))-1)} -> AUS | E4: {=MID($A4,MIN(FIND({0;1;2;3;4;5;6;7;8;9},$A4&"0123456789")),FIND("-",$A4)-MIN(FIND({0;1;2;3;4;5;6;7;8;9},$A4&"0123456789")))} -> 551 | F4: =MID($A4,FIND("-",$A4)+1,LEN($A4)-FIND("-",$A4)-LEN($G4)) -> 2 | G4: =IF(RIGHT($A4,2)="Mo","Mo",RIGHT($A4,1)) -> Mo | H4: =D4&"-"&F4 -> AUS-2 | J4: AUS551-2Mo | K4: =LEFT(A4,3) -> AUS | L4: 551 | M4: 2 | N4: Mo | O4: AUS-2
A5: ='Case 3 data'!A4 -> AUS316-2M | B5: ='Case 3 data'!B4 -> Patrick | C5: ='Case 3 data'!C4 -> Rivera | D5: {=LEFT($A5,MIN(FIND({0;1;2;3;4;5;6;7;8;9},$A5&"0123456789"))-1)} -> AUS | E5: {=MID($A5,MIN(FIND({0;1;2;3;4;5;6;7;8;9},$A5&"0123456789")),FIND("-",$A5)-MIN(FIND({0;1;2;3;4;5;6;7;8;9},$A5&"0123456789")))} -> 316 | F5: =MID($A5,FIND("-",$A5)+1,LEN($A5)-FIND("-",$A5)-LEN($G5)) -> 2 | G5: =IF(RIGHT($A5,2)="Mo","Mo",RIGHT($A5,1)) -> M | H5: =D5&"-"&F5 -> AUS-2 | J5: AUS316-2M | K5: AUS | L5: 316 | M5: 2 | N5: M | O5: AUS-2
A6: ='Case 3 data'!A5 -> GER160-2W | B6: ='Case 3 data'!B5 -> Ruby | C6: ='Case 3 data'!C5 -> Walker | D6: {=LEFT($A6,MIN(FIND({0;1;2;3;4;5;6;7;8;9},$A6&"0123456789"))-1)} -> GER | E6: {=MID($A6,MIN(FIND({0;1;2;3;4;5;6;7;8;9},$A6&"0123456789")),FIND("-",$A6)-MIN(FIND({0;1;2;3;4;5;6;7;8;9},$A6&"0123456789")))} -> 160 | F6: =MID($A6,FIND("-",$A6)+1,LEN($A6)-FIND("-",$A6)-LEN($G6)) -> 2 | G6: =IF(RIGHT($A6,2)="Mo","Mo",RIGHT($A6,1)) -> W | H6: =D6&"-"&F6 -> GER-2 | J6: GER160-2W | K6: GER | L6: 160 | M6: 2 | N6: W | O6: GER-2
A7: ='Case 3 data'!A6 -> GER265-1M | B7: ='Case 3 data'!B6 -> Teresita | C7: ='Case 3 data'!C6 -> Guillen | D7: {=LEFT($A7,MIN(FIND({0;1;2;3;4;5;6;7;8;9},$A7&"0123456789"))-1)} -> GER | E7: {=MID($A7,MIN(FIND({0;1;2;3;4;5;6;7;8;9},$A7&"0123456789")),FIND("-",$A7)-MIN(FIND({0;1;2;3;4;5;6;7;8;9},$A7&"0123456789")))} -> 265 | F7: =MID($A7,FIND("-",$A7)+1,LEN($A7)-FIND("-",$A7)-LEN($G7)) -> 1 | G7: =IF(RIGHT($A7,2)="Mo","Mo",RIGHT($A7,1)) -> M | H7: =D7&"-"&F7 -> GER-1 | J7: GER265-1M | K7: GER | L7: 265 | M7: 1 | N7: M | O7: GER-1
A8: ='Case 3 data'!A7 -> ARG363-4Mo | B8: ='Case 3 data'!B7 -> Earl | C8: ='Case 3 data'!C7 -> Morgan | D8: {=LEFT($A8,MIN(FIND({0;1;2;3;4;5;6;7;8;9},$A8&"0123456789"))-1)} -> ARG | E8: {=MID($A8,MIN(FIND({0;1;2;3;4;5;6;7;8;9},$A8&"0123456789")),FIND("-",$A8)-MIN(FIND({0;1;2;3;4;5;6;7;8;9},$A8&"0123456789")))} -> 363 | F8: =MID($A8,FIND("-",$A8)+1,LEN($A8)-FIND("-",$A8)-LEN($G8)) -> 4 | G8: =IF(RIGHT($A8,2)="Mo","Mo",RIGHT($A8,1)) -> Mo | H8: =D8&"-"&F8 -> ARG-4 | J8: ARG363-4Mo | K8: Japan | L8: 363 | M8: 4 | N8: Mo | O8: Japan-4
A9: ='Case 3 data'!A8 -> Canada351-3W | B9: ='Case 3 data'!B8 -> Joella | C9: ='Case 3 data'!C8 -> Causey | D9: {=LEFT($A9,MIN(FIND({0;1;2;3;4;5;6;7;8;9},$A9&"0123456789"))-1)} -> Canada | E9: {=MID($A9,MIN(FIND({0;1;2;3;4;5;6;7;8;9},$A9&"0123456789")),FIND("-",$A9)-MIN(FIND({0;1;2;3;4;5;6;7;8;9},$A9&"0123456789")))} -> 351 | F9: =MID($A9,FIND("-",$A9)+1,LEN($A9)-FIND("-",$A9)-LEN($G9)) -> 3 | G9: =IF(RIGHT($A9,2)="Mo","Mo",RIGHT($A9,1)) -> W | H9: =D9&"-"&F9 -> Canada-3 | J9: Canada351-3W | K9: =LEFT(A9,3) -> Can | L9: 351 | M9: 3 | N9: W | O9: Can-3
A10: ='Case 3 data'!A9 -> Japan195-5W | B10: ='Case 3 data'!B9 -> Gregg | C10: ='Case 3 data'!C9 -> Kelly | D10: {=LEFT($A10,MIN(FIND({0;1;2;3;4;5;6;7;8;9},$A10&"0123456789"))-1)} -> Japan | E10: {=MID($A10,MIN(FIND({0;1;2;3;4;5;6;7;8;9},$A10&"0123456789")),FIND("-",$A10)-MIN(FIND({0;1;2;3;4;5;6;7;8;9},$A10&"0123456789")))} -> 195 | F10: =MID($A10,FIND("-",$A10)+1,LEN($A10)-FIND("-",$A10)-LEN($G10)) -> 5 | G10: =IF(RIGHT($A10,2)="Mo","Mo",RIGHT($A10,1)) -> W | H10: =D10&"-"&F10 -> Japan-5 | J10: Japan195-5W | K10: AUS | L10: 195 | M10: 5 | N10: W | O10: AUS-5
A11: ='Case 3 data'!A10 -> ARG529-1W | B11: ='Case 3 data'!B10 -> William | C11: ='Case 3 data'!C10 -> Reed | D11: {=LEFT($A11,MIN(FIND({0;1;2;3;4;5;6;7;8;9},$A11&"0123456789"))-1)} -> ARG | E11: {=MID($A11,MIN(FIND({0;1;2;3;4;5;6;7;8;9},$A11&"0123456789")),FIND("-",$A11)-MIN(FIND({0;1;2;3;4;5;6;7;8;9},$A11&"0123456789")))} -> 529 | F11: =MID($A11,FIND("-",$A11)+1,LEN($A11)-FIND("-",$A11)-LEN($G11)) -> 1 | G11: =IF(RIGHT($A11,2)="Mo","Mo",RIGHT($A11,1)) -> W | H11: =D11&"-"&F11 -> ARG-1 | J11: ARG529-1W | K11: GER | L11: 529 | M11: 1 | N11: W | O11: GER-1
A12: ='Case 3 data'!A11 -> ENG301-6W | B12: ='Case 3 data'!B11 -> Julia | C12: ='Case 3 data'!C11 -> Johnson | D12: {=LEFT($A12,MIN(FIND({0;1;2;3;4;5;6;7;8;9},$A12&"0123456789"))-1)} -> ENG | E12: {=MID($A12,MIN(FIND({0;1;2;3;4;5;6;7;8;9},$A12&"0123456789")),FIND("-",$A12)-MIN(FIND({0;1;2;3;4;5;6;7;8;9},$A12&"0123456789")))} -> 301 | F12: =MID($A12,FIND("-",$A12)+1,LEN($A12)-FIND("-",$A12)-LEN($G12)) -> 6 | G12: =IF(RIGHT($A12,2)="Mo","Mo",RIGHT($A12,1)) -> W | H12: =D12&"-"&F12 -> ENG-6 | J12: ENG301-6W | K12: GER | L12: 301 | M12: 6 | N12: W | O12: GER-6
A13: ='Case 3 data'!A12 -> AUS60-2M | B13: ='Case 3 data'!B12 -> Tonya | C13: ='Case 3 data'!C12 -> Ruiz | D13: {=LEFT($A13,MIN(FIND({0;1;2;3;4;5;6;7;8;9},$A13&"0123456789"))-1)} -> AUS | E13: {=MID($A13,MIN(FIND({0;1;2;3;4;5;6;7;8;9},$A13&"0123456789")),FIND("-",$A13)-MIN(FIND({0;1;2;3;4;5;6;7;8;9},$A13&"0123456789")))} -> 60 | F13: =MID($A13,FIND("-",$A13)+1,LEN($A13)-FIND("-",$A13)-LEN($G13)) -> 2 | G13: =IF(RIGHT($A13,2)="Mo","Mo",RIGHT($A13,1)) -> M | H13: =D13&"-"&F13 -> AUS-2 | J13: AUS60-2M | K13: Japan | L13: 60 | M13: 2 | N13: M | O13: Japan-2
A14: ='Case 3 data'!A13 -> ARG102-7Mo | B14: ='Case 3 data'!B13 -> Wayne | C14: ='Case 3 data'!C13 -> Howard | D14: {=LEFT($A14,MIN(FIND({0;1;2;3;4;5;6;7;8;9},$A14&"0123456789"))-1)} -> ARG | E14: {=MID($A14,MIN(FIND({0;1;2;3;4;5;6;7;8;9},$A14&"0123456789")),FIND("-",$A14)-MIN(FIND({0;1;2;3;4;5;6;7;8;9},$A14&"0123456789")))} -> 102 | F14: =MID($A14,FIND("-",$A14)+1,LEN($A14)-FIND("-",$A14)-LEN($G14)) -> 7 | G14: =IF(RIGHT($A14,2)="Mo","Mo",RIGHT($A14,1)) -> Mo | H14: =D14&"-"&F14 -> ARG-7 | J14: ARG102-7Mo | K14: =LEFT(A14,3) -> ARG | L14: 102 | M14: 7 | N14: Mo | O14: ARG-7
A15: ='Case 3 data'!A14 -> US219-8M | B15: ='Case 3 data'!B14 -> Samuel | C15: ='Case 3 data'!C14 -> Goodman | D15: {=LEFT($A15,MIN(FIND({0;1;2;3;4;5;6;7;8;9},$A15&"0123456789"))-1)} -> US | E15: {=MID($A15,MIN(FIND({0;1;2;3;4;5;6;7;8;9},$A15&"0123456789")),FIND("-",$A15)-MIN(FIND({0;1;2;3;4;5;6;7;8;9},$A15&"0123456789")))} -> 219 | F15: =MID($A15,FIND("-",$A15)+1,LEN($A15)-FIND("-",$A15)-LEN($G15)) -> 8 | G15: =IF(RIGHT($A15,2)="Mo","Mo",RIGHT($A15,1)) -> M | H15: =D15&"-"&F15 -> US-8 | J15: US219-8M | K15: AUS | L15: 219 | M15: 8 | N15: M | O15: AUS-8
A16: ='Case 3 data'!A15 -> Canada342-9W | B16: ='Case 3 data'!B15 -> Sean | C16: ='Case 3 data'!C15 -> Morgan | D16: {=LEFT($A16,MIN(FIND({0;1;2;3;4;5;6;7;8;9},$A16&"0123456789"))-1)} -> Canada | E16: {=MID($A16,MIN(FIND({0;1;2;3;4;5;6;7;8;9},$A16&"0123456789")),FIND("-",$A16)-MIN(FIND({0;1;2;3;4;5;6;7;8;9},$A16&"0123456789")))} -> 342 | F16: =MID($A16,FIND("-",$A16)+1,LEN($A16)-FIND("-",$A16)-LEN($G16)) -> 9 | G16: =IF(RIGHT($A16,2)="Mo","Mo",RIGHT($A16,1)) -> W | H16: =D16&"-"&F16 -> Canada-9 | J16: Canada342-9W | K16: GER | L16: 342 | M16: 9 | N16: W | O16: GER-9
A17: ='Case 3 data'!A16 -> US476-10W | B17: ='Case 3 data'!B16 -> Julie | C17: ='Case 3 data'!C16 -> Johnson | D17: {=LEFT($A17,MIN(FIND({0;1;2;3;4;5;6;7;8;9},$A17&"0123456789"))-1)} -> US | E17: {=MID($A17,MIN(FIND({0;1;2;3;4;5;6;7;8;9},$A17&"0123456789")),FIND("-",$A17)-MIN(FIND({0;1;2;3;4;5;6;7;8;9},$A17&"0123456789")))} -> 476 | F17: =MID($A17,FIND("-",$A17)+1,LEN($A17)-FIND("-",$A17)-LEN($G17)) -> 10 | G17: =IF(RIGHT($A17,2)="Mo","Mo",RIGHT($A17,1)) -> W | H17: =D17&"-"&F17 -> US-10 | J17: US476-10W | K17: GER | L17: 476 | M17: 10 | N17: W | O17: GER-10
A18: ='Case 3 data'!A17 -> MEX93-5M | B18: ='Case 3 data'!B17 -> Samuel | C18: ='Case 3 data'!C17 -> Perry | D18: {=LEFT($A18,MIN(FIND({0;1;2;3;4;5;6;7;8;9},$A18&"0123456789"))-1)} -> MEX | E18: {=MID($A18,MIN(FIND({0;1;2;3;4;5;6;7;8;9},$A18&"0123456789")),FIND("-",$A18)-MIN(FIND({0;1;2;3;4;5;6;7;8;9},$A18&"0123456789")))} -> 93 | F18: =MID($A18,FIND("-",$A18)+1,LEN($A18)-FIND("-",$A18)-LEN($G18)) -> 5 | G18: =IF(RIGHT($A18,2)="Mo","Mo",RIGHT($A18,1)) -> M | H18: =D18&"-"&F18 -> MEX-5 | J18: MEX93-5M | K18: Japan | L18: 93 | M18: 5 | N18: M | O18: Japan-5
A19: ='Case 3 data'!A18 -> ENG442-9Mo | B19: ='Case 3 data'!B18 -> Jarrod | C19: ='Case 3 data'!C18 -> Beckett | D19: {=LEFT($A19,MIN(FIND({0;1;2;3;4;5;6;7;8;9},$A19&"0123456789"))-1)} -> ENG | E19: {=MID($A19,MIN(FIND({0;1;2;3;4;5;6;7;8;9},$A19&"0123456789")),FIND("-",$A19)-MIN(FIND({0;1;2;3;4;5;6;7;8;9},$A19&"0123456789")))} -> 442 | F19: =MID($A19,FIND("-",$A19)+1,LEN($A19)-FIND("-",$A19)-LEN($G19)) -> 9 | G19: =IF(RIGHT($A19,2)="Mo","Mo",RIGHT($A19,1)) -> Mo | H19: =D19&"-"&F19 -> ENG-9 | J19: ENG442-9Mo | K19: =LEFT(A19,3) -> ENG | L19: 442 | M19: 9 | N19: Mo | O19: ENG-9
A20: ='Case 3 data'!A19 -> Canada17-7W | B20: ='Case 3 data'!B19 -> Lillian | C20: ='Case 3 data'!C19 -> Nelson | D20: {=LEFT($A20,MIN(FIND({0;1;2;3;4;5;6;7;8;9},$A20&"0123456789"))-1)} -> Canada | E20: {=MID($A20,MIN(FIND({0;1;2;3;4;5;6;7;8;9},$A20&"0123456789")),FIND("-",$A20)-MIN(FIND({0;1;2;3;4;5;6;7;8;9},$A20&"0123456789")))} -> 17 | F20: =MID($A20,FIND("-",$A20)+1,LEN($A20)-FIND("-",$A20)-LEN($G20)) -> 7 | G20: =IF(RIGHT($A20,2)="Mo","Mo",RIGHT($A20,1)) -> W | H20: =D20&"-"&F20 -> Canada-7 | J20: Canada17-7W | K20: AUS | L20: 17 | M20: 7 | N20: W | O20: AUS-7
A21: ='Case 3 data'!A20 -> ARG559-10W | B21: ='Case 3 data'!B20 -> Delfina | C21: ='Case 3 data'!C20 -> Brandon | D21: {=LEFT($A21,MIN(FIND({0;1;2;3;4;5;6;7;8;9},$A21&"0123456789"))-1)} -> ARG | E21: {=MID($A21,MIN(FIND({0;1;2;3;4;5;6;7;8;9},$A21&"0123456789")),FIND("-",$A21)-MIN(FIND({0;1;2;3;4;5;6;7;8;9},$A21&"0123456789")))} -> 559 | F21: =MID($A21,FIND("-",$A21)+1,LEN($A21)-FIND("-",$A21)-LEN($G21)) -> 10 | G21: =IF(RIGHT($A21,2)="Mo","Mo",RIGHT($A21,1)) -> W | H21: =D21&"-"&F21 -> ARG-10 | J21: ARG559-10W | K21: GER | L21: 559 | M21: 10 | N21: W | O21: GER-10
A22: ='Case 3 data'!A21 -> ENG389-10W | B22: ='Case 3 data'!B21 -> Shaun | C22: ='Case 3 data'!C21 -> Jacobs | D22: {=LEFT($A22,MIN(FIND({0;1;2;3;4;5;6;7;8;9},$A22&"0123456789"))-1)} -> ENG | E22: {=MID($A22,MIN(FIND({0;1;2;3;4;5;6;7;8;9},$A22&"0123456789")),FIND("-",$A22)-MIN(FIND({0;1;2;3;4;5;6;7;8;9},$A22&"0123456789")))} -> 389 | F22: =MID($A22,FIND("-",$A22)+1,LEN($A22)-FIND("-",$A22)-LEN($G22)) -> 10 | G22: =IF(RIGHT($A22,2)="Mo","Mo",RIGHT($A22,1)) -> W | H22: =D22&"-"&F22 -> ENG-10 | J22: ENG389-10W | K22: GER | L22: 389 | M22: 10 | N22: W | O22: GER-10
A23: ='Case 3 data'!A22 -> MEX121-11W | B23: ='Case 3 data'!B22 -> Theresa | C23: ='Case 3 data'!C22 -> Barnes | D23: {=LEFT($A23,MIN(FIND({0;1;2;3;4;5;6;7;8;9},$A23&"0123456789"))-1)} -> MEX | E23: {=MID($A23,MIN(FIND({0;1;2;3;4;5;6;7;8;9},$A23&"0123456789")),FIND("-",$A23)-MIN(FIND({0;1;2;3;4;5;6;7;8;9},$A23&"0123456789")))} -> 121 | F23: =MID($A23,FIND("-",$A23)+1,LEN($A23)-FIND("-",$A23)-LEN($G23)) -> 11 | G23: =IF(RIGHT($A23,2)="Mo","Mo",RIGHT($A23,1)) -> W | H23: =D23&"-"&F23 -> MEX-11 | J23: MEX121-11W | K23: Japan | L23: 121 | M23: 11 | N23: W | O23: Japan-11
A24: ='Case 3 data'!A23 -> ENG489-12W | B24: ='Case 3 data'!B23 -> Stephen | C24: ='Case 3 data'!C23 -> Powell | D24: {=LEFT($A24,MIN(FIND({0;1;2;3;4;5;6;7;8;9},$A24&"0123456789"))-1)} -> ENG | E24: {=MID($A24,MIN(FIND({0;1;2;3;4;5;6;7;8;9},$A24&"0123456789")),FIND("-",$A24)-MIN(FIND({0;1;2;3;4;5;6;7;8;9},$A24&"0123456789")))} -> 489 | F24: =MID($A24,FIND("-",$A24)+1,LEN($A24)-FIND("-",$A24)-LEN($G24)) -> 12 | G24: =IF(RIGHT($A24,2)="Mo","Mo",RIGHT($A24,1)) -> W | H24: =D24&"-"&F24 -> ENG-12 | J24: ENG489-12W | K24: =LEFT(A24,3) -> ENG | L24: 489 | M24: 12 | N24: W | O24: ENG-12
A25: ='Case 3 data'!A24 -> AUS88-10W | B25: ='Case 3 data'!B24 -> Queenie | C25: ='Case 3 data'!C24 -> Thibodeau | D25: {=LEFT($A25,MIN(FIND({0;1;2;3;4;5;6;7;8;9},$A25&"0123456789"))-1)} -> AUS | E25: {=MID($A25,MIN(FIND({0;1;2;3;4;5;6;7;8;9},$A25&"0123456789")),FIND("-",$A25)-MIN(FIND({0;1;2;3;4;5;6;7;8;9},$A25&"0123456789")))} -> 88 | F25: =MID($A25,FIND("-",$A25)+1,LEN($A25)-FIND("-",$A25)-LEN($G25)) -> 10 | G25: =IF(RIGHT($A25,2)="Mo","Mo",RIGHT($A25,1)) -> W | H25: =D25&"-"&F25 -> AUS-10 | J25: AUS88-10W | K25: AUS | L25: 88 | M25: 10 | N25: W | O25: AUS-10
A26: ='Case 3 data'!A25 -> AUS455-3W | B26: ='Case 3 data'!B25 -> Juan | C26: ='Case 3 data'!C25 -> King | D26: {=LEFT($A26,MIN(FIND({0;1;2;3;4;5;6;7;8;9},$A26&"0123456789"))-1)} -> AUS | E26: {=MID($A26,MIN(FIND({0;1;2;3;4;5;6;7;8;9},$A26&"0123456789")),FIND("-",$A26)-MIN(FIND({0;1;2;3;4;5;6;7;8;9},$A26&"0123456789")))} -> 455 | F26: =MID($A26,FIND("-",$A26)+1,LEN($A26)-FIND("-",$A26)-LEN($G26)) -> 3 | G26: =IF(RIGHT($A26,2)="Mo","Mo",RIGHT($A26,1)) -> W | H26: =D26&"-"&F26 -> AUS-3 | J26: AUS455-3W | K26: GER | L26: 455 | M26: 3 | N26: W | O26: GER-3
A27: ='Case 3 data'!A26 -> AUS491-13M | B27: ='Case 3 data'!B26 -> Laureen | C27: ='Case 3 data'!C26 -> Varney | D27: {=LEFT($A27,MIN(FIND({0;1;2;3;4;5;6;7;8;9},$A27&"0123456789"))-1)} -> AUS | E27: {=MID($A27,MIN(FIND({0;1;2;3;4;5;6;7;8;9},$A27&"0123456789")),FIND("-",$A27)-MIN(FIND({0;1;2;3;4;5;6;7;8;9},$A27&"0123456789")))} -> 491 | F27: =MID($A27,FIND("-",$A27)+1,LEN($A27)-FIND("-",$A27)-LEN($G27)) -> 13 | G27: =IF(RIGHT($A27,2)="Mo","Mo",RIGHT($A27,1)) -> M | H27: =D27&"-"&F27 -> AUS-13 | J27: AUS491-13M | K27: GER | L27: 491 | M27: 13 | N27: M | O27: GER-13
A28: ='Case 3 data'!A27 -> ENG193-10Mo | B28: ='Case 3 data'!B27 -> Anthony | C28: ='Case 3 data'!C27 -> Griffin | D28: {=LEFT($A28,MIN(FIND({0;1;2;3;4;5;6;7;8;9},$A28&"0123456789"))-1)} -> ENG | E28: {=MID($A28,MIN(FIND({0;1;2;3;4;5;6;7;8;9},$A28&"0123456789")),FIND("-",$A28)-MIN(FIND({0;1;2;3;4;5;6;7;8;9},$A28&"0123456789")))} -> 193 | F28: =MID($A28,FIND("-",$A28)+1,LEN($A28)-FIND("-",$A28)-LEN($G28)) -> 10 | G28: =IF(RIGHT($A28,2)="Mo","Mo",RIGHT($A28,1)) -> Mo | H28: =D28&"-"&F28 -> ENG-10 | J28: ENG193-10Mo | K28: Japan | L28: 193 | M28: 10 | N28: Mo | O28: Japan-10
A29: ='Case 3 data'!A28 -> ARG508-14W | B29: ='Case 3 data'!B28 -> Olga | C29: ='Case 3 data'!C28 -> Rowe | D29: {=LEFT($A29,MIN(FIND({0;1;2;3;4;5;6;7;8;9},$A29&"0123456789"))-1)} -> ARG | E29: {=MID($A29,MIN(FIND({0;1;2;3;4;5;6;7;8;9},$A29&"0123456789")),FIND("-",$A29)-MIN(FIND({0;1;2;3;4;5;6;7;8;9},$A29&"0123456789")))} -> 508 | F29: =MID($A29,FIND("-",$A29)+1,LEN($A29)-FIND("-",$A29)-LEN($G29)) -> 14 | G29: =IF(RIGHT($A29,2)="Mo","Mo",RIGHT($A29,1)) -> W | H29: =D29&"-"&F29 -> ARG-14 | J29: ARG508-14W | K29: =LEFT(A29,3) -> ARG | L29: 508 | M29: 14 | N29: W | O29: ARG-14
A30: ='Case 3 data'!A29 -> GER345-5M | B30: ='Case 3 data'!B29 -> Alyce | C30: ='Case 3 data'!C29 -> Rafferty | D30: {=LEFT($A30,MIN(FIND({0;1;2;3;4;5;6;7;8;9},$A30&"0123456789"))-1)} -> GER | E30: {=MID($A30,MIN(FIND({0;1;2;3;4;5;6;7;8;9},$A30&"0123456789")),FIND("-",$A30)-MIN(FIND({0;1;2;3;4;5;6;7;8;9},$A30&"0123456789")))} -> 345 | F30: =MID($A30,FIND("-",$A30)+1,LEN($A30)-FIND("-",$A30)-LEN($G30)) -> 5 | G30: =IF(RIGHT($A30,2)="Mo","Mo",RIGHT($A30,1)) -> M | H30: =D30&"-"&F30 -> GER-5 | J30: GER345-5M | K30: AUS | L30: 345 | M30: 5 | N30: M | O30: AUS-5
A31: ='Case 3 data'!A30 -> Japan428-2Mo | B31: ='Case 3 data'!B30 -> Janella | C31: ='Case 3 data'!C30 -> Lacey | D31: {=LEFT($A31,MIN(FIND({0;1;2;3;4;5;6;7;8;9},$A31&"0123456789"))-1)} -> Japan | E31: {=MID($A31,MIN(FIND({0;1;2;3;4;5;6;7;8;9},$A31&"0123456789")),FIND("-",$A31)-MIN(FIND({0;1;2;3;4;5;6;7;8;9},$A31&"0123456789")))} -> 428 | F31: =MID($A31,FIND("-",$A31)+1,LEN($A31)-FIND("-",$A31)-LEN($G31)) -> 2 | G31: =IF(RIGHT($A31,2)="Mo","Mo",RIGHT($A31,1)) -> Mo | H31: =D31&"-"&F31 -> Japan-2 | J31: Japan428-2Mo | K31: GER | L31: 428 | M31: 2 | N31: Mo | O31: GER-2
A32: ='Case 3 data'!A31 -> ARG116-9Mo | B32: ='Case 3 data'!B31 -> Lyndsay | C32: ='Case 3 data'!C31 -> Landry | D32: {=LEFT($A32,MIN(FIND({0;1;2;3;4;5;6;7;8;9},$A32&"0123456789"))-1)} -> ARG | E32: {=MID($A32,MIN(FIND({0;1;2;3;4;5;6;7;8;9},$A32&"0123456789")),FIND("-",$A32)-MIN(FIND({0;1;2;3;4;5;6;7;8;9},$A32&"0123456789")))} -> 116 | F32: =MID($A32,FIND("-",$A32)+1,LEN($A32)-FIND("-",$A32)-LEN($G32)) -> 9 | G32: =IF(RIGHT($A32,2)="Mo","Mo",RIGHT($A32,1)) -> Mo | H32: =D32&"-"&F32 -> ARG-9 | J32: ARG116-9Mo | K32: GER | L32: 116 | M32: 9 | N32: Mo | O32: GER-9
A33: ='Case 3 data'!A32 -> Canada213-4M | B33: ='Case 3 data'!B32 -> Elvina | C33: ='Case 3 data'!C32 -> Dickens | D33: {=LEFT($A33,MIN(FIND({0;1;2;3;4;5;6;7;8;9},$A33&"0123456789"))-1)} -> Canada | E33: {=MID($A33,MIN(FIND({0;1;2;3;4;5;6;7;8;9},$A33&"0123456789")),FIND("-",$A33)-MIN(FIND({0;1;2;3;4;5;6;7;8;9},$A33&"0123456789")))} -> 213 | F33: =MID($A33,FIND("-",$A33)+1,LEN($A33)-FIND("-",$A33)-LEN($G33)) -> 4 | G33: =IF(RIGHT($A33,2)="Mo","Mo",RIGHT($A33,1)) -> M | H33: =D33&"-"&F33 -> Canada-4 | J33: Canada213-4M | K33: Japan | L33: 213 | M33: 4 | N33: M | O33: Japan-4
A34: ='Case 3 data'!A33 -> ENG208-2W | B34: ='Case 3 data'!B33 -> Lois | C34: ='Case 3 data'!C33 -> Flores | D34: {=LEFT($A34,MIN(FIND({0;1;2;3;4;5;6;7;8;9},$A34&"0123456789"))-1)} -> ENG | E34: {=MID($A34,MIN(FIND({0;1;2;3;4;5;6;7;8;9},$A34&"0123456789")),FIND("-",$A34)-MIN(FIND({0;1;2;3;4;5;6;7;8;9},$A34&"0123456789")))} -> 208 | F34: =MID($A34,FIND("-",$A34)+1,LEN($A34)-FIND("-",$A34)-LEN($G34)) -> 2 | G34: =IF(RIGHT($A34,2)="Mo","Mo",RIGHT($A34,1)) -> W | H34: =D34&"-"&F34 -> ENG-2 | J34: ENG208-2W | K34: =LEFT(A34,3) -> ENG | L34: 208 | M34: 2 | N34: W | O34: ENG-2
A35: ='Case 3 data'!A34 -> MEX7-9M | B35: ='Case 3 data'!B34 -> Gonzalo | C35: ='Case 3 data'!C34 -> Rigby | D35: {=LEFT($A35,MIN(FIND({0;1;2;3;4;5;6;7;8;9},$A35&"0123456789"))-1)} -> MEX | E35: {=MID($A35,MIN(FIND({0;1;2;3;4;5;6;7;8;9},$A35&"0123456789")),FIND("-",$A35)-MIN(FIND({0;1;2;3;4;5;6;7;8;9},$A35&"0123456789")))} -> 7 | F35: =MID($A35,FIND("-",$A35)+1,LEN($A35)-FIND("-",$A35)-LEN($G35)) -> 9 | G35: =IF(RIGHT($A35,2)="Mo","Mo",RIGHT($A35,1)) -> M | H35: =D35&"-"&F35 -> MEX-9 | J35: MEX7-9M | K35: AUS | L35: 7 | M35: 9 | N35: M | O35: AUS-9
A36: ='Case 3 data'!A35 -> ARG56-15W | B36: ='Case 3 data'!B35 -> John | C36: ='Case 3 data'!C35 -> Parker | D36: {=LEFT($A36,MIN(FIND({0;1;2;3;4;5;6;7;8;9},$A36&"0123456789"))-1)} -> ARG | E36: {=MID($A36,MIN(FIND({0;1;2;3;4;5;6;7;8;9},$A36&"0123456789")),FIND("-",$A36)-MIN(FIND({0;1;2;3;4;5;6;7;8;9},$A36&"0123456789")))} -> 56 | F36: =MID($A36,FIND("-",$A36)+1,LEN($A36)-FIND("-",$A36)-LEN($G36)) -> 15 | G36: =IF(RIGHT($A36,2)="Mo","Mo",RIGHT($A36,1)) -> W | H36: =D36&"-"&F36 -> ARG-15 | J36: ARG56-15W | K36: GER | L36: 56 | M36: 15 | N36: W | O36: GER-15
A37: ='Case 3 data'!A36 -> US404-6W | B37: ='Case 3 data'!B36 -> Olive | C37: ='Case 3 data'!C36 -> Romero | D37: {=LEFT($A37,MIN(FIND({0;1;2;3;4;5;6;7;8;9},$A37&"0123456789"))-1)} -> US | E37: {=MID($A37,MIN(FIND({0;1;2;3;4;5;6;7;8;9},$A37&"0123456789")),FIND("-",$A37)-MIN(FIND({0;1;2;3;4;5;6;7;8;9},$A37&"0123456789")))} -> 404 | F37: =MID($A37,FIND("-",$A37)+1,LEN($A37)-FIND("-",$A37)-LEN($G37)) -> 6 | G37: =IF(RIGHT($A37,2)="Mo","Mo",RIGHT($A37,1)) -> W | H37: =D37&"-"&F37 -> US-6 | J37: US404-6W | K37: GER | L37: 404 | M37: 6 | N37: W | O37: GER-6
A38: ='Case 3 data'!A37 -> ARG43-9Mo | B38: ='Case 3 data'!B37 -> Emmitt | C38: ='Case 3 data'!C37 -> Valles | D38: {=LEFT($A38,MIN(FIND({0;1;2;3;4;5;6;7;8;9},$A38&"0123456789"))-1)} -> ARG | E38: {=MID($A38,MIN(FIND({0;1;2;3;4;5;6;7;8;9},$A38&"0123456789")),FIND("-",$A38)-MIN(FIND({0;1;2;3;4;5;6;7;8;9},$A38&"0123456789")))} -> 43 | F38: =MID($A38,FIND("-",$A38)+1,LEN($A38)-FIND("-",$A38)-LEN($G38)) -> 9 | G38: =IF(RIGHT($A38,2)="Mo","Mo",RIGHT($A38,1)) -> Mo | H38: =D38&"-"&F38 -> ARG-9 | J38: ARG43-9Mo | K38: Japan | L38: 43 | M38: 9 | N38: Mo | O38: Japan-9
A39: ='Case 3 data'!A38 -> GER188-9M | B39: ='Case 3 data'!B38 -> Vernia | C39: ='Case 3 data'!C38 -> Mccrary | D39: {=LEFT($A39,MIN(FIND({0;1;2;3;4;5;6;7;8;9},$A39&"0123456789"))-1)} -> GER | E39: {=MID($A39,MIN(FIND({0;1;2;3;4;5;6;7;8;9},$A39&"0123456789")),FIND("-",$A39)-MIN(FIND({0;1;2;3;4;5;6;7;8;9},$A39&"0123456789")))} -> 188 | F39: =MID($A39,FIND("-",$A39)+1,LEN($A39)-FIND("-",$A39)-LEN($G39)) -> 9 | G39: =IF(RIGHT($A39,2)="Mo","Mo",RIGHT($A39,1)) -> M | H39: =D39&"-"&F39 -> GER-9 | J39: GER188-9M | K39: =LEFT(A39,3) -> GER | L39: 188 | M39: 9 | N39: M | O39: GER-9
A40: ='Case 3 data'!A39 -> AUS275-8W | B40: ='Case 3 data'!B39 -> Michelle | C40: ='Case 3 data'!C39 -> Campbell | D40: {=LEFT($A40,MIN(FIND({0;1;2;3;4;5;6;7;8;9},$A40&"0123456789"))-1)} -> AUS | E40: {=MID($A40,MIN(FIND({0;1;2;3;4;5;6;7;8;9},$A40&"0123456789")),FIND("-",$A40)-MIN(FIND({0;1;2;3;4;5;6;7;8;9},$A40&"0123456789")))} -> 275 | F40: =MID($A40,FIND("-",$A40)+1,LEN($A40)-FIND("-",$A40)-LEN($G40)) -> 8 | G40: =IF(RIGHT($A40,2)="Mo","Mo",RIGHT($A40,1)) -> W | H40: =D40&"-"&F40 -> AUS-8 | J40: AUS275-8W | K40: AUS | L40: 275 | M40: 8 | N40: W | O40: AUS-8
...

Sheet Sheet1
A2: Japan177-3Mo | B2: Japan
A3: AUS551-2Mo | B3: AUS
A4: AUS316-2M | B4: AUS
A5: GER160-2W | B5: GER
A6: GER265-1M | B6: GER
A7: ARG363-4Mo | B7: ARG
A8: Canada351-3W | B8: Canada
A9: Japan195-5W | B9: Japan
A10: ARG529-1W | B10: ARG
A11: ENG301-6W | B11: ENG
A12: AUS60-2M | B12: AUS
A13: ARG102-7Mo | B13: ARG
... A598: Japan326-11M | B598: Japan

Sheet Case 3 data
A1: EmployeeCode | B1: FirstName | C1: LastName
A2: Japan177-3Mo | B2: Carl | C2: Rodriguez
A3: AUS551-2Mo | B3: Anne | C3: Wright
A4: AUS316-2M | B4: Patrick | C4: Rivera
A5: GER160-2W | B5: Ruby | C5: Walker
A6: GER265-1M | B6: Teresita | C6: Guillen
A7: ARG363-4Mo | B7: Earl | C7: Morgan
A8: Canada351-3W | B8: Joella | C8: Causey
A9: Japan195-5W | B9: Gregg | C9: Kelly
A10: ARG529-1W | B10: William | C10: Reed
A11: ENG301-6W | B11: Julia | C11: Johnson
A12: AUS60-2M | B12: Tonya | C12: Ruiz
... A598: Japan326-11M | B598: Mary | C598: Baker
