Workbook
Name _Hlk4423505: P4_Q6!$A$1

Sheet P4_Q11
A1: 11.The 2016 data is not broken down by month. Noah wants to estimate what the monthly gross wages are by month.
A2: To do so, Noah requests that you apply the percentage of gross wages earned each month in 2015 to the 2016 total gross wages to estimate the monthly expenditures in 2016.
A3: Display the month (sorted so January is listed first) and the predicted gross wages per month for 2016 (round this number to two decimal points).
A5: Below table columnA,B copied from P4_Q8
A6: 2015 | B6: 2015 Gross_Wages | C6: % of 2015 | D6: Predicted 2016
A7: Jan | B7: 10497752 | C7: =ROUND(Table13[[#This Row],[2015 Gross_Wages]]/$B$16,2) -> 0.16 | D7: =ROUND(Table13[[#This Row],[% of 2015]]*$B$17,2) -> 13748756
A8: Feb | B8: 10313416 | C8: =ROUND(Table13[[#This Row],[2015 Gross_Wages]]/$B$16,2) -> 0.15 | D8: =ROUND(Table13[[#This Row],[% of 2015]]*$B$17,2) -> 12889459
A9: Mar | B9: 11059608 | C9: =ROUND(Table13[[#This Row],[2015 Gross_Wages]]/$B$16,2) -> 0.16 | D9: =ROUND(Table13[[#This Row],[% of 2015]]*$B$17,2) -> 13748756
A10: Apr | B10: 11078106 | C10: =ROUND(Table13[[#This Row],[2015 Gross_Wages]]/$B$16,2) -> 0.16 | D10: =ROUND(Table13[[#This Row],[% of 2015]]*$B$17,2) -> 13748756
A11: May | B11: 13993523 | C11: =ROUND(Table13[[#This Row],[2015 Gross_Wages]]/$B$16,2) -> 0.21 | D11: =ROUND(Table13[[#This Row],[% of 2015]]*$B$17,2) -> 18045242
A12: Jun | B12: 10633648 | C12: =ROUND(Table13[[#This Row],[2015 Gross_Wages]]/$B$16,2) -> 0.16 | D12: =ROUND(Table13[[#This Row],[% of 2015]]*$B$17,2) -> 13748756
A15: Row Labels | B15: Sum of Gross_Wages
A16: 2015 | B16: 67576053
A17: 2016 | B17: 85929725
A18: Grand Total | B18: 153505778

Sheet P4_Q10
A1: 10. Make a table that displays the job code, the predicted 2017 gross wages for the job code, the percentage increase from 2015 to 2016, the gross wages for 2016 and the gross wages for 2015. Round all variables to two decimal places.
A2: For the purposes of this example, Noah only wants to predict 2017 expenses for the first 6 months of the year for each of job codes 001 through 008.
A3: Job code | B3: Predicted 2017 Gross Wages | C3: % Increase | D3: 2015 Gross Pay | E3: 2016 Gross Pay
A4: =TEXT(1,"000") -> 001 | B4: =ROUND(IFERROR((E4/D4)*E4,0),2) -> 26773556 | C4: =ROUND(IFERROR((E4-D4)/D4,0),2) -> 0.43 | D4: =ROUND(P4_Q9!$B8,2) -> 13178934 | E4: =ROUND(P4_Q9!$C8,2) -> 18784220
A5: =TEXT(2,"000") -> 002 | B5: =ROUND(IFERROR((E5/D5)*E5,0),2) -> 40695084 | C5: =ROUND(IFERROR((E5-D5)/D5,0),2) -> 0.01 | D5: =ROUND(P4_Q9!$B9,2) -> 39621371 | E5: =ROUND(P4_Q9!$C9,2) -> 40154639
A6: =TEXT(3,"000") -> 003 | B6: =ROUND(IFERROR((E6/D6)*E6,0),2) -> 1385929.5 | C6: =ROUND(IFERROR((E6-D6)/D6,0),2) -> -0.28 | D6: =ROUND(P4_Q9!$B10,2) -> 2678797 | E6: =ROUND(P4_Q9!$C10,2) -> 1926817
A7: =TEXT(4,"000") -> 004 | B7: =ROUND(IFERROR((E7/D7)*E7,0),2) -> 7272707 | C7: =ROUND(IFERROR((E7-D7)/D7,0),2) -> 0.48 | D7: =ROUND(P4_Q9!$B11,2) -> 3339832 | E7: =ROUND(P4_Q9!$C11,2) -> 4928450
A8: =TEXT(5,"000") -> 005 | B8: =ROUND(IFERROR((E8/D8)*E8,0),2) -> 165645.7 | C8: =ROUND(IFERROR((E8-D8)/D8,0),2) -> 0.01 | D8: =ROUND(P4_Q9!$B12,2) -> 162539 | E8: =ROUND(P4_Q9!$C12,2) -> 164085
A9: =TEXT(6,"000") -> 006 | B9: =ROUND(IFERROR((E9/D9)*E9,0),2) -> 13024980 | C9: =ROUND(IFERROR((E9-D9)/D9,0),2) -> 0.56 | D9: =ROUND(P4_Q9!$B13,2) -> 5376020 | E9: =ROUND(P4_Q9!$C13,2) -> 8367948
A10: =TEXT(7,"000") -> 007 | B10: =ROUND(IFERROR((E10/D10)*E10,0),2) -> 32832.3 | C10: =ROUND(IFERROR((E10-D10)/D10,0),2) -> -0.87 | D10: =ROUND(P4_Q9!$B14,2) -> 2014041 | E10: =ROUND(P4_Q9!$C14,2) -> 257149
A11: =TEXT(8,"000") -> 008 | B11: =ROUND(IFERROR((E11/D11)*E11,0),2) -> 6578863.7 | C11: =ROUND(IFERROR((E11-D11)/D11,0),2) -> 1.34 | D11: =ROUND(P4_Q9!$B15,2) -> 1204204 | E11: =ROUND(P4_Q9!$C15,2) -> 2814657

Sheet P4_Q9
A1: 1. Noah wants to predict his likely gross wage expenses for the first six months for each job code in 2017. To make the prediction, you will use the following formula:
A5: Answer: Please find the predicted 2017 wages for each job as below table
A6: Sum of Gross_Wages | B6: Column Labels
A7: Row Labels | B7: 2015 | C7: 2016 | D7: % Increase | E7: Predicted 2017 Wages
A8: 001 | B8: 13178934 | C8: 18784220 | D8: =IFERROR((C8-B8)/B8,0) -> 0.42532165 | E8: =IFERROR((C8/B8)*C8,0) -> 26773556
A9: 002 | B9: 39621371 | C9: 40154639 | D9: =IFERROR((C9-B9)/B9,0) -> 0.0134591 | E9: =IFERROR((C9/B9)*C9,0) -> 40695084
A10: 003 | B10: 2678797 | C10: 1926817 | D10: =IFERROR((C10-B10)/B10,0) -> -0.28071556 | E10: =IFERROR((C10/B10)*C10,0) -> 1385929.5
A11: 004 | B11: 3339832 | C11: 4928450 | D11: =IFERROR((C11-B11)/B11,0) -> 0.47565806 | E11: =IFERROR((C11/B11)*C11,0) -> 7272707
A12: 005 | B12: 162539 | C12: 164085 | D12: =IFERROR((C12-B12)/B12,0) -> 0.0095115634 | E12: =IFERROR((C12/B12)*C12,0) -> 165645.7
A13: 006 | B13: 5376020 | C13: 8367948 | D13: =IFERROR((C13-B13)/B13,0) -> 0.55653216 | E13: =IFERROR((C13/B13)*C13,0) -> 13024980
A14: 007 | B14: 2014041 | C14: 257149 | D14: =IFERROR((C14-B14)/B14,0) -> -0.87232186 | E14: =IFERROR((C14/B14)*C14,0) -> 32832.305
A15: 008 | B15: 1204204 | C15: 2814657 | D15: =IFERROR((C15-B15)/B15,0) -> 1.337359 | E15: =IFERROR((C15/B15)*C15,0) -> 6578863.7
A16: 009 | B16: 0 | C16: 6238118 | D16: =IFERROR((C16-B16)/B16,0) -> 0 | E16: =IFERROR((C16/B16)*C16,0) -> 0
A17: 010 | B17: 0 | C17: 1270293 | D17: =IFERROR((C17-B17)/B17,0) -> 0 | E17: =IFERROR((C17/B17)*C17,0) -> 0
A18: 011 | B18: 0 | C18: 70281 | D18: =IFERROR((C18-B18)/B18,0) -> 0 | E18: =IFERROR((C18/B18)*C18,0) -> 0
A19: 012 | B19: 0 | C19: 953068 | D19: =IFERROR((C19-B19)/B19,0) -> 0 | E19: =IFERROR((C19/B19)*C19,0) -> 0

Sheet P4_Q8
A1: 8. Noah wants to better understand monthly cash flows. To do this, he wants to know the monthly pattern of expenses for gross wages in 2015 (monthly wages are not available for 2016).
A2: That is, prepare a table that shows each month (sorted so January is listed first) and how much the amount of gross wages for that month differs from the average of the gross wages for the first six months.
A3: Positive values should show that the average for that month was more than the overall average. Using a formula, round your answers to two decimal places. Which month or months should Noah plan to have extra cash for higher-than-normal wage expenses?
A5: Answer: Noah should plan to have extra cash available in May, as it is the only month with higher-than-normal wage expenses during the first half of 2015.
A7: Row Labels | B7: Sum of Gross_Wages | C7: Difference
A8: Jan | B8: 10497752 | C8: =ROUND($B8-$B$15,2) -> -764923.5
A9: Feb | B9: 10313416 | C9: =ROUND($B9-$B$15,2) -> -949259.5
A10: Mar | B10: 11059608 | C10: =ROUND($B10-$B$15,2) -> -203067.5
A11: Apr | B11: 11078106 | C11: =ROUND($B11-$B$15,2) -> -184569.5
A12: May | B12: 13993523 | C12: =ROUND($B12-$B$15,2) -> 2730847.5
A13: Jun | B13: 10633648 | C13: =ROUND($B13-$B$15,2) -> -629027.5
A14: Grand Total | B14: 67576053
A15: Average | B15: =AVERAGE(B8:B13) -> 11262676

Sheet P4_Q7
A1: 7. Noah would like to know the percentage of each employee’s wages categorized into the different job codes for 2016. Display a chart that lists each employee in a separate row and each job code in a separate and unique column.
A2: Then, display the percentage of each employee’s 2016 pay that is associated with each job code (this means each employee’s row should sum to 100%, within 1% to 2% to accommodate for errors).
A3: Remove all observations that do not include an employee name or employees with no hours in 2016 on the list. For the final display, round the values to two decimal places using a formula. Sort the results by the employee’s name.
A4: Employee | B4: 001 | C4: 002 | D4: 003 | E4: 004 | F4: 005 | G4: 006 | H4: 007 | I4: 008 | J4: 009 | K4: 010 | L4: 011 | M4: 012
A5: Afton Call | B5: =ROUND(P4_Q7_Pivot!$B7,2) -> 0.08 | C5: =ROUND(P4_Q7_Pivot!$C7,2) -> 0 | D5: =ROUND(P4_Q7_Pivot!$D7,2) -> 0 | E5: =ROUND(P4_Q7_Pivot!$E7,2) -> 0.02 | F5: =ROUND(P4_Q7_Pivot!$F7,2) -> 0.1 | G5: =ROUND(P4_Q7_Pivot!$G7,2) -> 0 | H5: =ROUND(P4_Q7_Pivot!$H7,2) -> 0 | I5: =ROUND(P4_Q7_Pivot!$I7,2) -> 0.17 | J5: =ROUND(P4_Q7_Pivot!$J7,2) -> 0.25 | K5: =ROUND(P4_Q7_Pivot!$K7,2) -> 0.13 | L5: =ROUND(P4_Q7_Pivot!$L7,2) -> 0.13 | M5: =ROUND(P4_Q7_Pivot!$M7,2) -> 0.13
A6: Al Ramos | B6: =ROUND(P4_Q7_Pivot!$B8,2) -> 0 | C6: =ROUND(P4_Q7_Pivot!$C8,2) -> 0.95 | D6: =ROUND(P4_Q7_Pivot!$D8,2) -> 0 | E6: =ROUND(P4_Q7_Pivot!$E8,2) -> 0 | F6: =ROUND(P4_Q7_Pivot!$F8,2) -> 0 | G6: =ROUND(P4_Q7_Pivot!$G8,2) -> 0 | H6: =ROUND(P4_Q7_Pivot!$H8,2) -> 0 | I6: =ROUND(P4_Q7_Pivot!$I8,2) -> 0 | J6: =ROUND(P4_Q7_Pivot!$J8,2) -> 0.03 | K6: =ROUND(P4_Q7_Pivot!$K8,2) -> 0.02 | L6: =ROUND(P4_Q7_Pivot!$L8,2) -> 0 | M6: =ROUND(P4_Q7_Pivot!$M8,2) -> 0.01
A7: Alberta Gill | B7: =ROUND(P4_Q7_Pivot!$B9,2) -> 0 | C7: =ROUND(P4_Q7_Pivot!$C9,2) -> 0 | D7: =ROUND(P4_Q7_Pivot!$D9,2) -> 0.11 | E7: =ROUND(P4_Q7_Pivot!$E9,2) -> 0 | F7: =ROUND(P4_Q7_Pivot!$F9,2) -> 0 | G7: =ROUND(P4_Q7_Pivot!$G9,2) -> 0 | H7: =ROUND(P4_Q7_Pivot!$H9,2) -> 0 | I7: =ROUND(P4_Q7_Pivot!$I9,2) -> 0.22 | J7: =ROUND(P4_Q7_Pivot!$J9,2) -> 0.2 | K7: =ROUND(P4_Q7_Pivot!$K9,2) -> 0.19 | L7: =ROUND(P4_Q7_Pivot!$L9,2) -> 0 | M7: =ROUND(P4_Q7_Pivot!$M9,2) -> 0.28
A8: Allan Wood | B8: =ROUND(P4_Q7_Pivot!$B10,2) -> 0 | C8: =ROUND(P4_Q7_Pivot!$C10,2) -> 0.92 | D8: =ROUND(P4_Q7_Pivot!$D10,2) -> 0 | E8: =ROUND(P4_Q7_Pivot!$E10,2) -> 0 | F8: =ROUND(P4_Q7_Pivot!$F10,2) -> 0 | G8: =ROUND(P4_Q7_Pivot!$G10,2) -> 0 | H8: =ROUND(P4_Q7_Pivot!$H10,2) -> 0 | I8: =ROUND(P4_Q7_Pivot!$I10,2) -> 0 | J8: =ROUND(P4_Q7_Pivot!$J10,2) -> 0.07 | K8: =ROUND(P4_Q7_Pivot!$K10,2) -> 0.01 | L8: =ROUND(P4_Q7_Pivot!$L10,2) -> 0 | M8: =ROUND(P4_Q7_Pivot!$M10,2) -> 0
A9: Allen Price | B9: =ROUND(P4_Q7_Pivot!$B11,2) -> 0 | C9: =ROUND(P4_Q7_Pivot!$C11,2) -> 0 | D9: =ROUND(P4_Q7_Pivot!$D11,2) -> 0 | E9: =ROUND(P4_Q7_Pivot!$E11,2) -> 0 | F9: =ROUND(P4_Q7_Pivot!$F11,2) -> 0.04 | G9: =ROUND(P4_Q7_Pivot!$G11,2) -> 0 | H9: =ROUND(P4_Q7_Pivot!$H11,2) -> 0 | I9: =ROUND(P4_Q7_Pivot!$I11,2) -> 0.05 | J9: =ROUND(P4_Q7_Pivot!$J11,2) -> 0.62 | K9: =ROUND(P4_Q7_Pivot!$K11,2) -> 0.11 | L9: =ROUND(P4_Q7_Pivot!$L11,2) -> 0 | M9: =ROUND(P4_Q7_Pivot!$M11,2) -> 0.17
A10: Angel Watts | B10: =ROUND(P4_Q7_Pivot!$B12,2) -> 0 | C10: =ROUND(P4_Q7_Pivot!$C12,2) -> 0 | D10: =ROUND(P4_Q7_Pivot!$D12,2) -> 0 | E10: =ROUND(P4_Q7_Pivot!$E12,2) -> 0 | F10: =ROUND(P4_Q7_Pivot!$F12,2) -> 0.01 | G10: =ROUND(P4_Q7_Pivot!$G12,2) -> 0 | H10: =ROUND(P4_Q7_Pivot!$H12,2) -> 0 | I10: =ROUND(P4_Q7_Pivot!$I12,2) -> 0 | J10: =ROUND(P4_Q7_Pivot!$J12,2) -> 0.79 | K10: =ROUND(P4_Q7_Pivot!$K12,2) -> 0.2 | L10: =ROUND(P4_Q7_Pivot!$L12,2) -> 0 | M10: =ROUND(P4_Q7_Pivot!$M12,2) -> 0
A11: Antonio Torres | B11: =ROUND(P4_Q7_Pivot!$B13,2) -> 0.97 | C11: =ROUND(P4_Q7_Pivot!$C13,2) -> 0 | D11: =ROUND(P4_Q7_Pivot!$D13,2) -> 0 | E11: =ROUND(P4_Q7_Pivot!$E13,2) -> 0 | F11: =ROUND(P4_Q7_Pivot!$F13,2) -> 0 | G11: =ROUND(P4_Q7_Pivot!$G13,2) -> 0 | H11: =ROUND(P4_Q7_Pivot!$H13,2) -> 0 | I11: =ROUND(P4_Q7_Pivot!$I13,2) -> 0 | J11: =ROUND(P4_Q7_Pivot!$J13,2) -> 0.02 | K11: =ROUND(P4_Q7_Pivot!$K13,2) -> 0.01 | L11: =ROUND(P4_Q7_Pivot!$L13,2) -> 0 | M11: =ROUND(P4_Q7_Pivot!$M13,2) -> 0
A12: Barry Mckenzie | B12: =ROUND(P4_Q7_Pivot!$B14,2) -> 0.58 | C12: =ROUND(P4_Q7_Pivot!$C14,2) -> 0 | D12: =ROUND(P4_Q7_Pivot!$D14,2) -> 0 | E12: =ROUND(P4_Q7_Pivot!$E14,2) -> 0 | F12: =ROUND(P4_Q7_Pivot!$F14,2) -> 0 | G12: =ROUND(P4_Q7_Pivot!$G14,2) -> 0.1 | H12: =ROUND(P4_Q7_Pivot!$H14,2) -> 0.03 | I12: =ROUND(P4_Q7_Pivot!$I14,2) -> 0.24 | J12: =ROUND(P4_Q7_Pivot!$J14,2) -> 0.05 | K12: =ROUND(P4_Q7_Pivot!$K14,2) -> 0 | L12: =ROUND(P4_Q7_Pivot!$L14,2) -> 0 | M12: =ROUND(P4_Q7_Pivot!$M14,2) -> 0
A13: Beulah Gibbs | B13: =ROUND(P4_Q7_Pivot!$B15,2) -> 0.01 | C13: =ROUND(P4_Q7_Pivot!$C15,2) -> 0 | D13: =ROUND(P4_Q7_Pivot!$D15,2) -> 0 | E13: =ROUND(P4_Q7_Pivot!$E15,2) -> 0.59 | F13: =ROUND(P4_Q7_Pivot!$F15,2) -> 0 | G13: =ROUND(P4_Q7_Pivot!$G15,2) -> 0 | H13: =ROUND(P4_Q7_Pivot!$H15,2) -> 0 | I13: =ROUND(P4_Q7_Pivot!$I15,2) -> 0.22 | J13: =ROUND(P4_Q7_Pivot!$J15,2) -> 0.11 | K13: =ROUND(P4_Q7_Pivot!$K15,2) -> 0 | L13: =ROUND(P4_Q7_Pivot!$L15,2) -> 0 | M13: =ROUND(P4_Q7_Pivot!$M15,2) -> 0.07
A14: Brittany Carlson | B14: =ROUND(P4_Q7_Pivot!$B16,2) -> 0.06 | C14: =ROUND(P4_Q7_Pivot!$C16,2) -> 0.05 | D14: =ROUND(P4_Q7_Pivot!$D16,2) -> 0 | E14: =ROUND(P4_Q7_Pivot!$E16,2) -> 0 | F14: =ROUND(P4_Q7_Pivot!$F16,2) -> 0.04 | G14: =ROUND(P4_Q7_Pivot!$G16,2) -> 0 | H14: =ROUND(P4_Q7_Pivot!$H16,2) -> 0 | I14: =ROUND(P4_Q7_Pivot!$I16,2) -> 0 | J14: =ROUND(P4_Q7_Pivot!$J16,2) -> 0.71 | K14: =ROUND(P4_Q7_Pivot!$K16,2) -> 0.09 | L14: =ROUND(P4_Q7_Pivot!$L16,2) -> 0 | M14: =ROUND(P4_Q7_Pivot!$M16,2) -> 0.05
A15: Cary Foster | B15: =ROUND(P4_Q7_Pivot!$B17,2) -> 0 | C15: =ROUND(P4_Q7_Pivot!$C17,2) -> 0.82 | D15: =ROUND(P4_Q7_Pivot!$D17,2) -> 0 | E15: =ROUND(P4_Q7_Pivot!$E17,2) -> 0.03 | F15: =ROUND(P4_Q7_Pivot!$F17,2) -> 0 | G15: =ROUND(P4_Q7_Pivot!$G17,2) -> 0 | H15: =ROUND(P4_Q7_Pivot!$H17,2) -> 0 | I15: =ROUND(P4_Q7_Pivot!$I17,2) -> 0.06 | J15: =ROUND(P4_Q7_Pivot!$J17,2) -> 0.05 | K15: =ROUND(P4_Q7_Pivot!$K17,2) -> 0.02 | L15: =ROUND(P4_Q7_Pivot!$L17,2) -> 0 | M15: =ROUND(P4_Q7_Pivot!$M17,2) -> 0.01
A16: Cassandra Poole | B16: =ROUND(P4_Q7_Pivot!$B18,2) -> 0 | C16: =ROUND(P4_Q7_Pivot!$C18,2) -> 0.14 | D16: =ROUND(P4_Q7_Pivot!$D18,2) -> 0 | E16: =ROUND(P4_Q7_Pivot!$E18,2) -> 0.63 | F16: =ROUND(P4_Q7_Pivot!$F18,2) -> 0 | G16: =ROUND(P4_Q7_Pivot!$G18,2) -> 0 | H16: =ROUND(P4_Q7_Pivot!$H18,2) -> 0 | I16: =ROUND(P4_Q7_Pivot!$I18,2) -> 0.01 | J16: =ROUND(P4_Q7_Pivot!$J18,2) -> 0.22 | K16: =ROUND(P4_Q7_Pivot!$K18,2) -> 0 | L16: =ROUND(P4_Q7_Pivot!$L18,2) -> 0 | M16: =ROUND(P4_Q7_Pivot!$M18,2) -> 0
... A92: Grand Total | B92: =ROUND(P4_Q7_Pivot!$B94,2) -> 0.22 | C92: =ROUND(P4_Q7_Pivot!$C94,2) -> 0.48 | D92: =ROUND(P4_Q7_Pivot!$D94,2) -> 0.01 | E92: =ROUND(P4_Q7_Pivot!$E94,2) -> 0.06 | F92: =ROUND(P4_Q7_Pivot!$F94,2) -> 0 | G92: =ROUND(P4_Q7_Pivot!$G94,2) -> 0.1 | H92: =ROUND(P4_Q7_Pivot!$H94,2) -> 0 | I92: =ROUND(P4_Q7_Pivot!$I94,2) -> 0.02 | J92: =ROUND(P4_Q7_Pivot!$J94,2) -> 0.07 | K92: =ROUND(P4_Q7_Pivot!$K94,2) -> 0.01 | L92: =ROUND(P4_Q7_Pivot!$L94,2) -> 0 | M92: =ROUND(P4_Q7_Pivot!$M94,2) -> 0.01

Sheet P4_Q7_Pivot
A2: YEAR | B2: 2016
A3: Total_Hours | B3: (Multiple Items)
A5: Sum of Gross_Wages | B5: Column Labels
A6: Row Labels | B6: 001 | C6: 002 | D6: 003 | E6: 004 | F6: 005 | G6: 006 | H6: 007 | I6: 008 | J6: 009 | K6: 010 | L6: 011 | M6: 012 | N6: Grand Total
A7: Afton Call | B7: 0.08045977 | C7: 0 | D7: 0 | E7: 0.020114943 | F7: 0.098850575 | G7: 0 | H7: 0 | I7: 0.16896552 | J7: 0.2454023 | K7: 0.12873563 | L7: 0.12873563 | M7: 0.12873563 | N7: 1
A8: Al Ramos | B8: 0 | C8: 0.94568334 | D8: 0 | E8: 0 | F8: 0.00012967702 | G8: 0 | H8: 0 | I8: 0 | J8: 0.029177689 | K8: 0.016672862 | L8: 0 | M8: 0.0083364312 | N8: 1
A9: Alberta Gill | B9: 0 | C9: 0 | D9: 0.11276076 | E9: 0 | F9: 0 | G9: 0 | H9: 0 | I9: 0.22231654 | J9: 0.19529285 | K9: 0.19064228 | L9: 0 | M9: 0.27898758 | N9: 1
A10: Allan Wood | B10: 0 | C10: 0.91865142 | D10: 0 | E10: 0 | F10: 6.4435536e-06 | G10: 0 | H10: 0 | I10: 0 | J10: 0.066859601 | K10: 0.014482531 | L10: 0 | M10: 0 | N10: 1
A11: Allen Price | B11: 0 | C11: 0 | D11: 0 | E11: 0 | F11: 0.040136901 | G11: 0 | H11: 0 | I11: 0.051026758 | J11: 0.62258867 | K11: 0.11449907 | L11: 0 | M11: 0.1717486 | N11: 1
A12: Angel Watts | B12: 0 | C12: 0 | D12: 0 | E12: 0 | F12: 0.014218009 | G12: 0 | H12: 0 | I12: 0 | J12: 0.78862559 | K12: 0.1971564 | L12: 0 | M12: 0 | N12: 1
A13: Antonio Torres | B13: 0.96807903 | C13: 0.0014494014 | D13: 0 | E13: 0 | F13: 0 | G13: 0 | H13: 0 | I13: 0 | J13: 0.022705678 | K13: 0.0073710113 | L13: 0 | M13: 0.00039488136 | N13: 1
A14: Barry Mckenzie | B14: 0.57914343 | C14: 0.0044305867 | D14: 0 | E14: 0 | F14: 0.00042032195 | G14: 0.10285475 | H14: 0.028482343 | I14: 0.23567894 | J14: 0.047470571 | K14: 0.00050635276 | L14: 0 | M14: 0.0010127055 | N14: 1
A15: Beulah Gibbs | B15: 0.013085266 | C15: 0.00010468213 | D15: 0 | E15: 0.58763655 | F15: 0.00032872145 | G15: 0 | H15: 0 | I15: 0.22046448 | J15: 0.10599212 | K15: 0.00041872851 | L15: 0 | M15: 0.071969452 | N15: 1
A16: Brittany Carlson | B16: 0.059101655 | C16: 0.047281324 | D16: 0 | E16: 0 | F16: 0.042553191 | G16: 0 | H16: 0 | I16: 0 | J16: 0.70921986 | K16: 0.094562648 | L16: 0 | M16: 0.047281324 | N16: 1
A17: Cary Foster | B17: 0 | C17: 0.824037 | D17: 0 | E17: 0.034877779 | F17: 0 | G17: 0 | H17: 0 | I17: 0.060432289 | J17: 0.054495396 | K17: 0.017438356 | L17: 0 | M17: 0.008719178 | N17: 1
A18: Cassandra Poole | B18: 0 | C18: 0.138593 | D18: 0 | E18: 0.63357862 | F18: 0.00015491124 | G18: 0 | H18: 0 | I18: 0.0052860555 | J18: 0.21900449 | K18: 0.0033829266 | L18: 0 | M18: 0 | N18: 1
... A94: Grand Total | B94: 0.22314129 | C94: 0.4773242 | D94: 0.014024804 | E94: 0.058585223 | F94: 0.0019373677 | G94: 0.09947105 | H94: 0.0030562932 | I94: 0.022235151 | J94: 0.073879182 | K94: 0.014502489 | L94: 0.00083544077 | M94: 0.011007501 | N94: 1

Sheet P4_Q6
A1: 6. The company operates in two locations. Noah is concerned whether the company is paying a similar amount for employees at both locations. He prepared a pipe-delimited text file (Analytics_mindset_case_studies_locations.csv) for you that contains the names of all employees and their locations.
A2: This additional file contains two columns separated by a pipe, wherein the first column lists the name of the employee (FirstName LastName) and the second column provides the location where that employee works (either location one or two).
A3: Upload this data into Excel and prepare a table (or tables) that shows the total number of hours (include regular and overtime hours) employees in both locations worked in 2015 and 2016, the gross wages for each location in 2015 and in 2016, and the average pay for each location in 2015 and 2016 (i.e., pay per hour).
A4: Sort the data so location one is listed first. Clearly label each column. You can exclude the phantom entries you found in question 3. Does there appear to be any difference in pay based on the location? Why or why not?
A6: Answer
A7: As below table states, In 2015, Location 1 had an average pay of 261.09, while Location 2 had a significantly higher average pay of 917.33. In 2016, the same pattern continued, with Location 1 at 147.20 and Location 2 at 241.27.
A8: Although both locations experienced changes in total hours and wages, Location 2 consistently shows a higher average pay per hour than Location 1 in both years.
A9: This difference should be further investigated to determine whether it is justified by operational needs or reflects inefficiencies in workforce allocation.
A10: Emp_No | B10: (Multiple Items)
B12: Column Labels
B13: 2015 | D13: 2016
A14: Row Labels | B14: Sum of Total_Hours | C14: Sum of Gross_Wages | D14: Sum of Total_Hours | E14: Sum of Gross_Wages | F14: 2015 AVERAGE PAY | G14: 2016 AVERAGE PAY
A15: 1 | B15: 91416 | C15: 23867897 | D15: 209559 | E15: 30847595 | F15: =C15/B15 -> 261.09102 | G15: =E15/D15 -> 147.20243
A16: 2 | B16: 47647 | C16: 43708156 | D16: 220816 | E16: 53276861 | F16: =C16/B16 -> 917.3328 | G16: =E16/D16 -> 241.27265

Sheet P4_Q5
A1: 5. What was the total employee cost for all projects in 2016? The total employee cost should include everything paid for wages, Social Security and Medicaid, FUTA, SUTA and workers’ compensation.
A3: Answer: The total employee cost for all projects in 2016 is 97.524.520
A4: YEAR | B4: 2016
A6: Sum of Gross_Wages | B6: Sum of Fica_Medc | C6: Sum of Futa | D6: Sum of Suta | E6: Sum of Work_Comp | F6: Total
A7: 85929725 | B7: 8422378 | C7: 151485 | D7: 2120859 | E7: 900073 | F7: =SUM(A7:E7) -> 97524520

Sheet P4_Q4
A1: 4. In 2015, were there any employees who incurred overtime when they had not already worked 40 regular work hours during the pay period? Assume, for this problem, that all pay on the same date is for the same pay period.
A2: Return the name of the employee, the pay date, the total number of regular hours worked and the total number if overtime hours worked. Make sure only to list values if an employee worked less than 40 hours but listed some overtime hours. Sort the data by the employee name and then the pay date.
A4: Answer: There are employees who incurred overtime when they had not already worked 40 regular working hours during the pay period
A5: Emp_Name | B5: Pay_Date | C5: Sum of Reg_Hrs | D5: Sum of OT_Hrs | E5: Help column
A6: Al Ramos | B6: 42006 | C6: 25 | D6: 0 | E6: =IF(AND($C6<40,$D6>0),"Keep","")
A7: Al Ramos | B7: 42013 | C7: 8 | D7: 0 | E7: =IF(AND($C7<40,$D7>0),"Keep","")
A8: Al Ramos | B8: 42020 | C8: 43 | D8: 0 | E8: =IF(AND($C8<40,$D8>0),"Keep","")
A9: Al Ramos | B9: 42027 | C9: 42 | D9: 0 | E9: =IF(AND($C9<40,$D9>0),"Keep","")
A10: Al Ramos | B10: 42034 | C10: 41 | D10: 0 | E10: =IF(AND($C10<40,$D10>0),"Keep","")
A11: Al Ramos | B11: 42041 | C11: 40 | D11: 0 | E11: =IF(AND($C11<40,$D11>0),"Keep","")
A12: Al Ramos | B12: 42048 | C12: 39 | D12: 0 | E12: =IF(AND($C12<40,$D12>0),"Keep","")
A13: Al Ramos | B13: 42055 | C13: 36 | D13: 0 | E13: =IF(AND($C13<40,$D13>0),"Keep","")
A14: Al Ramos | B14: 42062 | C14: 35 | D14: 0 | E14: =IF(AND($C14<40,$D14>0),"Keep","")
A15: Al Ramos | B15: 42069 | C15: 40 | D15: 0 | E15: =IF(AND($C15<40,$D15>0),"Keep","")
A16: Al Ramos | B16: 42076 | C16: 435 | D16: 0 | E16: =IF(AND($C16<40,$D16>0),"Keep","")
A17: Al Ramos | B17: 42083 | C17: 38 | D17: 0 | E17: =IF(AND($C17<40,$D17>0),"Keep","")
... A2035: Yvette Miller | B2035: 42181 | C2035: 40 | D2035: 0 | E2035: =IF(AND($C2035<40,$D2035>0),"Keep","")

Sheet P4_Q4_pivot
A1: Emp_Name | B1: Pay_Date | C1: Sum of Reg_Hrs | D1: Sum of OT_Hrs
A2: Al Ramos | B2: 42006 | C2: 25 | D2: 0
A3: Al Ramos | B3: 42013 | C3: 8 | D3: 0
A4: Al Ramos | B4: 42020 | C4: 43 | D4: 0
A5: Al Ramos | B5: 42027 | C5: 42 | D5: 0
A6: Al Ramos | B6: 42034 | C6: 41 | D6: 0
A7: Al Ramos | B7: 42041 | C7: 40 | D7: 0
A8: Al Ramos | B8: 42048 | C8: 39 | D8: 0
A9: Al Ramos | B9: 42055 | C9: 36 | D9: 0
A10: Al Ramos | B10: 42062 | C10: 35 | D10: 0
A11: Al Ramos | B11: 42069 | C11: 40 | D11: 0
A12: Al Ramos | B12: 42076 | C12: 435 | D12: 0
A13: Al Ramos | B13: 42083 | C13: 38 | D13: 0
... A2031: Yvette Miller | B2031: 42181 | C2031: 40 | D2031: 0

Sheet P4_Q3
A1: 3. Noah knows there are some errors with the new system used in 2016. What is the total number of transactions entered in 2016 without an employee number? What was the total gross wage amount for these “phantom” entries? Make sure to use a descriptive title for each column.
A2: Total number of transaction without employee number is 68 and in total, 1805269 has been paid for these phantom entries
A3: YEAR | B3: 2016
A5: Emp_No | B5: Count of Emp_No | C5: Sum of Gross_Wages | D5: Sum of transaction count
A6: (blank) | C6: 1805269 | D6: 68
A7: Grand Total | C7: 1805269 | D7: 68

Sheet P4_Q2
A1: 2. To reduce overtime pay, Noah is considering shuffling employees from one job code to another. Which job codes have the most overtime pay in 2015? | K1: Answer: Office
A2: Job_Code | B2: Job_description | C2: Sum of OT_Hrs | D2: Sum of OT_Pay
A3: 001 | B3: Office | C3: 1277 | D3: 208754
A4: 006 | B4: Service | C4: 288 | D4: 190379
A5: 002 | B5: Sales | C5: 159 | D5: 101016
A6: 004 | B6: Proj Management | C6: 107 | D6: 54925
A7: 005 | B7: Installation | C7: 14 | D7: 37164
A8: 008 | B8: Employee Training | C8: 22 | D8: 30653
A9: 003 | B9: Travel | C9: 1 | D9: 5355
A10: 011 | B10: Internal Projects | C10: 0 | D10: 0
A11: 010 | B11: New Foreign Manufacturing Oversight | C11: 0 | D11: 0
A12: 012 | B12: Internal Auditing | C12: 0 | D12: 0
A13: 009 | B13: New Foreign Manufacturing Plant | C13: 0 | D13: 0
A14: 007 | B14: Customer Training | C14: 0 | D14: 0

Sheet P4_Q1
A1: 1. Which employees are earning the most overtime pay and how much did they earn in the first six months of 2015?
A2: Cindy Lunt
A4: OT_Hrs | B4: (Multiple Items)
A6: Emp_Name | B6: Sum of OT_Pay | C6: Sum of OT_Hrs
A7: Cindy Lunt | B7: 311569 | C7: 402
A8: Nettie Stevens | B8: 106029 | C8: 126
A9: Clarence Padilla | B9: 86542 | C9: 939
A10: Elisa Warren | B10: 58939 | C10: 43
A11: Deborah Bennett | B11: 36276 | C11: 8
A12: Kenny Robertson | B12: 8918 | C12: 25
A13: Tommy Graves | B13: 5790 | C13: 33
A14: Sue Riley | B14: 4410 | C14: 14
A15: Marc Wallace | B15: 2954 | C15: 80
A16: Jo Manning | B16: 2604 | C16: 62
A17: Lynn Perkins | B17: 1122 | C17: 8
A18: Stanley Peterson | B18: 915 | C18: 71
... A24: Norman Ruiz | B24: 132 | C24: 28

Sheet P3_Memo
A1: To: Noah
A2: Subject: Analysis of Payroll Increase from 2015 to 2016
A4: 1. Overview
A6: Based on the analysis of payroll data from 2015 to 2016, total payroll expenses increased significantly.
A7: However, this increase was not driven by an increase in employee count, as the number of employees decreased from 851 in 2015 to 804 in 2016 (see Table 1). Instead, the increase is primarily driven by changes in wages, working hours, and job-specific factors.
A9: Table 1: Employee Count Comparison (from P1_5Qs)
A16: 2. Key Drivers of Payroll Increase
A18: Using the aggregated results as below table 2, the three job codes with the largest positive wage differences are:
A20: 001 – Office
A21: 006 – Service
A22: 008 – Employee Training
A24: These job categories contributed the most to the overall payroll increase.
... A48: Several employees contributed significantly, including:
B49: Antonio Torres (increase in both hours and wages)
B50: Clarence Padilla (substantial increase in working hours)
A51: This indicates that both workload expansion and compensation adjustments contributed to the increase.
A52: 3.2 Service (006)
A53: The Service category experienced a significant increase in total wages, which is driven by a substantial increase in total working hours.
A54: While some employees also show increases in pay per hour, the main driver appears to be increased labor demand.
A55: 3.3 Employee Training (008)
A56: The Employee Training category shows an increase in total wages despite a decrease in pay per hour.
A57: This suggests that the increase is driven by higher working hours rather than changes in wage rates.
A59: Table 3: Employee-Level Details (from P3_Q2)
A158: 4. Additional Findings
A159: From the broader analysis (see supporting results in P1_5Qs), the increase in payroll is not due to employee growth but is instead driven by:
B160: Increased working hours
B161: Redistribution of workload across job categories
B162: Selective increases in compensation
A164: Table 4: Supporting Payroll & Hours Summary (from P1_5Qs)
A203: 5. Data Discrepancies
A204: Several data issues were identified during the analysis:
B205: Job code 144 appears to be invalid and likely results from an error in project code extraction
B206: Some employees show extremely large percentage changes due to missing or very small base values
B207: Certain records contain unusually high pay-per-hour values, suggesting potential data entry or allocation errors
B208: Missing or zero values for some employees in one of the years required exclusion to ensure valid comparisons
A210: 6. Conclusion
A211: In conclusion, the payroll increase in 2016 is primarily driven by higher working hours and increases in pay rates within key job categories.
A212: The Office, Service, and Employee Training categories are the main contributors to this change.

Sheet P3_Q2
A1: Job code | B1: Employee number | C1: Employee name | D1: 2015 hours | E1: 2015 gross pay | F1: 2015 gross pay per hour | G1: 2016 hours | H1: 2016 gross pay | I1: 2016 gross pay per hour | J1: Hours difference | K1: Gross pay difference | L1: Gross pay per hour difference
A2: =Q3_worksheet!A27 -> 001 | B2: =Q3_worksheet!B27 -> (blank) | C2: =Q3_worksheet!C27 -> 0 | D2: =Q3_worksheet!D27 -> 0 | E2: =Q3_worksheet!E27 -> 0 | F2: =IFERROR(E2/D2,0) -> 0 | G2: =Q3_worksheet!F27 -> 16565 | H2: =Q3_worksheet!G27 -> 12580 | I2: =IFERROR(H2/G2,0) -> 0.75943254 | J2: =G2-D2 -> 16565 | K2: =H2-E2 -> 12580 | L2: =I2-F2 -> 0.75943254
A3: =Q3_worksheet!A99 -> 002 | B3: =Q3_worksheet!B99 -> 195 | C3: =Q3_worksheet!C99 -> Al Ramos | D3: =Q3_worksheet!D99 -> 2548 | E3: =Q3_worksheet!E99 -> 2565652 | F3: =IFERROR(E3/D3,0) -> 1006.9278 | G3: =Q3_worksheet!F99 -> 911 | H3: =Q3_worksheet!G99 -> 2625338 | I3: =IFERROR(H3/G3,0) -> 2881.82 | J3: =G3-D3 -> -1637 | K3: =H3-E3 -> 59686 | L3: =I3-F3 -> 1874.8922
A4: =Q3_worksheet!A137 -> 003 | B4: =Q3_worksheet!B137 -> 404 | C4: =Q3_worksheet!C137 -> Alberta Gill | D4: =Q3_worksheet!D137 -> 133 | E4: =Q3_worksheet!E137 -> 198175 | F4: =IFERROR(E4/D4,0) -> 1490.0376 | G4: =Q3_worksheet!F137 -> 95 | H4: =Q3_worksheet!G137 -> 21919 | I4: =IFERROR(H4/G4,0) -> 230.72632 | J4: =G4-D4 -> -38 | K4: =H4-E4 -> -176256 | L4: =I4-F4 -> -1259.3113
A5: =Q3_worksheet!A321 -> 008 | B5: =Q3_worksheet!B321 -> 404 | C5: =Q3_worksheet!C321 -> Alberta Gill | D5: =Q3_worksheet!D321 -> 177 | E5: =Q3_worksheet!E321 -> 338153 | F5: =IFERROR(E5/D5,0) -> 1910.4689 | G5: =Q3_worksheet!F321 -> 185 | H5: =Q3_worksheet!G321 -> 43215 | I5: =IFERROR(H5/G5,0) -> 233.59459 | J5: =G5-D5 -> 8 | K5: =H5-E5 -> -294938 | L5: =I5-F5 -> -1676.8743
A6: =Q3_worksheet!A92 -> 002 | B6: =Q3_worksheet!B92 -> 106 | C6: =Q3_worksheet!C92 -> Allan Wood | D6: =Q3_worksheet!D92 -> 185 | E6: =Q3_worksheet!E92 -> 5310 | F6: =IFERROR(E6/D6,0) -> 28.702703 | G6: =Q3_worksheet!F92 -> 1010 | H6: =Q3_worksheet!G92 -> 2138536 | I6: =IFERROR(H6/G6,0) -> 2117.3624 | J6: =G6-D6 -> 825 | K6: =H6-E6 -> 2133226 | L6: =I6-F6 -> 2088.6597
A7: =Q3_worksheet!A32 -> 001 | B7: =Q3_worksheet!B32 -> 19 | C7: =Q3_worksheet!C32 -> Frank Diaz | D7: =Q3_worksheet!D32 -> 0 | E7: =Q3_worksheet!E32 -> 0 | F7: =IFERROR(E7/D7,0) -> 0 | G7: =Q3_worksheet!F32 -> 4 | H7: =Q3_worksheet!G32 -> 108 | I7: =IFERROR(H7/G7,0) -> 27 | J7: =G7-D7 -> 4 | K7: =H7-E7 -> 108 | L7: =I7-F7 -> 27
A8: =Q3_worksheet!A33 -> 001 | B8: =Q3_worksheet!B33 -> 22 | C8: =Q3_worksheet!C33 -> Marion Scott | D8: =Q3_worksheet!D33 -> 0 | E8: =Q3_worksheet!E33 -> 0 | F8: =IFERROR(E8/D8,0) -> 0 | G8: =Q3_worksheet!F33 -> 29 | H8: =Q3_worksheet!G33 -> 78931 | I8: =IFERROR(H8/G8,0) -> 2721.7586 | J8: =G8-D8 -> 29 | K8: =H8-E8 -> 78931 | L8: =I8-F8 -> 2721.7586
A9: =Q3_worksheet!A302 -> 008 | B9: =Q3_worksheet!B302 -> 304 | C9: =Q3_worksheet!C302 -> Allen Price | D9: =Q3_worksheet!D302 -> 19 | E9: =Q3_worksheet!E302 -> 437 | F9: =IFERROR(E9/D9,0) -> 23 | G9: =Q3_worksheet!F302 -> 7 | H9: =Q3_worksheet!G302 -> 164 | I9: =IFERROR(H9/G9,0) -> 23.428571 | J9: =G9-D9 -> -12 | K9: =H9-E9 -> -273 | L9: =I9-F9 -> 0.42857143
A10: =Q3_worksheet!A28 -> 001 | B10: =Q3_worksheet!B28 -> 1 | C10: =Q3_worksheet!C28 -> Antonio Torres | D10: =Q3_worksheet!D28 -> 911 | E10: =Q3_worksheet!E28 -> 2011582 | F10: =IFERROR(E10/D10,0) -> 2208.1032 | G10: =Q3_worksheet!F28 -> 1101 | H10: =Q3_worksheet!G28 -> 3005624 | I10: =IFERROR(H10/G10,0) -> 2729.9037 | J10: =G10-D10 -> 190 | K10: =H10-E10 -> 994042 | L10: =I10-F10 -> 521.80054
A11: =Q3_worksheet!A64 -> 001 | B11: =Q3_worksheet!B64 -> 391 | C11: =Q3_worksheet!C64 -> Barry Mckenzie | D11: =Q3_worksheet!D64 -> 405 | E11: =Q3_worksheet!E64 -> 446351 | F11: =IFERROR(E11/D11,0) -> 1102.1012 | G11: =Q3_worksheet!F64 -> 1620 | H11: =Q3_worksheet!G64 -> 471227 | I11: =IFERROR(H11/G11,0) -> 290.88086 | J11: =G11-D11 -> 1215 | K11: =H11-E11 -> 24876 | L11: =I11-F11 -> -811.22037
A12: =Q3_worksheet!A315 -> 008 | B12: =Q3_worksheet!B315 -> 391 | C12: =Q3_worksheet!C315 -> Barry Mckenzie | D12: =Q3_worksheet!D315 -> 12 | E12: =Q3_worksheet!E315 -> 309 | F12: =IFERROR(E12/D12,0) -> 25.75 | G12: =Q3_worksheet!F315 -> 745 | H12: =Q3_worksheet!G315 -> 191763 | I12: =IFERROR(H12/G12,0) -> 257.4 | J12: =G12-D12 -> 733 | K12: =H12-E12 -> 191454 | L12: =I12-F12 -> 231.65
A13: =Q3_worksheet!A38 -> 001 | B13: =Q3_worksheet!B38 -> 37 | C13: =Q3_worksheet!C38 -> Kirk Byrd | D13: =Q3_worksheet!D38 -> 0 | E13: =Q3_worksheet!E38 -> 0 | F13: =IFERROR(E13/D13,0) -> 0 | G13: =Q3_worksheet!F38 -> 5 | H13: =Q3_worksheet!G38 -> 1225 | I13: =IFERROR(H13/G13,0) -> 245 | J13: =G13-D13 -> 5 | K13: =H13-E13 -> 1225 | L13: =I13-F13 -> 245
A14: =Q3_worksheet!A149 -> 004 | B14: =Q3_worksheet!B149 -> 259 | C14: =Q3_worksheet!C149 -> Beulah Gibbs | D14: =Q3_worksheet!D149 -> 1154 | E14: =Q3_worksheet!E149 -> 401449 | F14: =IFERROR(E14/D14,0) -> 347.87608 | G14: =Q3_worksheet!F149 -> 2249 | H14: =Q3_worksheet!G149 -> 600648 | I14: =IFERROR(H14/G14,0) -> 267.07337 | J14: =G14-D14 -> 1095 | K14: =H14-E14 -> 199199 | L14: =I14-F14 -> -80.802717
A15: =Q3_worksheet!A40 -> 001 | B15: =Q3_worksheet!B40 -> 106 | C15: =Q3_worksheet!C40 -> Allan Wood | D15: =Q3_worksheet!D40 -> 646 | E15: =Q3_worksheet!E40 -> 227334 | F15: =IFERROR(E15/D15,0) -> 351.91022 | G15: =Q3_worksheet!F40 -> 0 | H15: =Q3_worksheet!G40 -> 0 | I15: =IFERROR(H15/G15,0) -> 0 | J15: =G15-D15 -> -646 | K15: =H15-E15 -> -227334 | L15: =I15-F15 -> -351.91022
A16: =Q3_worksheet!A296 -> 008 | B16: =Q3_worksheet!B296 -> 259 | C16: =Q3_worksheet!C296 -> Beulah Gibbs | D16: =Q3_worksheet!D296 -> 122 | E16: =Q3_worksheet!E296 -> 43012 | F16: =IFERROR(E16/D16,0) -> 352.55738 | G16: =Q3_worksheet!F296 -> 86 | H16: =Q3_worksheet!G296 -> 225346 | I16: =IFERROR(H16/G16,0) -> 2620.3023 | J16: =G16-D16 -> -36 | K16: =H16-E16 -> 182334 | L16: =I16-F16 -> 2267.7449
A17: =Q3_worksheet!A41 -> 001 | B17: =Q3_worksheet!B41 -> 168 | C17: =Q3_worksheet!C41 -> Brittany Carlson | D17: =Q3_worksheet!D41 -> 122 | E17: =Q3_worksheet!E41 -> 74453 | F17: =IFERROR(E17/D17,0) -> 610.27049 | G17: =Q3_worksheet!F41 -> 10 | H17: =Q3_worksheet!G41 -> 375 | I17: =IFERROR(H17/G17,0) -> 37.5 | J17: =G17-D17 -> -112 | K17: =H17-E17 -> -74078 | L17: =I17-F17 -> -572.77049
A18: =Q3_worksheet!A43 -> 001 | B18: =Q3_worksheet!B43 -> 194 | C18: =Q3_worksheet!C43 -> Hector Wright | D18: =Q3_worksheet!D43 -> 4 | E18: =Q3_worksheet!E43 -> 90 | F18: =IFERROR(E18/D18,0) -> 22.5 | G18: =Q3_worksheet!F43 -> 0 | H18: =Q3_worksheet!G43 -> 0 | I18: =IFERROR(H18/G18,0) -> 0 | J18: =G18-D18 -> -4 | K18: =H18-E18 -> -90 | L18: =I18-F18 -> -22.5
A19: =Q3_worksheet!A93 -> 002 | B19: =Q3_worksheet!B93 -> 168 | C19: =Q3_worksheet!C93 -> Brittany Carlson | D19: =Q3_worksheet!D93 -> 56 | E19: =Q3_worksheet!E93 -> 2100 | F19: =IFERROR(E19/D19,0) -> 37.5 | G19: =Q3_worksheet!F93 -> 8 | H19: =Q3_worksheet!G93 -> 300 | I19: =IFERROR(H19/G19,0) -> 37.5 | J19: =G19-D19 -> -48 | K19: =H19-E19 -> -1800 | L19: =I19-F19 -> 0
A20: =Q3_worksheet!A103 -> 002 | B20: =Q3_worksheet!B103 -> 249 | C20: =Q3_worksheet!C103 -> Cary Foster | D20: =Q3_worksheet!D103 -> 580 | E20: =Q3_worksheet!E103 -> 1953907 | F20: =IFERROR(E20/D20,0) -> 3368.8052 | G20: =Q3_worksheet!F103 -> 756 | H20: =Q3_worksheet!G103 -> 3089674 | I20: =IFERROR(H20/G20,0) -> 4086.8704 | J20: =G20-D20 -> 176 | K20: =H20-E20 -> 1135767 | L20: =I20-F20 -> 718.0652
A21: =Q3_worksheet!A148 -> 004 | B21: =Q3_worksheet!B148 -> 249 | C21: =Q3_worksheet!C148 -> Cary Foster | D21: =Q3_worksheet!D148 -> 78 | E21: =Q3_worksheet!E148 -> 247397 | F21: =IFERROR(E21/D21,0) -> 3171.7564 | G21: =Q3_worksheet!F148 -> 32 | H21: =Q3_worksheet!G148 -> 130772 | I21: =IFERROR(H21/G21,0) -> 4086.625 | J21: =G21-D21 -> -46 | K21: =H21-E21 -> -116625 | L21: =I21-F21 -> 914.86859
A22: =Q3_worksheet!A295 -> 008 | B22: =Q3_worksheet!B295 -> 249 | C22: =Q3_worksheet!C295 -> Cary Foster | D22: =Q3_worksheet!D295 -> 40 | E22: =Q3_worksheet!E295 -> 163462 | F22: =IFERROR(E22/D22,0) -> 4086.55 | G22: =Q3_worksheet!F295 -> 54 | H22: =Q3_worksheet!G295 -> 226587 | I22: =IFERROR(H22/G22,0) -> 4196.0556 | J22: =G22-D22 -> 14 | K22: =H22-E22 -> 63125 | L22: =I22-F22 -> 109.50556
A23: =Q3_worksheet!A95 -> 002 | B23: =Q3_worksheet!B95 -> 179 | C23: =Q3_worksheet!C95 -> Cassandra Poole | D23: =Q3_worksheet!D95 -> 225 | E23: =Q3_worksheet!E95 -> 183562 | F23: =IFERROR(E23/D23,0) -> 815.83111 | G23: =Q3_worksheet!F95 -> 677 | H23: =Q3_worksheet!G95 -> 297922 | I23: =IFERROR(H23/G23,0) -> 440.06204 | J23: =G23-D23 -> 452 | K23: =H23-E23 -> 114360 | L23: =I23-F23 -> -375.76907
A24: =Q3_worksheet!A49 -> 001 | B24: =Q3_worksheet!B49 -> 259 | C24: =Q3_worksheet!C49 -> Beulah Gibbs | D24: =Q3_worksheet!D49 -> 0 | E24: =Q3_worksheet!E49 -> 0 | F24: =IFERROR(E24/D24,0) -> 0 | G24: =Q3_worksheet!F49 -> 5 | H24: =Q3_worksheet!G49 -> 13375 | I24: =IFERROR(H24/G24,0) -> 2675 | J24: =G24-D24 -> 5 | K24: =H24-E24 -> 13375 | L24: =I24-F24 -> 2675
A25: =Q3_worksheet!A146 -> 004 | B25: =Q3_worksheet!B146 -> 179 | C25: =Q3_worksheet!C146 -> Cassandra Poole | D25: =Q3_worksheet!D146 -> 1497 | E25: =Q3_worksheet!E146 -> 1138379 | F25: =IFERROR(E25/D25,0) -> 760.44021 | G25: =Q3_worksheet!F146 -> 309 | H25: =Q3_worksheet!G146 -> 1361952 | I25: =IFERROR(H25/G25,0) -> 4407.6117 | J25: =G25-D25 -> -1188 | K25: =H25-E25 -> 223573 | L25: =I25-F25 -> 3647.1714
A26: =Q3_worksheet!A58 -> 001 | B26: =Q3_worksheet!B58 -> 368 | C26: =Q3_worksheet!C58 -> Cesar Greene | D26: =Q3_worksheet!D58 -> 1 | E26: =Q3_worksheet!E58 -> 245 | F26: =IFERROR(E26/D26,0) -> 245 | G26: =Q3_worksheet!F58 -> 175 | H26: =Q3_worksheet!G58 -> 42875 | I26: =IFERROR(H26/G26,0) -> 245 | J26: =G26-D26 -> 174 | K26: =H26-E26 -> 42630 | L26: =I26-F26 -> 0
A27: =Q3_worksheet!A205 -> 005 | B27: =Q3_worksheet!B205 -> 368 | C27: =Q3_worksheet!C205 -> Cesar Greene | D27: =Q3_worksheet!D205 -> 23 | E27: =Q3_worksheet!E205 -> 5194 | F27: =IFERROR(E27/D27,0) -> 225.82609 | G27: =Q3_worksheet!F205 -> 63 | H27: =Q3_worksheet!G205 -> 9894 | I27: =IFERROR(H27/G27,0) -> 157.04762 | J27: =G27-D27 -> 40 | K27: =H27-E27 -> 4700 | L27: =I27-F27 -> -68.778468
A28: =Q3_worksheet!A311 -> 008 | B28: =Q3_worksheet!B311 -> 368 | C28: =Q3_worksheet!C311 -> Cesar Greene | D28: =Q3_worksheet!D311 -> 86 | E28: =Q3_worksheet!E311 -> 18865 | F28: =IFERROR(E28/D28,0) -> 219.36047 | G28: =Q3_worksheet!F311 -> 465 | H28: =Q3_worksheet!G311 -> 113925 | I28: =IFERROR(H28/G28,0) -> 245 | J28: =G28-D28 -> 379 | K28: =H28-E28 -> 95060 | L28: =I28-F28 -> 25.639535
A29: =Q3_worksheet!A54 -> 001 | B29: =Q3_worksheet!B54 -> 352 | C29: =Q3_worksheet!C54 -> Myra Vega | D29: =Q3_worksheet!D54 -> 0 | E29: =Q3_worksheet!E54 -> 0 | F29: =IFERROR(E29/D29,0) -> 0 | G29: =Q3_worksheet!F54 -> 10 | H29: =Q3_worksheet!G54 -> 190 | I29: =IFERROR(H29/G29,0) -> 19 | J29: =G29-D29 -> 10 | K29: =H29-E29 -> 190 | L29: =I29-F29 -> 19
A30: =Q3_worksheet!A55 -> 001 | B30: =Q3_worksheet!B55 -> 357 | C30: =Q3_worksheet!C55 -> Jesus Peterson | D30: =Q3_worksheet!D55 -> 0 | E30: =Q3_worksheet!E55 -> 0 | F30: =IFERROR(E30/D30,0) -> 0 | G30: =Q3_worksheet!F55 -> 49 | H30: =Q3_worksheet!G55 -> 26875 | I30: =IFERROR(H30/G30,0) -> 548.46939 | J30: =G30-D30 -> 49 | K30: =H30-E30 -> 26875 | L30: =I30-F30 -> 548.46939
A31: =Q3_worksheet!A56 -> 001 | B31: =Q3_worksheet!B56 -> 357 | C31: =Q3_worksheet!C56 -> Stanley Peterson | D31: =Q3_worksheet!D56 -> 4 | E31: =Q3_worksheet!E56 -> 80 | F31: =IFERROR(E31/D31,0) -> 20 | G31: =Q3_worksheet!F56 -> 0 | H31: =Q3_worksheet!G56 -> 0 | I31: =IFERROR(H31/G31,0) -> 0 | J31: =G31-D31 -> -4 | K31: =H31-E31 -> -80 | L31: =I31-F31 -> -20
A32: =Q3_worksheet!A35 -> 001 | B32: =Q3_worksheet!B35 -> 27 | C32: =Q3_worksheet!C35 -> Cindy Lunt | D32: =Q3_worksheet!D35 -> 644 | E32: =Q3_worksheet!E35 -> 239490 | F32: =IFERROR(E32/D32,0) -> 371.87888 | G32: =Q3_worksheet!F35 -> 327 | H32: =Q3_worksheet!G35 -> 478089 | I32: =IFERROR(H32/G32,0) -> 1462.0459 | J32: =G32-D32 -> -317 | K32: =H32-E32 -> 238599 | L32: =I32-F32 -> 1090.167
A33: =Q3_worksheet!A86 -> 002 | B33: =Q3_worksheet!B86 -> 27 | C33: =Q3_worksheet!C86 -> Cindy Lunt | D33: =Q3_worksheet!D86 -> 783 | E33: =Q3_worksheet!E86 -> 271697 | F33: =IFERROR(E33/D33,0) -> 346.99489 | G33: =Q3_worksheet!F86 -> 418 | H33: =Q3_worksheet!G86 -> 470466 | I33: =IFERROR(H33/G33,0) -> 1125.5167 | J33: =G33-D33 -> -365 | K33: =H33-E33 -> 198769 | L33: =I33-F33 -> 778.52185
A34: =Q3_worksheet!A142 -> 004 | B34: =Q3_worksheet!B142 -> 27 | C34: =Q3_worksheet!C142 -> Cindy Lunt | D34: =Q3_worksheet!D142 -> 291 | E34: =Q3_worksheet!E142 -> 117275 | F34: =IFERROR(E34/D34,0) -> 403.00687 | G34: =Q3_worksheet!F142 -> 735 | H34: =Q3_worksheet!G142 -> 241714 | I34: =IFERROR(H34/G34,0) -> 328.86259 | J34: =G34-D34 -> 444 | K34: =H34-E34 -> 124439 | L34: =I34-F34 -> -74.144288
A35: =Q3_worksheet!A235 -> 006 | B35: =Q3_worksheet!B235 -> 27 | C35: =Q3_worksheet!C235 -> Cindy Lunt | D35: =Q3_worksheet!D235 -> 272 | E35: =Q3_worksheet!E235 -> 112760 | F35: =IFERROR(E35/D35,0) -> 414.55882 | G35: =Q3_worksheet!F235 -> 96 | H35: =Q3_worksheet!G235 -> 320313 | I35: =IFERROR(H35/G35,0) -> 3336.5938 | J35: =G35-D35 -> -176 | K35: =H35-E35 -> 207553 | L35: =I35-F35 -> 2922.0349
A36: =Q3_worksheet!A275 -> 008 | B36: =Q3_worksheet!B275 -> 27 | C36: =Q3_worksheet!C275 -> Cindy Lunt | D36: =Q3_worksheet!D275 -> 117 | E36: =Q3_worksheet!E275 -> 51942 | F36: =IFERROR(E36/D36,0) -> 443.94872 | G36: =Q3_worksheet!F275 -> 48 | H36: =Q3_worksheet!G275 -> 157076 | I36: =IFERROR(H36/G36,0) -> 3272.4167 | J36: =G36-D36 -> -69 | K36: =H36-E36 -> 105134 | L36: =I36-F36 -> 2828.4679
A37: =Q3_worksheet!A62 -> 001 | B37: =Q3_worksheet!B62 -> 385 | C37: =Q3_worksheet!C62 -> Lillian Jefferson | D37: =Q3_worksheet!D62 -> 82 | E37: =Q3_worksheet!E62 -> 1230 | F37: =IFERROR(E37/D37,0) -> 15 | G37: =Q3_worksheet!F62 -> 0 | H37: =Q3_worksheet!G62 -> 0 | I37: =IFERROR(H37/G37,0) -> 0 | J37: =G37-D37 -> -82 | K37: =H37-E37 -> -1230 | L37: =I37-F37 -> -15
A38: =Q3_worksheet!A225 -> 005 | B38: =Q3_worksheet!B225 -> 411 | C38: =Q3_worksheet!C225 -> Claire Edwards | D38: =Q3_worksheet!D225 -> 25 | E38: =Q3_worksheet!E225 -> 5625 | F38: =IFERROR(E38/D38,0) -> 225 | G38: =Q3_worksheet!F225 -> 25 | H38: =Q3_worksheet!G225 -> 573 | I38: =IFERROR(H38/G38,0) -> 22.92 | J38: =G38-D38 -> 0 | K38: =H38-E38 -> -5052 | L38: =I38-F38 -> -202.08
A39: =Q3_worksheet!A47 -> 001 | B39: =Q3_worksheet!B47 -> 239 | C39: =Q3_worksheet!C47 -> Clarence Padilla | D39: =Q3_worksheet!D47 -> 38339 | E39: =Q3_worksheet!E47 -> 1350365 | F39: =IFERROR(E39/D39,0) -> 35.221706 | G39: =Q3_worksheet!F47 -> 46219 | H39: =Q3_worksheet!G47 -> 1985158 | I39: =IFERROR(H39/G39,0) -> 42.951124 | J39: =G39-D39 -> 7880 | K39: =H39-E39 -> 634793 | L39: =I39-F39 -> 7.7294176
A40: =Q3_worksheet!A265 -> 007 | B40: =Q3_worksheet!B265 -> 239 | C40: =Q3_worksheet!C265 -> Clarence Padilla | D40: =Q3_worksheet!D265 -> 1406 | E40: =Q3_worksheet!E265 -> 61328 | F40: =IFERROR(E40/D40,0) -> 43.618777 | G40: =Q3_worksheet!F265 -> 105 | H40: =Q3_worksheet!G265 -> 24676 | I40: =IFERROR(H40/G40,0) -> 235.00952 | J40: =G40-D40 -> -1301 | K40: =H40-E40 -> -36652 | L40: =I40-F40 -> 191.39075
...

Sheet P3_Q1
A1: Job code | B1: Employee number | C1: 2015 total hours | D1: 2015 gross pay | E1: 2015 gross pay per hour | F1: 2016 total hours | G1: 2016 gross pay | H1: 2016 gross pay per hour | I1: Hours difference | J1: Totral gross pay difference | K1: Gross pay per hour difference
A2: =Q3_worksheet!A13 -> 009 | B2: =Q3_worksheet!B13 -> New Foreign Manufacturing Plant | C2: =Q3_worksheet!C13 -> 0 | D2: =Q3_worksheet!D13 -> 0 | E2: =IFERROR(Table4[[#This Row],[2015 gross pay]]/Table4[[#This Row],[2015 total hours]],0) -> 0 | F2: =Q3_worksheet!E13 -> 24579 | G2: =Q3_worksheet!F13 -> 6238118 | H2: =IFERROR(Table4[[#This Row],[2016 gross pay]]/Table4[[#This Row],[2016 total hours]],0) -> 253.79869 | I2: =Table4[[#This Row],[2016 total hours]]-Table4[[#This Row],[2015 gross pay]] -> 24579 | J2: =Table4[[#This Row],[2016 gross pay]]-Table4[[#This Row],[2015 gross pay]] -> 6238118 | K2: =Table4[[#This Row],[2016 gross pay per hour]]-Table4[[#This Row],[2015 gross pay per hour]] -> 253.79869
A3: =Q3_worksheet!A5 -> 001 | B3: =Q3_worksheet!B5 -> Office | C3: =Q3_worksheet!C5 -> 89442 | D3: =Q3_worksheet!D5 -> 13178934 | E3: =IFERROR(Table4[[#This Row],[2015 gross pay]]/Table4[[#This Row],[2015 total hours]],0) -> 147.34615 | F3: =Q3_worksheet!E5 -> 283090 | G3: =Q3_worksheet!F5 -> 18784220 | H3: =IFERROR(Table4[[#This Row],[2016 gross pay]]/Table4[[#This Row],[2016 total hours]],0) -> 66.354234 | I3: =Table4[[#This Row],[2016 total hours]]-Table4[[#This Row],[2015 gross pay]] -> -12895844 | J3: =Table4[[#This Row],[2016 gross pay]]-Table4[[#This Row],[2015 gross pay]] -> 5605286 | K3: =Table4[[#This Row],[2016 gross pay per hour]]-Table4[[#This Row],[2015 gross pay per hour]] -> -80.991912
A4: =Q3_worksheet!A10 -> 006 | B4: =Q3_worksheet!B10 -> Service | C4: =Q3_worksheet!C10 -> 10406 | D4: =Q3_worksheet!D10 -> 5376020 | E4: =IFERROR(Table4[[#This Row],[2015 gross pay]]/Table4[[#This Row],[2015 total hours]],0) -> 516.62695 | F4: =Q3_worksheet!E10 -> 64249 | G4: =Q3_worksheet!F10 -> 8367948 | H4: =IFERROR(Table4[[#This Row],[2016 gross pay]]/Table4[[#This Row],[2016 total hours]],0) -> 130.24246 | I4: =Table4[[#This Row],[2016 total hours]]-Table4[[#This Row],[2015 gross pay]] -> -5311771 | J4: =Table4[[#This Row],[2016 gross pay]]-Table4[[#This Row],[2015 gross pay]] -> 2991928 | K4: =Table4[[#This Row],[2016 gross pay per hour]]-Table4[[#This Row],[2015 gross pay per hour]] -> -386.38448
A5: =Q3_worksheet!A12 -> 008 | B5: =Q3_worksheet!B12 -> Employee Training | C5: =Q3_worksheet!C12 -> 3843 | D5: =Q3_worksheet!D12 -> 1204204 | E5: =IFERROR(Table4[[#This Row],[2015 gross pay]]/Table4[[#This Row],[2015 total hours]],0) -> 313.34999 | F5: =Q3_worksheet!E12 -> 14072 | G5: =Q3_worksheet!F12 -> 2814657 | H5: =IFERROR(Table4[[#This Row],[2016 gross pay]]/Table4[[#This Row],[2016 total hours]],0) -> 200.01826 | I5: =Table4[[#This Row],[2016 total hours]]-Table4[[#This Row],[2015 gross pay]] -> -1190132 | J5: =Table4[[#This Row],[2016 gross pay]]-Table4[[#This Row],[2015 gross pay]] -> 1610453 | K5: =Table4[[#This Row],[2016 gross pay per hour]]-Table4[[#This Row],[2015 gross pay per hour]] -> -113.33172
A6: =Q3_worksheet!A8 -> 004 | B6: =Q3_worksheet!B8 -> Proj Management | C6: =Q3_worksheet!C8 -> 4784 | D6: =Q3_worksheet!D8 -> 3339832 | E6: =IFERROR(Table4[[#This Row],[2015 gross pay]]/Table4[[#This Row],[2015 total hours]],0) -> 698.12542 | F6: =Q3_worksheet!E8 -> 12359 | G6: =Q3_worksheet!F8 -> 4928450 | H6: =IFERROR(Table4[[#This Row],[2016 gross pay]]/Table4[[#This Row],[2016 total hours]],0) -> 398.77417 | I6: =Table4[[#This Row],[2016 total hours]]-Table4[[#This Row],[2015 gross pay]] -> -3327473 | J6: =Table4[[#This Row],[2016 gross pay]]-Table4[[#This Row],[2015 gross pay]] -> 1588618 | K6: =Table4[[#This Row],[2016 gross pay per hour]]-Table4[[#This Row],[2015 gross pay per hour]] -> -299.35125
A7: =Q3_worksheet!A14 -> 010 | B7: =Q3_worksheet!B14 -> New Foreign Manufacturing Oversight | C7: =Q3_worksheet!C14 -> 0 | D7: =Q3_worksheet!D14 -> 0 | E7: =IFERROR(Table4[[#This Row],[2015 gross pay]]/Table4[[#This Row],[2015 total hours]],0) -> 0 | F7: =Q3_worksheet!E14 -> 1300 | G7: =Q3_worksheet!F14 -> 1270293 | H7: =IFERROR(Table4[[#This Row],[2016 gross pay]]/Table4[[#This Row],[2016 total hours]],0) -> 977.14846 | I7: =Table4[[#This Row],[2016 total hours]]-Table4[[#This Row],[2015 gross pay]] -> 1300 | J7: =Table4[[#This Row],[2016 gross pay]]-Table4[[#This Row],[2015 gross pay]] -> 1270293 | K7: =Table4[[#This Row],[2016 gross pay per hour]]-Table4[[#This Row],[2015 gross pay per hour]] -> 977.14846
A8: =Q3_worksheet!A16 -> 012 | B8: =Q3_worksheet!B16 -> Internal Auditing | C8: =Q3_worksheet!C16 -> 0 | D8: =Q3_worksheet!D16 -> 0 | E8: =IFERROR(Table4[[#This Row],[2015 gross pay]]/Table4[[#This Row],[2015 total hours]],0) -> 0 | F8: =Q3_worksheet!E16 -> 1589 | G8: =Q3_worksheet!F16 -> 953068 | H8: =IFERROR(Table4[[#This Row],[2016 gross pay]]/Table4[[#This Row],[2016 total hours]],0) -> 599.79106 | I8: =Table4[[#This Row],[2016 total hours]]-Table4[[#This Row],[2015 gross pay]] -> 1589 | J8: =Table4[[#This Row],[2016 gross pay]]-Table4[[#This Row],[2015 gross pay]] -> 953068 | K8: =Table4[[#This Row],[2016 gross pay per hour]]-Table4[[#This Row],[2015 gross pay per hour]] -> 599.79106
A9: =Q3_worksheet!A6 -> 002 | B9: =Q3_worksheet!B6 -> Sales | C9: =Q3_worksheet!C6 -> 26247 | D9: =Q3_worksheet!D6 -> 39621371 | E9: =IFERROR(Table4[[#This Row],[2015 gross pay]]/Table4[[#This Row],[2015 total hours]],0) -> 1509.5581 | F9: =Q3_worksheet!E6 -> 52576 | G9: =Q3_worksheet!F6 -> 40154639 | H9: =IFERROR(Table4[[#This Row],[2016 gross pay]]/Table4[[#This Row],[2016 total hours]],0) -> 763.74466 | I9: =Table4[[#This Row],[2016 total hours]]-Table4[[#This Row],[2015 gross pay]] -> -39568795 | J9: =Table4[[#This Row],[2016 gross pay]]-Table4[[#This Row],[2015 gross pay]] -> 533268 | K9: =Table4[[#This Row],[2016 gross pay per hour]]-Table4[[#This Row],[2015 gross pay per hour]] -> -745.81343
A10: =Q3_worksheet!A15 -> 011 | B10: =Q3_worksheet!B15 -> Internal Projects | C10: =Q3_worksheet!C15 -> 0 | D10: =Q3_worksheet!D15 -> 0 | E10: =IFERROR(Table4[[#This Row],[2015 gross pay]]/Table4[[#This Row],[2015 total hours]],0) -> 0 | F10: =Q3_worksheet!E15 -> 100 | G10: =Q3_worksheet!F15 -> 70281 | H10: =IFERROR(Table4[[#This Row],[2016 gross pay]]/Table4[[#This Row],[2016 total hours]],0) -> 702.81 | I10: =Table4[[#This Row],[2016 total hours]]-Table4[[#This Row],[2015 gross pay]] -> 100 | J10: =Table4[[#This Row],[2016 gross pay]]-Table4[[#This Row],[2015 gross pay]] -> 70281 | K10: =Table4[[#This Row],[2016 gross pay per hour]]-Table4[[#This Row],[2015 gross pay per hour]] -> 702.81
A11: =Q3_worksheet!A9 -> 005 | B11: =Q3_worksheet!B9 -> Installation | C11: =Q3_worksheet!C9 -> 1430 | D11: =Q3_worksheet!D9 -> 162539 | E11: =IFERROR(Table4[[#This Row],[2015 gross pay]]/Table4[[#This Row],[2015 total hours]],0) -> 113.66364 | F11: =Q3_worksheet!E9 -> 2192 | G11: =Q3_worksheet!F9 -> 164085 | H11: =IFERROR(Table4[[#This Row],[2016 gross pay]]/Table4[[#This Row],[2016 total hours]],0) -> 74.856296 | I11: =Table4[[#This Row],[2016 total hours]]-Table4[[#This Row],[2015 gross pay]] -> -160347 | J11: =Table4[[#This Row],[2016 gross pay]]-Table4[[#This Row],[2015 gross pay]] -> 1546 | K11: =Table4[[#This Row],[2016 gross pay per hour]]-Table4[[#This Row],[2015 gross pay per hour]] -> -38.807341
A12: =Q3_worksheet!A17 -> 144 | B12: =Q3_worksheet!B17 -> 0 | C12: =Q3_worksheet!C17 -> 1 | D12: =Q3_worksheet!D17 -> 315 | E12: =IFERROR(Table4[[#This Row],[2015 gross pay]]/Table4[[#This Row],[2015 total hours]],0) -> 315 | F12: =Q3_worksheet!E17 -> 0 | G12: =Q3_worksheet!F17 -> 0 | H12: =IFERROR(Table4[[#This Row],[2016 gross pay]]/Table4[[#This Row],[2016 total hours]],0) -> 0 | I12: =Table4[[#This Row],[2016 total hours]]-Table4[[#This Row],[2015 gross pay]] -> -315 | J12: =Table4[[#This Row],[2016 gross pay]]-Table4[[#This Row],[2015 gross pay]] -> -315 | K12: =Table4[[#This Row],[2016 gross pay per hour]]-Table4[[#This Row],[2015 gross pay per hour]] -> -315
A13: =Q3_worksheet!A7 -> 003 | B13: =Q3_worksheet!B7 -> Travel | C13: =Q3_worksheet!C7 -> 1064 | D13: =Q3_worksheet!D7 -> 2678797 | E13: =IFERROR(Table4[[#This Row],[2015 gross pay]]/Table4[[#This Row],[2015 total hours]],0) -> 2517.6664 | F13: =Q3_worksheet!E7 -> 6054 | G13: =Q3_worksheet!F7 -> 1926817 | H13: =IFERROR(Table4[[#This Row],[2016 gross pay]]/Table4[[#This Row],[2016 total hours]],0) -> 318.27172 | I13: =Table4[[#This Row],[2016 total hours]]-Table4[[#This Row],[2015 gross pay]] -> -2672743 | J13: =Table4[[#This Row],[2016 gross pay]]-Table4[[#This Row],[2015 gross pay]] -> -751980 | K13: =Table4[[#This Row],[2016 gross pay per hour]]-Table4[[#This Row],[2015 gross pay per hour]] -> -2199.3946
A14: =Q3_worksheet!A11 -> 007 | B14: =Q3_worksheet!B11 -> Customer Training | C14: =Q3_worksheet!C11 -> 1846 | D14: =Q3_worksheet!D11 -> 2014041 | E14: =IFERROR(Table4[[#This Row],[2015 gross pay]]/Table4[[#This Row],[2015 total hours]],0) -> 1091.0298 | F14: =Q3_worksheet!E11 -> 443 | G14: =Q3_worksheet!F11 -> 257149 | H14: =IFERROR(Table4[[#This Row],[2016 gross pay]]/Table4[[#This Row],[2016 total hours]],0) -> 580.47178 | I14: =Table4[[#This Row],[2016 total hours]]-Table4[[#This Row],[2015 gross pay]] -> -2013598 | J14: =Table4[[#This Row],[2016 gross pay]]-Table4[[#This Row],[2015 gross pay]] -> -1756892 | K14: =Table4[[#This Row],[2016 gross pay per hour]]-Table4[[#This Row],[2015 gross pay per hour]] -> -510.55801
A15: note:job code 144, comes from project 14S1440, It most likely to be an project code error

Sheet Q3_worksheet
C2: YEAR | D2: Values
C3: 2015 | E3: 2016
A4: Job_code | B4: Job_description | C4: Total_Hours | D4: Gross_Wages | E4: Total_Hours | F4: Gross_Wages
A5: 001 | B5: Office | C5: 89442 | D5: 13178934 | E5: 283090 | F5: 18784220
A6: 002 | B6: Sales | C6: 26247 | D6: 39621371 | E6: 52576 | F6: 40154639
A7: 003 | B7: Travel | C7: 1064 | D7: 2678797 | E7: 6054 | F7: 1926817
A8: 004 | B8: Proj Management | C8: 4784 | D8: 3339832 | E8: 12359 | F8: 4928450
A9: 005 | B9: Installation | C9: 1430 | D9: 162539 | E9: 2192 | F9: 164085
A10: 006 | B10: Service | C10: 10406 | D10: 5376020 | E10: 64249 | F10: 8367948
A11: 007 | B11: Customer Training | C11: 1846 | D11: 2014041 | E11: 443 | F11: 257149
A12: 008 | B12: Employee Training | C12: 3843 | D12: 1204204 | E12: 14072 | F12: 2814657
A13: 009 | B13: New Foreign Manufacturing Plant | C13: 0 | D13: 0 | E13: 24579 | F13: 6238118
A14: 010 | B14: New Foreign Manufacturing Oversight | C14: 0 | D14: 0 | E14: 1300 | F14: 1270293
A15: 011 | B15: Internal Projects | C15: 0 | D15: 0 | E15: 100 | F15: 70281
A16: 012 | B16: Internal Auditing | C16: 0 | D16: 0 | E16: 1589 | F16: 953068
A17: 144 | C17: 1 | D17: 315
A18: 144, comes from project 14S1440, I think it is an error
D24: YEAR | E24: Values
D25: 2015 | E25: 2015 | F25: 2016 | G25: 2016
A26: Job_code | B26: Emp_No | C26: Emp_Name | D26: Sum of Total_Hours | E26: Sum of Gross_Wages | F26: Sum of Total_Hours | G26: Sum of Gross_Wages
A27: 001 | B27: (blank) | F27: 16565 | G27: 12580
A28: 001 | B28: 1 | C28: Antonio Torres | D28: 911 | E28: 2011582 | F28: 1101 | G28: 3005624
A29: 001 | B29: 3 | C29: Melanie Green | D29: 849 | E29: 2089458 | F29: 938 | G29: 720018
A30: 001 | B30: 7 | C30: Shelia Keller | D30: 3 | E30: 6868 | F30: 580 | G30: 1418184
A31: 001 | B31: 18 | C31: Marty Barnes | D31: 4998 | E31: 12840 | F31: 74200 | G31: 14840
A32: 001 | B32: 19 | C32: Frank Diaz | F32: 4 | G32: 108
A33: 001 | B33: 22 | C33: Marion Scott | F33: 29 | G33: 78931
A34: 001 | B34: 25 | C34: Tami Luna | D34: 4301 | E34: 1107808 | F34: 4947 | G34: 1100882
A35: 001 | B35: 27 | C35: Cindy Lunt | D35: 644 | E35: 239490 | F35: 327 | G35: 478089
A36: 001 | B36: 30 | C36: Joe Perry | D36: 2 | E36: 4873 | F36: 155 | G36: 38905
A37: 001 | B37: 34 | C37: Sheryl Hill | D37: 4 | E37: 20815 | F37: 108 | G37: 531011
A38: 001 | B38: 37 | C38: Kirk Byrd | F38: 5 | G38: 1225
A39: 001 | B39: 44 | C39: Dale Hamilton | D39: 1040 | E39: 100100 | F39: 1000 | G39: 96250
A40: 001 | B40: 106 | C40: Allan Wood | D40: 646 | E40: 227334
A41: 001 | B41: 168 | C41: Brittany Carlson | D41: 122 | E41: 74453 | F41: 10 | G41: 375
A42: 001 | B42: 180 | C42: Elisa Warren | D42: 51 | E42: 37782 | F42: 175 | G42: 7510
A43: 001 | B43: 194 | C43: Hector Wright | D43: 4 | E43: 90
A44: 001 | B44: 199 | C44: Nettie Stevens | D44: 6 | E44: 2142 | F44: 3 | G44: 1091
A45: 001 | B45: 203 | C45: Helen Paul | D45: 466 | E45: 3020213 | F45: 461 | G45: 2970103
A46: 001 | B46: 210 | C46: Kenny Robertson | D46: 743 | E46: 496408 | F46: 84 | G46: 199752
...

Sheet P1_5Qs
A1: 1.What is the employees’ number in 2016 comparing to 2015? | I1: 3. which job categories contributed most to the increase?
A2: Row Labels | B2: Employee number | J2: YEAR | K2: Values
A3: 2015 | B3: 851 | J3: 2015 | L3: 2016
A4: 2016 | B4: 804 | I4: Job_description | J4: Sum of gross wages | K4: Difference | L4: Sum of gross wages | M4: Difference
A5: Grand Total | B5: 1655 | J5: 315
I6: Customer Training | J6: 2014041 | L6: 257149 | M6: -0.87232186
A7: The increase in payroll expenses in 2016 was not driven by an increase in the number of employees. | I7: Employee Training | J7: 1204204 | L7: 2814657 | M7: 1.337359
A8: In fact, the number of employees slightly decreased from 851 in 2015 to 804 in 2016. | I8: Installation | J8: 162539 | L8: 164085 | M8: 0.0095115634
I9: Internal Auditing | J9: 0 | L9: 953068
I10: Internal Projects | J10: 0 | L10: 70281
I11: New Foreign Manufacturing Oversight | J11: 0 | L11: 1270293
A12: 2.Did total salary per employee increase? | I12: New Foreign Manufacturing Plant | J12: 0 | L12: 6238118
A13: Total gross wages increased significantly from 67.6 million in 2015 to 85.9 million in 2016, representing a 27.16% increase. | I13: Office | J13: 13178934 | L13: 18784220 | M13: 0.42532165
A14: However, this increase was not uniform across all employees. | I14: Proj Management | J14: 3339832 | L14: 4928450 | M14: 0.47565806
A15: Some employees experienced substantial salary increases, while others saw decreases or were not present in both years. | I15: Sales | J15: 39621371 | L15: 40154639 | M15: 0.0134591
A16: Additionally, new employees appeared in 2016 while some from 2015 were no longer present. | I16: Service | J16: 5376020 | L16: 8367948 | M16: 0.55653216
A17: This suggests that the increase in payroll was driven by changes in workforce composition and significant salary increases for certain individuals, | I17: Travel | J17: 2678797 | L17: 1926817 | M17: -0.28071556
A18: rather than a consistent rise in salary across all employees. | I18: Grand Total | J18: 67576053 | L18: 85929725 | M18: 0.27160024
B19: Column Labels | I19: As aboved data showed, the main contributors to the payroll increase were: Employee Training: +133.74%; Service: +55.65%; Project Management: +47.57%; Office: +42.53%.
B20: 2015 | D20: 2016 | I20: In addition, some job categories such as Internal Auditing, Internal Projects, and New Foreign Manufacturing roles appeared only in 2016, contributing additional costs.
A21: Row Labels | B21: Sum of Gross_Wages | C21: Gross_Wages difference | D21: Sum of Gross_Wages | E21: Gross_Wages difference | I21: On the other hand, some categories like Customer Training (-87.23%) and Travel (-28.07%) saw decreases, partially offsetting the increase.
D22: 1805269 | I22: Overall, the increase was mainly driven by core operational roles and newly introduced job categories.
A23: Afton Call | D23: 1740
A24: Al Ramos | B24: 2565652 | D24: 2776128 | E24: 0.082036067
A25: Alberta Gill | B25: 536328 | D25: 194385 | E25: -0.63756321
A26: Allan Wood | B26: 232644 | D26: 2327908 | E26: 9.0063101
A27: Allen Price | B27: 437 | D27: 3214 | E27: 6.3546911 | I27: 4.Was the increase driven by overtime or regular hours?
A28: Angel Watts | B28: 427 | D28: 1055 | E28: 1.470726 | J28: Values | K28: YEAR
A29: Antonio Torres | B29: 2011582 | D29: 3104730 | E29: 0.54342701 | J29: Sum of OT_Hrs | L29: Sum of Reg_Hrs
A30: Barry Mckenzie | B30: 446660 | D30: 813662 | E30: 0.82165853 | I30: Job_description | J30: 2015 | K30: 2016 | L30: 2015 | M30: 2016 | N30: OT hours difference | O30: Reg hour difference
A31: Beulah Gibbs | B31: 444461 | D31: 1022142 | E31: 1.2997338 | J31: 1 | L31: 0 | N31: =$K31-$J31 -> -1 | O31: =$M31-$L31 -> 0
A32: Brendan Curry | B32: 61298 | I32: Customer Training | J32: 0 | K32: 0 | L32: 1846 | M32: 443 | N32: =$K32-$J32 -> 0 | O32: =$M32-$L32 -> -1403
A33: Brittany Carlson | B33: 76703 | D33: 6345 | E33: -0.91727833 | I33: Employee Training | J33: 22 | K33: 9 | L33: 3821 | M33: 14063 | N33: =$K33-$J33 -> -13 | O33: =$M33-$L33 -> 10242
A34: Carlton Mcdonald | B34: 467 | I34: Installation | J34: 14 | K34: 0 | L34: 1416 | M34: 2192 | N34: =$K34-$J34 -> -14 | O34: =$M34-$L34 -> 776
A35: Cary Foster | B35: 2364766 | D35: 3749436 | E35: 0.58554208 | I35: Internal Auditing | J35: 0 | K35: 0 | L35: 0 | M35: 1589 | N35: =$K35-$J35 -> 0 | O35: =$M35-$L35 -> 1589
A36: Cassandra Poole | B36: 1321941 | D36: 2149618 | E36: 0.62610737 | I36: Internal Projects | J36: 0 | K36: 0 | L36: 0 | M36: 100 | N36: =$K36-$J36 -> 0 | O36: =$M36-$L36 -> 100
