Workbook
Name Slicer_FI: #N/A
Name Slicer_ID: #N/A

Sheet 2025 DEC Forecast
A1: ID | B1: ID.1.Name | C1: Date | D1: FI | E1: Type | F1: Bankdata Model forecast | G1: SND_Dec | H1: BiasAdj_Dec | I1: Chosen | J1: Final forecast | K1: Deviation from Bankdata
A2: 150 | B2: Securities | C2: 46022 | D2: 1 | E2: Forecast | F2: 246397.6 | G2: =SUMIFS(Actuals!$F:$F,Actuals!$A:$A,A2,Actuals!$D:$D,D2,Actuals!$B:$B,DATE(2024,12,31)) -> 242329.95 | H2: =F2*(1/(1+AVERAGEIFS(Forecasts!$L:$L,Forecasts!$A:$A,A2,Forecasts!$D:$D,D2,Forecasts!$R:$R,"1 train date (May-Aug)"))) -> 248333.39 | I2: =_xlfn.XLOOKUP(A2,'Forecast method comparsion'!$A$23:$A$35,'Forecast method comparsion'!$F$23:$F$35,"Model") -> Bias djust based on model | J2: =IF(ISNUMBER(SEARCH("SND",I2)),G2,IF(ISNUMBER(SEARCH("Bias",I2)),H2,F2)) -> 248333.39 | K2: =IFERROR((J2-F2)/F2,"") -> 0.0078563912
A3: 150 | B3: Securities | C3: 46022 | D3: 51 | E3: Forecast | F3: 276948.47 | G3: =SUMIFS(Actuals!$F:$F,Actuals!$A:$A,A3,Actuals!$D:$D,D3,Actuals!$B:$B,DATE(2024,12,31)) -> 265701.9 | H3: =F3*(1/(1+AVERAGEIFS(Forecasts!$L:$L,Forecasts!$A:$A,A3,Forecasts!$D:$D,D3,Forecasts!$R:$R,"1 train date (May-Aug)"))) -> 278480.03 | I3: =_xlfn.XLOOKUP(A3,'Forecast method comparsion'!$A$23:$A$35,'Forecast method comparsion'!$F$23:$F$35,"Model") -> Bias djust based on model | J3: =IF(ISNUMBER(SEARCH("SND",I3)),G3,IF(ISNUMBER(SEARCH("Bias",I3)),H3,F3)) -> 278480.03 | K3: =IFERROR((J3-F3)/F3,"") -> 0.0055301223
A4: 2370 | B4: Foreign Securities | C4: 46022 | D4: 1 | E4: Forecast | F4: 18442.8 | G4: =SUMIFS(Actuals!$F:$F,Actuals!$A:$A,A4,Actuals!$D:$D,D4,Actuals!$B:$B,DATE(2024,12,31)) -> 16240.95 | H4: =F4*(1/(1+AVERAGEIFS(Forecasts!$L:$L,Forecasts!$A:$A,A4,Forecasts!$D:$D,D4,Forecasts!$R:$R,"1 train date (May-Aug)"))) -> 19780.137 | I4: =_xlfn.XLOOKUP(A4,'Forecast method comparsion'!$A$23:$A$35,'Forecast method comparsion'!$F$23:$F$35,"Model") -> Bias djust based on model | J4: =IF(ISNUMBER(SEARCH("SND",I4)),G4,IF(ISNUMBER(SEARCH("Bias",I4)),H4,F4)) -> 19780.137 | K4: =IFERROR((J4-F4)/F4,"") -> 0.072512677
A5: 360 | B5: Domestic Securities | C5: 46022 | D5: 1 | E5: Forecast | F5: 52822.181 | G5: =SUMIFS(Actuals!$F:$F,Actuals!$A:$A,A5,Actuals!$D:$D,D5,Actuals!$B:$B,DATE(2024,12,31)) -> 49146.75 | H5: =F5*(1/(1+AVERAGEIFS(Forecasts!$L:$L,Forecasts!$A:$A,A5,Forecasts!$D:$D,D5,Forecasts!$R:$R,"1 train date (May-Aug)"))) -> 52530.399 | I5: =_xlfn.XLOOKUP(A5,'Forecast method comparsion'!$A$23:$A$35,'Forecast method comparsion'!$F$23:$F$35,"Model") -> Model | J5: =IF(ISNUMBER(SEARCH("SND",I5)),G5,IF(ISNUMBER(SEARCH("Bias",I5)),H5,F5)) -> 52822.181 | K5: =IFERROR((J5-F5)/F5,"") -> 0
A6: 9649 | B6: Credit cases | C6: 46022 | D6: 1 | E6: Forecast | F6: 2124.9167 | G6: =SUMIFS(Actuals!$F:$F,Actuals!$A:$A,A6,Actuals!$D:$D,D6,Actuals!$B:$B,DATE(2024,12,31)) -> 2713.5 | H6: =F6*(1/(1+AVERAGEIFS(Forecasts!$L:$L,Forecasts!$A:$A,A6,Forecasts!$D:$D,D6,Forecasts!$R:$R,"1 train date (May-Aug)"))) -> 2245.5802 | I6: =_xlfn.XLOOKUP(A6,'Forecast method comparsion'!$A$23:$A$35,'Forecast method comparsion'!$F$23:$F$35,"Model") -> Bias djust based on model | J6: =IF(ISNUMBER(SEARCH("SND",I6)),G6,IF(ISNUMBER(SEARCH("Bias",I6)),H6,F6)) -> 2245.5802 | K6: =IFERROR((J6-F6)/F6,"") -> 0.056785047
A7: 9652 | B7: Reports | C7: 46022 | D7: 1 | E7: Forecast | F7: 63189.481 | G7: =SUMIFS(Actuals!$F:$F,Actuals!$A:$A,A7,Actuals!$D:$D,D7,Actuals!$B:$B,DATE(2024,12,31)) -> 71197.65 | H7: =F7*(1/(1+AVERAGEIFS(Forecasts!$L:$L,Forecasts!$A:$A,A7,Forecasts!$D:$D,D7,Forecasts!$R:$R,"1 train date (May-Aug)"))) -> 60357.708 | I7: =_xlfn.XLOOKUP(A7,'Forecast method comparsion'!$A$23:$A$35,'Forecast method comparsion'!$F$23:$F$35,"Model") -> Model | J7: =IF(ISNUMBER(SEARCH("SND",I7)),G7,IF(ISNUMBER(SEARCH("Bias",I7)),H7,F7)) -> 63189.481 | K7: =IFERROR((J7-F7)/F7,"") -> 0
A8: 9656 | B8: MobilePay transactions | C8: 46022 | D8: 1 | E8: Forecast | F8: 877784.22 | G8: =SUMIFS(Actuals!$F:$F,Actuals!$A:$A,A8,Actuals!$D:$D,D8,Actuals!$B:$B,DATE(2024,12,31)) -> 858139.65 | H8: =F8*(1/(1+AVERAGEIFS(Forecasts!$L:$L,Forecasts!$A:$A,A8,Forecasts!$D:$D,D8,Forecasts!$R:$R,"1 train date (May-Aug)"))) -> 910525.74 | I8: =_xlfn.XLOOKUP(A8,'Forecast method comparsion'!$A$23:$A$35,'Forecast method comparsion'!$F$23:$F$35,"Model") -> SND | J8: =IF(ISNUMBER(SEARCH("SND",I8)),G8,IF(ISNUMBER(SEARCH("Bias",I8)),H8,F8)) -> 858139.65 | K8: =IFERROR((J8-F8)/F8,"") -> -0.022379722
A9: 9657 | B9: Card transactions | C9: 46022 | D9: 1 | E9: Forecast | F9: 5833.8 | G9: =SUMIFS(Actuals!$F:$F,Actuals!$A:$A,A9,Actuals!$D:$D,D9,Actuals!$B:$B,DATE(2024,12,31)) -> 5353.2 | H9: =F9*(1/(1+AVERAGEIFS(Forecasts!$L:$L,Forecasts!$A:$A,A9,Forecasts!$D:$D,D9,Forecasts!$R:$R,"1 train date (May-Aug)"))) -> 5975.8526 | I9: =_xlfn.XLOOKUP(A9,'Forecast method comparsion'!$A$23:$A$35,'Forecast method comparsion'!$F$23:$F$35,"Model") -> SND | J9: =IF(ISNUMBER(SEARCH("SND",I9)),G9,IF(ISNUMBER(SEARCH("Bias",I9)),H9,F9)) -> 5353.2 | K9: =IFERROR((J9-F9)/F9,"") -> -0.082381981
A10: 9683 | B10: Logins Mobilbank/Netbank | C10: 46022 | D10: 1 | E10: Forecast | F10: 3790079.9 | G10: =SUMIFS(Actuals!$F:$F,Actuals!$A:$A,A10,Actuals!$D:$D,D10,Actuals!$B:$B,DATE(2024,12,31)) -> 3703664.7 | H10: =F10*(1/(1+AVERAGEIFS(Forecasts!$L:$L,Forecasts!$A:$A,A10,Forecasts!$D:$D,D10,Forecasts!$R:$R,"1 train date (May-Aug)"))) -> 3890749.4 | I10: =_xlfn.XLOOKUP(A10,'Forecast method comparsion'!$A$23:$A$35,'Forecast method comparsion'!$F$23:$F$35,"Model") -> SND | J10: =IF(ISNUMBER(SEARCH("SND",I10)),G10,IF(ISNUMBER(SEARCH("Bias",I10)),H10,F10)) -> 3703664.7 | K10: =IFERROR((J10-F10)/F10,"") -> -0.022800372
A11: 9692 | B11: Documents archived | C11: 46022 | D11: 1 | E11: Forecast | F11: 735985.8 | G11: =SUMIFS(Actuals!$F:$F,Actuals!$A:$A,A11,Actuals!$D:$D,D11,Actuals!$B:$B,DATE(2024,12,31)) -> 917622.9 | H11: =F11*(1/(1+AVERAGEIFS(Forecasts!$L:$L,Forecasts!$A:$A,A11,Forecasts!$D:$D,D11,Forecasts!$R:$R,"1 train date (May-Aug)"))) -> 675377.68 | I11: =_xlfn.XLOOKUP(A11,'Forecast method comparsion'!$A$23:$A$35,'Forecast method comparsion'!$F$23:$F$35,"Model") -> Model | J11: =IF(ISNUMBER(SEARCH("SND",I11)),G11,IF(ISNUMBER(SEARCH("Bias",I11)),H11,F11)) -> 735985.8 | K11: =IFERROR((J11-F11)/F11,"") -> 0
A12: 9700 | B12: Domestic transactions | C12: 46022 | D12: 1 | E12: Forecast | F12: 1126167.8 | G12: =SUMIFS(Actuals!$F:$F,Actuals!$A:$A,A12,Actuals!$D:$D,D12,Actuals!$B:$B,DATE(2024,12,31)) -> 1145662.7 | H12: =F12*(1/(1+AVERAGEIFS(Forecasts!$L:$L,Forecasts!$A:$A,A12,Forecasts!$D:$D,D12,Forecasts!$R:$R,"1 train date (May-Aug)"))) -> 1134700 | I12: =_xlfn.XLOOKUP(A12,'Forecast method comparsion'!$A$23:$A$35,'Forecast method comparsion'!$F$23:$F$35,"Model") -> SND | J12: =IF(ISNUMBER(SEARCH("SND",I12)),G12,IF(ISNUMBER(SEARCH("Bias",I12)),H12,F12)) -> 1145662.7 | K12: =IFERROR((J12-F12)/F12,"") -> 0.017310756
A13: 9701 | B13: International transactions | C13: 46022 | D13: 1 | E13: Forecast | F13: 24766.759 | G13: =SUMIFS(Actuals!$F:$F,Actuals!$A:$A,A13,Actuals!$D:$D,D13,Actuals!$B:$B,DATE(2024,12,31)) -> 24485.4 | H13: =F13*(1/(1+AVERAGEIFS(Forecasts!$L:$L,Forecasts!$A:$A,A13,Forecasts!$D:$D,D13,Forecasts!$R:$R,"1 train date (May-Aug)"))) -> 25049.436 | I13: =_xlfn.XLOOKUP(A13,'Forecast method comparsion'!$A$23:$A$35,'Forecast method comparsion'!$F$23:$F$35,"Model") -> SND | J13: =IF(ISNUMBER(SEARCH("SND",I13)),G13,IF(ISNUMBER(SEARCH("Bias",I13)),H13,F13)) -> 24485.4 | K13: =IFERROR((J13-F13)/F13,"") -> -0.011360336
... A105: 9768 | B105: Dopix documents | C105: 46022 | D105: 42 | E105: Forecast | F105: 529287.88 | G105: =SUMIFS(Actuals!$F:$F,Actuals!$A:$A,A105,Actuals!$D:$D,D105,Actuals!$B:$B,DATE(2024,12,31)) -> 389248.75 | H105: =F105*(1/(1+AVERAGEIFS(Forecasts!$L:$L,Forecasts!$A:$A,A105,Forecasts!$D:$D,D105,Forecasts!$R:$R,"1 train date (May-Aug)"))) -> 543059.93 | I105: =_xlfn.XLOOKUP(A105,'Forecast method comparsion'!$A$23:$A$35,'Forecast method comparsion'!$F$23:$F$35,"Model") -> Bias djust based on model | J105: =IF(ISNUMBER(SEARCH("SND",I105)),G105,IF(ISNUMBER(SEARCH("Bias",I105)),H105,F105)) -> 543059.93 | K105: =IFERROR((J105-F105)/F105,"") -> 0.026019957

Sheet Forecast method comparsion
A1: Existed model vs SND model (Train data for making choose, and test data for double check)
B3: Column Labels
B4: Model MAPE | D4: SND MAPE | F4: MAPE bias adjusted | H4: Total Model MAPE | I4: Total SND MAPE | J4: Total MAPE bias adjusted
A5: Row Labels | B5: 1 train date (May-Aug) | C5: 2 Test data (Sep-Nov) | D5: 1 train date (May-Aug) | E5: 2 Test data (Sep-Nov) | F5: 1 train date (May-Aug) | G5: 2 Test data (Sep-Nov)
A6: 150 | B6: 0.0083924156 | C6: 0.0071833592 | D6: 0.012430648 | E6: 0.013628576 | F6: 0.0081152085 | G6: 0.0059201151 | H6: 0.0081333321 | I6: 0.012687347 | J6: 0.0076448314
A7: 360 | B7: 0.22479379 | C7: 0.1679411 | D7: 0.3418703 | E7: 0.22851761 | F7: 0.22654848 | G7: 0.16837841 | H7: 0.21261107 | I7: 0.31758044 | J7: 0.21408346
A8: 2370 | B8: 0.22175927 | C8: 0.19741762 | D8: 0.21996919 | E8: 0.24847121 | F8: 0.2079582 | G8: 0.11793277 | H8: 0.2165432 | I8: 0.22607677 | J8: 0.18866704
A9: 9649 | B9: 0.10347219 | C9: 0.10786232 | D9: 0.11122584 | E9: 0.099378281 | F9: 0.093006958 | G9: 0.083026435 | H9: 0.10441294 | I9: 0.10868708 | J9: 0.090868274
A10: 9652 | B10: 0.13249074 | C10: 0.093025152 | D10: 0.27267166 | E10: 0.20004873 | F10: 0.12770391 | G10: 0.09600333 | H10: 0.12403383 | I10: 0.2571096 | J10: 0.12091092
A11: 9656 | B11: 0.06677858 | C11: 0.054274831 | D11: 0.052525726 | E11: 0.027635731 | F11: 0.067113077 | G11: 0.053736128 | H11: 0.064099205 | I11: 0.047192155 | J11: 0.064246588
A12: 9657 | B12: 0.055444727 | C12: 0.038584623 | D12: 0.050714786 | E12: 0.025586803 | F12: 0.052678442 | G12: 0.044685611 | H12: 0.051831848 | I12: 0.045330218 | J12: 0.050965692
A13: 9683 | B13: 0.050842929 | C13: 0.031529275 | D13: 0.045676863 | E13: 0.021214083 | F13: 0.04536081 | G13: 0.024854954 | H13: 0.046704289 | I13: 0.040434838 | J13: 0.040966698
A14: 9692 | B14: 0.12744896 | C14: 0.06854808 | D14: 0.26638753 | E14: 0.15694776 | F14: 0.11233673 | G14: 0.095624555 | H14: 0.11482735 | I14: 0.24293615 | J14: 0.10875555
A15: 9700 | B15: 0.053579473 | C15: 0.044669594 | D15: 0.047947518 | E15: 0.020566164 | F15: 0.049806154 | G15: 0.032491265 | H15: 0.051670213 | I15: 0.042080085 | J15: 0.046095821
A16: 9701 | B16: 0.065023013 | C16: 0.072402227 | D16: 0.070959571 | E16: 0.040355989 | F16: 0.064336851 | G16: 0.07131236 | H16: 0.066604273 | I16: 0.064401661 | J16: 0.065831603
A17: 9702 | B17: 0.063932788 | C17: 0.056271023 | D17: 0.073501692 | E17: 0.049266855 | F17: 0.064217252 | G17: 0.057252849 | H17: 0.062290981 | I17: 0.068308513 | J17: 0.06272488
A18: 9768 | B18: 0.18123252 | C18: 0.10583716 | D18: 0.33602793 | E18: 0.19382171 | F18: 0.1774228 | G18: 0.10080982 | H18: 0.16507637 | I18: 0.30555517 | J18: 0.16100573
A19: Grand Total | B19: 0.10424549 | C19: 0.080426644 | D19: 0.14630071 | E19: 0.10195688 | F19: 0.099738836 | G19: 0.073232969 | H19: 0.099141453 | I19: 0.13679846 | J19: 0.094059007
A21: Final pick for each ID
A22: ID | B22: ID name | C22: Model | D22: SND | E22: Bias-adj | F22: Winner
A23: 150 | B23: =_xlfn.XLOOKUP(A23,ID!A:A,ID!B:B,,0,1) -> Securities | C23: =C6 -> 0.0071833592 | D23: =E6 -> 0.013628576 | E23: =G6 -> 0.0059201151 | F23: Bias djust based on model
A24: 360 | B24: =_xlfn.XLOOKUP(A24,ID!A:A,ID!B:B,,0,1) -> Domestic Securities | C24: =C7 -> 0.1679411 | D24: =E7 -> 0.22851761 | E24: =G7 -> 0.16837841 | F24: Model
A25: 2370 | B25: =_xlfn.XLOOKUP(A25,ID!A:A,ID!B:B,,0,1) -> Foreign Securities | C25: =C8 -> 0.19741762 | D25: =E8 -> 0.24847121 | E25: =G8 -> 0.11793277 | F25: Bias djust based on model
A26: 9649 | B26: =_xlfn.XLOOKUP(A26,ID!A:A,ID!B:B,,0,1) -> Credit cases | C26: =C9 -> 0.10786232 | D26: =E9 -> 0.099378281 | E26: =G9 -> 0.083026435 | F26: Bias djust based on model
A27: 9652 | B27: =_xlfn.XLOOKUP(A27,ID!A:A,ID!B:B,,0,1) -> Reports | C27: =C10 -> 0.093025152 | D27: =E10 -> 0.20004873 | E27: =G10 -> 0.09600333 | F27: Model
A28: 9656 | B28: =_xlfn.XLOOKUP(A28,ID!A:A,ID!B:B,,0,1) -> MobilePay transactions | C28: =C11 -> 0.054274831 | D28: =E11 -> 0.027635731 | E28: =G11 -> 0.053736128 | F28: SND
A29: 9657 | B29: =_xlfn.XLOOKUP(A29,ID!A:A,ID!B:B,,0,1) -> Card transactions | C29: =C12 -> 0.038584623 | D29: =E12 -> 0.025586803 | E29: =G12 -> 0.044685611 | F29: SND
A30: 9683 | B30: =_xlfn.XLOOKUP(A30,ID!A:A,ID!B:B,,0,1) -> Logins Mobilbank/Netbank | C30: =C13 -> 0.031529275 | D30: =E13 -> 0.021214083 | E30: =G13 -> 0.024854954 | F30: SND
A31: 9692 | B31: =_xlfn.XLOOKUP(A31,ID!A:A,ID!B:B,,0,1) -> Documents archived | C31: =C14 -> 0.06854808 | D31: =E14 -> 0.15694776 | E31: =G14 -> 0.095624555 | F31: Model
A32: 9700 | B32: =_xlfn.XLOOKUP(A32,ID!A:A,ID!B:B,,0,1) -> Domestic transactions | C32: =C15 -> 0.044669594 | D32: =E15 -> 0.020566164 | E32: =G15 -> 0.032491265 | F32: SND
A33: 9701 | B33: =_xlfn.XLOOKUP(A33,ID!A:A,ID!B:B,,0,1) -> International transactions | C33: =C16 -> 0.072402227 | D33: =E16 -> 0.040355989 | E33: =G16 -> 0.07131236 | F33: SND
A34: 9702 | B34: =_xlfn.XLOOKUP(A34,ID!A:A,ID!B:B,,0,1) -> European transactions | C34: =C17 -> 0.056271023 | D34: =E17 -> 0.049266855 | E34: =G17 -> 0.057252849 | F34: SND
A35: 9768 | B35: =_xlfn.XLOOKUP(A35,ID!A:A,ID!B:B,,0,1) -> Dopix documents | C35: =C18 -> 0.10583716 | D35: =E18 -> 0.19382171 | E35: =G18 -> 0.10080982 | F35: Bias djust based on model
A37: the IDs where SND wins , MobilePay, cards, logins, domestic/international/European transactions ,are series with strong, consistent seasonal-and-trend structure. Their past genuinely predicts their future, because they grow smoothly and repeat their seasonal shape year over year.
A39: the IDs where SND loses badly ,Reports 9652, Dopix 9768, Documents 9692, SND at 16–20% vs model far lower, are series whose history does not cleanly predict their future. They're lumpy or event-driven.

Sheet December_Forecast_Plan
A1: Method | B1: Formula
A2: Bankdata forecast | B2: Latest November-vintage December forecast
A3: SND forecast | B3: Dec 2024 actual × recent YoY growth
A4: Bias-adjusted Bankdata | B4: Bankdata forecast × (1 - Historical Bias)
A5: I try all 3 and then compare MAPE and bias and thus apply for december
A7: Condition (from validated scores) | B7: Method assigned
A8: SND MAPE < model MAPE | B8: SND
A9: Model MAPE ≤ SND, low bias | B9: Keep Bankdata
A10: High and persistent one-directional bias | B10: Bias-adjusted Bankdata

Sheet Stabiliity of forecast model
A1: Stability of current forecast Accuracy only compares forecast to actual. Volatility compares forecasts to earlier forecasts. It shows whether the model is stable enough for planning.
A4: ID volidatility: how much the model changes its mind about a given month over time
A5: Sum of Q | B5: Forecast Month | J5: Volatility
A6: Date | B6: 5 | C6: 6 | D6: 7 | E6: 8 | F6: 9 | G6: 10 | H6: 11 | I6: Grand Total | J6: Revision spread
A7: 45808 | B7: 16843.019 | I7: 16843.019 | J7: =(MAX(B7:H7)-MIN(B7:H7))/AVERAGE(B7:H7) -> 0
A8: 45838 | B8: 16674.588 | C8: 16674.588 | I8: 33349.177 | J8: =(MAX(B8:H8)-MIN(B8:H8))/AVERAGE(B8:H8) -> 0
A9: 45869 | B9: 16507.842 | C9: 16507.842 | D9: 17242.186 | I9: 50257.871 | J9: =(MAX(B9:H9)-MIN(B9:H9))/AVERAGE(B9:H9) -> 0.04383457
A10: 45900 | B10: 16342.764 | C10: 16342.764 | D10: 17069.765 | E10: 13635.811 | I10: 63391.104 | J10: =(MAX(B10:H10)-MIN(B10:H10))/AVERAGE(B10:H10) -> 0.21668364
A11: 45930 | B11: 16179.336 | C11: 16179.336 | D11: 16899.067 | E11: 13666.675 | F11: 15668.521 | I11: 78592.936 | J11: =(MAX(B11:H11)-MIN(B11:H11))/AVERAGE(B11:H11) -> 0.20564136
A12: 45961 | B12: 16017.543 | C12: 16017.543 | D12: 16730.076 | E12: 14400 | F12: 15700.198 | G12: 17733.867 | I12: 96599.227 | J12: =(MAX(B12:H12)-MIN(B12:H12))/AVERAGE(B12:H12) -> 0.20707414
A13: 45991 | B13: 15857.368 | C13: 15857.368 | D13: 16562.776 | E13: 14850 | F13: 15729.895 | G13: 17772.611 | H13: 18645.75 | I13: 115275.77 | J13: =(MAX(B13:H13)-MIN(B13:H13))/AVERAGE(B13:H13) -> 0.23049294
A14: 46022 | B14: 15698.794 | C14: 15698.794 | D14: 16397.148 | E14: 15075 | F14: 15761.571 | G14: 17813.939 | H14: 18442.8 | I14: 114888.05 | J14: =(MAX(B14:H14)-MIN(B14:H14))/AVERAGE(B14:H14) -> 0.20519628
A15: Grand Total | B15: 130121.25 | C15: 113278.24 | D15: 100901.02 | E15: 71627.486 | F15: 62860.186 | G15: 53320.417 | H15: 37088.55 | I15: 569197.15
A16: Volatility depends on the cost type, so few representaive IDs has been checked
A17: FI 1: 150 (most accurate), 2370 (least accurate, most biased), and 360 (as inaccurate as 2370 but unbiased).
A18: 1. Stability mirrors accuracy: ID 150 is revised only ~2% across vintages, ID 2370 ~21% — the model changes its mind most about the series it forecasts worst.
A20: 2. ID 2370's revisions trend upward (November rises from ~15,800 to ~18,600) — the live counterpart of its −16% under-forecast: it starts too low and is pulled up as real data arrives.
A22: 3. Volatility not equal to bias: ID 360 is equally volatile but non-directional (near-zero bias), so 2370 is uniquely bad because it is volatile and one-directional.

Sheet Accumulation
A1: Cumulative deviation helps distinguish between operational monthly error and full-year budget impact
A2: Month | B2: Forecast | C2: Actual_Q | D2: Cumulate forecast | E2: Cumulate actual | F2: Cumulate deviation | K2: Reference ID | L2: 2370 | M2: =_xlfn.XLOOKUP(L2,ID!A:A,ID!B:B,"",0,1) -> Foreign Securities
A3: 45808 | B3: =SUMIFS(Forecasts[Q],Forecasts[ID],$L$2,Forecasts[FI],$L$3,Forecasts[FC_Month],5,Forecasts[Date],A3) -> 16843.019 | C3: =SUMIFS(Actuals[Q],Actuals[ID],$L$2,Actuals[FI],$L$3,Actuals[Date],A3) -> 15355.35 | D3: =B3 -> 16843.019 | E3: =C3 -> 15355.35 | F3: =(D3-E3)/E3 -> 0.096882748 | K3: Reference FI | L3: 1
A4: 45838 | B4: =SUMIFS(Forecasts[Q],Forecasts[ID],$L$2,Forecasts[FI],$L$3,Forecasts[FC_Month],5,Forecasts[Date],A4) -> 16674.588 | C4: =SUMIFS(Actuals[Q],Actuals[ID],$L$2,Actuals[FI],$L$3,Actuals[Date],A4) -> 17416.35 | D4: =D3+B4 -> 33517.607 | E4: =E3+C4 -> 32771.7 | F4: =(D4-E4)/E4 -> 0.022760699
A5: 45869 | B5: =SUMIFS(Forecasts[Q],Forecasts[ID],$L$2,Forecasts[FI],$L$3,Forecasts[FC_Month],5,Forecasts[Date],A5) -> 16507.842 | C5: =SUMIFS(Actuals[Q],Actuals[ID],$L$2,Actuals[FI],$L$3,Actuals[Date],A5) -> 13196.25 | D5: =D4+B5 -> 50025.449 | E5: =E4+C5 -> 45967.95 | F5: =(D5-E5)/E5 -> 0.088268005
A6: 45900 | B6: =SUMIFS(Forecasts[Q],Forecasts[ID],$L$2,Forecasts[FI],$L$3,Forecasts[FC_Month],5,Forecasts[Date],A6) -> 16342.764 | C6: =SUMIFS(Actuals[Q],Actuals[ID],$L$2,Actuals[FI],$L$3,Actuals[Date],A6) -> 16114.95 | D6: =D5+B6 -> 66368.213 | E6: =E5+C6 -> 62082.9 | F6: =(D6-E6)/E6 -> 0.069025662
A7: 45930 | B7: =SUMIFS(Forecasts[Q],Forecasts[ID],$L$2,Forecasts[FI],$L$3,Forecasts[FC_Month],5,Forecasts[Date],A7) -> 16179.336 | C7: =SUMIFS(Actuals[Q],Actuals[ID],$L$2,Actuals[FI],$L$3,Actuals[Date],A7) -> 17891.1 | D7: =D6+B7 -> 82547.55 | E7: =E6+C7 -> 79974 | F7: =(D7-E7)/E7 -> 0.032179829
A8: 45961 | B8: =SUMIFS(Forecasts[Q],Forecasts[ID],$L$2,Forecasts[FI],$L$3,Forecasts[FC_Month],5,Forecasts[Date],A8) -> 16017.543 | C8: =SUMIFS(Actuals[Q],Actuals[ID],$L$2,Actuals[FI],$L$3,Actuals[Date],A8) -> 21848.85 | D8: =D7+B8 -> 98565.093 | E8: =E7+C8 -> 101822.85 | F8: =(D8-E8)/E8 -> -0.031994364
A9: 45991 | B9: =SUMIFS(Forecasts[Q],Forecasts[ID],$L$2,Forecasts[FI],$L$3,Forecasts[FC_Month],5,Forecasts[Date],A9) -> 15857.368 | C9: =SUMIFS(Actuals[Q],Actuals[ID],$L$2,Actuals[FI],$L$3,Actuals[Date],A9) -> 18840.6 | D9: =D8+B9 -> 114422.46 | E9: =E8+C9 -> 120663.45 | F9: =(D9-E9)/E9 -> -0.051722289
A12: ID 2370
A13: the cumulative deviation starts positive and ends negative.
A14: For ID 2370, forecast bias on average is -16%, while here we can see cumulated devisation actually ends with -5%.
A15: so the under forecasting in the autumn months outweighs the over forecasting in summer.

Sheet Accuracy calculation
A1: Accuracy of forecast
A3: ID forecast accuracy | F3: Horizon forecast accuracy | J3: Forecast Month accuracy
A4: ID | B4: ID.1.Name | C4: MAPE - Average of APE | D4: BIAS - Average of signed error | F4: Horizon | G4: MAPE - Average of APE | H4: Count of APE | J4: FC Month | K4: MAPE - Average of APE | L4: Count of APE | M4: BIAS - Average of Signed error
A5: 150 | B5: Securities | C5: 0.0081333321 | D5: -0.0025673549 | F5: 0 | G5: 0.10093786 | H5: 728 | J5: 5 | K5: 0.10874655 | L5: 728 | M5: -0.02315562
A6: 360 | B6: Domestic Securities | C6: 0.21261107 | D6: -0.02905401 | F6: 1 | G6: 0.10435248 | H6: 624 | J6: 6 | K6: 0.10382333 | L6: 624 | M6: -0.013661308
A7: 2370 | B7: Foreign Securities | C7: 0.2165432 | D7: -0.16190301 | F7: 2 | G7: 0.093289968 | H7: 520 | J7: 7 | K7: 0.10345451 | L7: 520 | M7: -0.024823455
A8: 9649 | B8: Credit cases | C8: 0.10441294 | D8: -0.060052615 | F8: 3 | G8: 0.09295306 | H8: 416 | J8: 8 | K8: 0.097990615 | L8: 416 | M8: -0.0098261454
A9: 9652 | B9: Reports | C9: 0.12403383 | D9: 0.016547127 | F9: 4 | G9: 0.095512251 | H9: 312 | J9: 9 | K9: 0.0857998 | L9: 312 | M9: -0.010974404
A10: 9656 | B10: MobilePay transactions | C10: 0.064099205 | D10: -0.01761999 | F10: 5 | G10: 0.10166031 | H10: 208 | J10: 10 | K10: 0.076872454 | L10: 208 | M10: -0.037813433
A11: 9657 | B11: Card transactions | C11: 0.051831848 | D11: -0.01203306 | F11: 6 | G11: 0.11516139 | H11: 104 | J11: 11 | K11: 0.071415553 | L11: 104 | M11: -0.040419011
A12: 9683 | B12: Logins Mobilbank/Netbank | C12: 0.046704289 | D12: -0.021264699 | F12: 7 | J12: Grand Total | K12: 0.099141453 | L12: 2912 | M12: -0.019873148
A13: 9692 | B13: Documents archived | C13: 0.11482735 | D13: 0.055069017 | F13: Grand Total | G13: 0.099141453 | H13: 2912
A14: 9700 | B14: Domestic transactions | C14: 0.051670213 | D14: -0.02229266 | F14: The horizon table alone suggests that accuracy does not improve as the forecast horizon gets shorter. But this is partly an aggregation problem, because different horizons contain different target months | J14: MAPE falls steadily as the month gets later , from 10.9% (May) down to 7.1% (November).
A15: 9701 | B15: International transactions | C15: 0.066604273 | D15: -0.0062558145 | J15: On the surface this looks like the model improving over the year.
A16: 9702 | B16: European transactions | C16: 0.062290981 | D16: -0.016226108 | J16: Since the composition of ID and FI is same for each month
A17: 9768 | B17: Dopix documents | C17: 0.16507637 | D17: 0.019302255 | J17: and horizon does not improve forecast,
A18: Grand Total | C18: 0.099141453 | D18: -0.019873148 | J18: 2 reasons for better forecase in later month
A19: Forecast error are overall around 10% off. Most of accuracy can be accepted. 3 ID might need extra effort. | J19: 1. forecast model improved;2. later month is more stable to forecast
A20: 1. ID 360, Domestic Securities, has around20% off from the actual cost, while the BIAS is relatively low, which means the error distributed quite evenly. There are both forecast above and under the actual cost so the forecast aim is correct, but the individual months scatter widely. it is either due to underfitting. or irreducible noice (high randomness of the data) | F20: Target Month accuracy | J20: Cross check , forecast month vs target month
F21: Target Month | G21: MAPE - Average of APE | H21: Count of APE | J21: MAPE - Average of APE | K21: Forecast Month
F22: 45808 | G22: 0.10797919 | H22: 104 | J22: Target Month | K22: 5 | L22: 6 | M22: 7 | N22: 8 | O22: 9 | P22: 10 | Q22: 11 | R22: Grand Total
F23: 45838 | G23: 0.12514462 | H23: 208 | J23: 45808 | K23: 0.10797919 | R23: 0.10797919
A24: 2. ID 2370, Foreign Securtiies, has around 20% off from the actual cost, while the BIAS is relatively high,means most error is unde the actual cost, thus it is also relatively easy to increase the accuracy for forecast. A simple bias correction might be helpful. | F24: 45869 | G24: 0.13078885 | H24: 312 | J24: 45838 | K24: 0.13350849 | L24: 0.11678076 | R24: 0.12514462
F25: 45900 | G25: 0.097388191 | H25: 416 | J25: 45869 | K25: 0.12747244 | L25: 0.13261124 | M25: 0.13228287 | R25: 0.13078885
F26: 45930 | G26: 0.09024279 | H26: 520 | J26: 45900 | K26: 0.084438816 | L26: 0.093888141 | M26: 0.10378045 | N26: 0.10744536 | R26: 0.097388191
A27: 3. ID 9768, has around 16% off from the actual cost, while the BIAS is relatively low, which means the error distributed quite evenly. There are both forecast above and under the actual cost. so the forecast aim is correct, but the individual months scatter widely. it is either due to underfitting or irreducible noice(high randomness of the data) | F27: 45961 | G27: 0.087922122 | H27: 624 | J27: 45930 | K27: 0.091372365 | L27: 0.086398925 | M27: 0.077772763 | N27: 0.099408316 | O27: 0.096261581 | R27: 0.09024279
F28: 45991 | G28: 0.093860893 | H28: 728 | J28: 45961 | K28: 0.10129316 | L28: 0.091233437 | M28: 0.09950552 | N28: 0.083639809 | O28: 0.077461135 | P28: 0.074399674 | R28: 0.087922122
F29: 46022 | J29: 45991 | K29: 0.11516139 | L29: 0.10202746 | M29: 0.10393095 | N29: 0.10146898 | O29: 0.083676685 | P29: 0.079345234 | Q29: 0.071415553 | R29: 0.093860893
F30: Grand Total | G30: 0.099141453 | H30: 2912 | J30: 46022
F31: summer (May–July) is harder than autumn (August–November) | J31: Grand Total | K31: 0.10874655 | L31: 0.10382333 | M31: 0.10345451 | N31: 0.097990615 | O31: 0.0857998 | P31: 0.076872454 | Q31: 0.071415553 | R31: 0.099141453
A32: FI forecast accuracy | J32: The model DOES improve as the forecast horizon shorter, as more data arrives. Fresh information genuinely helps.
A33: Row Labels | B33: MAPE - Average of APE | C33: BIAS - Average of Signed error
A34: 1 | B34: 0.082407699 | C34: -0.017749647 | J34: Forecasts generally improve when more actual data becomes available, but some target months remain harder regardless of horizon.Summer months (May–Jul) remain genuinely harder regardless of horizon. So the month effect is real and independent of the forecast month effect.
A35: 8 | B35: 0.096443585 | C35: -0.034131826
A36: 9 | B36: 0.082796003 | C36: -0.0203041
A37: 13 | B37: 0.12120105 | C37: -0.061671355
A38: 15 | B38: 0.096340364 | C38: -0.02342949
A39: 24 | B39: 0.10919861 | C39: 0.013869394
A40: 42 | B40: 0.11557549 | C40: -0.043380411
A41: 51 | B41: 0.089168817 | C41: 0.027812252
...

Sheet Forecasts
A1: ID | B1: Date | C1: FC_Month | D1: FI | E1: Type | F1: Q | G1: Actuals.Q | H1: Horizon | I1: Error(bias) | J1: Absolute Error | K1: APE | L1: SignedPE | M1: ID.1.Name | N1: SeasonalBase | O1: Drift | P1: SND | Q1: APE- SND | R1: Window | S1: BiasFactor | T1: BiasAdjustForecast | U1: APE-bias adjusted
A2: 150 | B2: 45808 | C2: 5 | D2: 1 | E2: Forecast | F2: 244562.29 | G2: 245576.7 | H2: 0 | I2: -1014.4101 | J2: 1014.4101 | K2: 0.0041307262 | L2: -0.0041307262 | M2: Securities | N2: =SUMIFS(Actuals!$F:$F,Actuals!$A:$A,$A2,Actuals!$D:$D,$D2,Actuals!$B:$B,EDATE($B2,-12)) -> 245222.55 | O2: =AVERAGE(SUMIFS(Actuals!$F:$F,Actuals!$A:$A,$A2,Actuals!$D:$D,$D2,Actuals!$B:$B,EOMONTH(DATE(2025,$C2-1,1),0))/SUMIFS(Actuals!$F:$F,Actuals!$A:$A,$A2,Actuals!$D:$D,$D2,Actuals!$B:$B,EOMONTH(DATE(2024,$C2-1,1),0)), SUMIFS(Actuals!$F:$F,Actuals!$A:$A,$A2,Actuals!$D:$D,$D2,Actuals!$B:$B,EOMONTH(DATE(2025,$C2-2,1),0))/SUMIFS(Actuals!$F:$F,Actuals!$A:$A,$A2,Actuals!$D:$D,$D2,Actuals!$B:$B,EOMONTH(DATE(2024,$C2-2,1),0)), SUMIFS(Actuals!$F:$F,Actuals!$A:$A,$A2,Actuals!$D:$D,$D2,Actuals!$B:$B,EOMONTH(DATE(2025,$C2-3,1),0))/SUMIFS(Actuals!$F:$F,Actuals!$A:$A,$A2,Actuals!$D:$D,$D2,Actuals!$B:$B,EOMONTH(DATE(2024,$C2-3,1),0)) ) -> 1.0184515 | P2: =N2*O2 -> 249747.28 | Q2: =IFERROR(ABS(P2-G2)/ABS(G2),"") -> 0.016982817 | R2: =IF(C2<=8,"1 train date (May-Aug)","2 Test data (Sep-Nov)") -> 1 train date (May-Aug) | S2: =1/(1+AVERAGEIFS($L:$L,$A:$A,$A2,$R:$R,"1 train date (May-Aug)")) -> 1.0018126 | T2: =F2*S2 -> 245005.59 | U2: =IFERROR(ABS(T2-G2)/ABS(G2),"") -> 0.0023255829
A3: 150 | B3: 45838 | C3: 5 | D3: 1 | E3: Forecast | F3: 244445.22 | G3: 245087.1 | H3: 1 | I3: -641.8801 | J3: 641.8801 | K3: 0.0026189877 | L3: -0.0026189877 | M3: Securities | N3: =SUMIFS(Actuals!$F:$F,Actuals!$A:$A,$A3,Actuals!$D:$D,$D3,Actuals!$B:$B,EDATE($B3,-12)) -> 245874.6 | O3: =AVERAGE(SUMIFS(Actuals!$F:$F,Actuals!$A:$A,$A3,Actuals!$D:$D,$D3,Actuals!$B:$B,EOMONTH(DATE(2025,$C3-1,1),0))/SUMIFS(Actuals!$F:$F,Actuals!$A:$A,$A3,Actuals!$D:$D,$D3,Actuals!$B:$B,EOMONTH(DATE(2024,$C3-1,1),0)), SUMIFS(Actuals!$F:$F,Actuals!$A:$A,$A3,Actuals!$D:$D,$D3,Actuals!$B:$B,EOMONTH(DATE(2025,$C3-2,1),0))/SUMIFS(Actuals!$F:$F,Actuals!$A:$A,$A3,Actuals!$D:$D,$D3,Actuals!$B:$B,EOMONTH(DATE(2024,$C3-2,1),0)), SUMIFS(Actuals!$F:$F,Actuals!$A:$A,$A3,Actuals!$D:$D,$D3,Actuals!$B:$B,EOMONTH(DATE(2025,$C3-3,1),0))/SUMIFS(Actuals!$F:$F,Actuals!$A:$A,$A3,Actuals!$D:$D,$D3,Actuals!$B:$B,EOMONTH(DATE(2024,$C3-3,1),0)) ) -> 1.0184515 | P3: =N3*O3 -> 250411.37 | Q3: =IFERROR(ABS(P3-G3)/ABS(G3),"") -> 0.021723973 | R3: =IF(C3<=8,"1 train date (May-Aug)","2 Test data (Sep-Nov)") -> 1 train date (May-Aug) | S3: =1/(1+AVERAGEIFS($L:$L,$A:$A,$A3,$R:$R,"1 train date (May-Aug)")) -> 1.0018126 | T3: =F3*S3 -> 244888.31 | U3: =IFERROR(ABS(T3-G3)/ABS(G3),"") -> 0.00081110421
A4: 150 | B4: 45838 | C4: 6 | D4: 1 | E4: Forecast | F4: 245555.07 | G4: 245087.1 | H4: 0 | I4: 467.97393 | J4: 467.97393 | K4: 0.0019094189 | L4: 0.0019094189 | M4: Securities | N4: =SUMIFS(Actuals!$F:$F,Actuals!$A:$A,$A4,Actuals!$D:$D,$D4,Actuals!$B:$B,EDATE($B4,-12)) -> 245874.6 | O4: =AVERAGE(SUMIFS(Actuals!$F:$F,Actuals!$A:$A,$A4,Actuals!$D:$D,$D4,Actuals!$B:$B,EOMONTH(DATE(2025,$C4-1,1),0))/SUMIFS(Actuals!$F:$F,Actuals!$A:$A,$A4,Actuals!$D:$D,$D4,Actuals!$B:$B,EOMONTH(DATE(2024,$C4-1,1),0)), SUMIFS(Actuals!$F:$F,Actuals!$A:$A,$A4,Actuals!$D:$D,$D4,Actuals!$B:$B,EOMONTH(DATE(2025,$C4-2,1),0))/SUMIFS(Actuals!$F:$F,Actuals!$A:$A,$A4,Actuals!$D:$D,$D4,Actuals!$B:$B,EOMONTH(DATE(2024,$C4-2,1),0)), SUMIFS(Actuals!$F:$F,Actuals!$A:$A,$A4,Actuals!$D:$D,$D4,Actuals!$B:$B,EOMONTH(DATE(2025,$C4-3,1),0))/SUMIFS(Actuals!$F:$F,Actuals!$A:$A,$A4,Actuals!$D:$D,$D4,Actuals!$B:$B,EOMONTH(DATE(2024,$C4-3,1),0)) ) -> 1.0127007 | P4: =N4*O4 -> 248997.39 | Q4: =IFERROR(ABS(P4-G4)/ABS(G4),"") -> 0.015954688 | R4: =IF(C4<=8,"1 train date (May-Aug)","2 Test data (Sep-Nov)") -> 1 train date (May-Aug) | S4: =1/(1+AVERAGEIFS($L:$L,$A:$A,$A4,$R:$R,"1 train date (May-Aug)")) -> 1.0018126 | T4: =F4*S4 -> 246000.17 | U4: =IFERROR(ABS(T4-G4)/ABS(G4),"") -> 0.0037255107
A5: 150 | B5: 45869 | C5: 5 | D5: 1 | E5: Forecast | F5: 244320.35 | G5: 243836.1 | H5: 2 | I5: 484.24524 | J5: 484.24524 | K5: 0.0019859457 | L5: 0.0019859457 | M5: Securities | N5: =SUMIFS(Actuals!$F:$F,Actuals!$A:$A,$A5,Actuals!$D:$D,$D5,Actuals!$B:$B,EDATE($B5,-12)) -> 245402.1 | O5: =AVERAGE(SUMIFS(Actuals!$F:$F,Actuals!$A:$A,$A5,Actuals!$D:$D,$D5,Actuals!$B:$B,EOMONTH(DATE(2025,$C5-1,1),0))/SUMIFS(Actuals!$F:$F,Actuals!$A:$A,$A5,Actuals!$D:$D,$D5,Actuals!$B:$B,EOMONTH(DATE(2024,$C5-1,1),0)), SUMIFS(Actuals!$F:$F,Actuals!$A:$A,$A5,Actuals!$D:$D,$D5,Actuals!$B:$B,EOMONTH(DATE(2025,$C5-2,1),0))/SUMIFS(Actuals!$F:$F,Actuals!$A:$A,$A5,Actuals!$D:$D,$D5,Actuals!$B:$B,EOMONTH(DATE(2024,$C5-2,1),0)), SUMIFS(Actuals!$F:$F,Actuals!$A:$A,$A5,Actuals!$D:$D,$D5,Actuals!$B:$B,EOMONTH(DATE(2025,$C5-3,1),0))/SUMIFS(Actuals!$F:$F,Actuals!$A:$A,$A5,Actuals!$D:$D,$D5,Actuals!$B:$B,EOMONTH(DATE(2024,$C5-3,1),0)) ) -> 1.0184515 | P5: =N5*O5 -> 249930.15 | Q5: =IFERROR(ABS(P5-G5)/ABS(G5),"") -> 0.024992391 | R5: =IF(C5<=8,"1 train date (May-Aug)","2 Test data (Sep-Nov)") -> 1 train date (May-Aug) | S5: =1/(1+AVERAGEIFS($L:$L,$A:$A,$A5,$R:$R,"1 train date (May-Aug)")) -> 1.0018126 | T5: =F5*S5 -> 244763.21 | U5: =IFERROR(ABS(T5-G5)/ABS(G5),"") -> 0.0038021762
A6: 150 | B6: 45869 | C6: 6 | D6: 1 | E6: Forecast | F6: 245534.16 | G6: 243836.1 | H6: 1 | I6: 1698.0603 | J6: 1698.0603 | K6: 0.0069639413 | L6: 0.0069639413 | M6: Securities | N6: =SUMIFS(Actuals!$F:$F,Actuals!$A:$A,$A6,Actuals!$D:$D,$D6,Actuals!$B:$B,EDATE($B6,-12)) -> 245402.1 | O6: =AVERAGE(SUMIFS(Actuals!$F:$F,Actuals!$A:$A,$A6,Actuals!$D:$D,$D6,Actuals!$B:$B,EOMONTH(DATE(2025,$C6-1,1),0))/SUMIFS(Actuals!$F:$F,Actuals!$A:$A,$A6,Actuals!$D:$D,$D6,Actuals!$B:$B,EOMONTH(DATE(2024,$C6-1,1),0)), SUMIFS(Actuals!$F:$F,Actuals!$A:$A,$A6,Actuals!$D:$D,$D6,Actuals!$B:$B,EOMONTH(DATE(2025,$C6-2,1),0))/SUMIFS(Actuals!$F:$F,Actuals!$A:$A,$A6,Actuals!$D:$D,$D6,Actuals!$B:$B,EOMONTH(DATE(2024,$C6-2,1),0)), SUMIFS(Actuals!$F:$F,Actuals!$A:$A,$A6,Actuals!$D:$D,$D6,Actuals!$B:$B,EOMONTH(DATE(2025,$C6-3,1),0))/SUMIFS(Actuals!$F:$F,Actuals!$A:$A,$A6,Actuals!$D:$D,$D6,Actuals!$B:$B,EOMONTH(DATE(2024,$C6-3,1),0)) ) -> 1.0127007 | P6: =N6*O6 -> 248518.89 | Q6: =IFERROR(ABS(P6-G6)/ABS(G6),"") -> 0.01920465 | R6: =IF(C6<=8,"1 train date (May-Aug)","2 Test data (Sep-Nov)") -> 1 train date (May-Aug) | S6: =1/(1+AVERAGEIFS($L:$L,$A:$A,$A6,$R:$R,"1 train date (May-Aug)")) -> 1.0018126 | T6: =F6*S6 -> 245979.22 | U6: =IFERROR(ABS(T6-G6)/ABS(G6),"") -> 0.0087891951
A7: 150 | B7: 45869 | C7: 7 | D7: 1 | E7: Forecast | F7: 245019.92 | G7: 243836.1 | H7: 0 | I7: 1183.8233 | J7: 1183.8233 | K7: 0.004854996 | L7: 0.004854996 | M7: Securities | N7: =SUMIFS(Actuals!$F:$F,Actuals!$A:$A,$A7,Actuals!$D:$D,$D7,Actuals!$B:$B,EDATE($B7,-12)) -> 245402.1 | O7: =AVERAGE(SUMIFS(Actuals!$F:$F,Actuals!$A:$A,$A7,Actuals!$D:$D,$D7,Actuals!$B:$B,EOMONTH(DATE(2025,$C7-1,1),0))/SUMIFS(Actuals!$F:$F,Actuals!$A:$A,$A7,Actuals!$D:$D,$D7,Actuals!$B:$B,EOMONTH(DATE(2024,$C7-1,1),0)), SUMIFS(Actuals!$F:$F,Actuals!$A:$A,$A7,Actuals!$D:$D,$D7,Actuals!$B:$B,EOMONTH(DATE(2025,$C7-2,1),0))/SUMIFS(Actuals!$F:$F,Actuals!$A:$A,$A7,Actuals!$D:$D,$D7,Actuals!$B:$B,EOMONTH(DATE(2024,$C7-2,1),0)), SUMIFS(Actuals!$F:$F,Actuals!$A:$A,$A7,Actuals!$D:$D,$D7,Actuals!$B:$B,EOMONTH(DATE(2025,$C7-3,1),0))/SUMIFS(Actuals!$F:$F,Actuals!$A:$A,$A7,Actuals!$D:$D,$D7,Actuals!$B:$B,EOMONTH(DATE(2024,$C7-3,1),0)) ) -> 1.0048978 | P7: =N7*O7 -> 246604.03 | Q7: =IFERROR(ABS(P7-G7)/ABS(G7),"") -> 0.011351606 | R7: =IF(C7<=8,"1 train date (May-Aug)","2 Test data (Sep-Nov)") -> 1 train date (May-Aug) | S7: =1/(1+AVERAGEIFS($L:$L,$A:$A,$A7,$R:$R,"1 train date (May-Aug)")) -> 1.0018126 | T7: =F7*S7 -> 245464.05 | U7: =IFERROR(ABS(T7-G7)/ABS(G7),"") -> 0.006676427
A8: 150 | B8: 45900 | C8: 5 | D8: 1 | E8: Forecast | F8: 244199.37 | G8: 245375.1 | H8: 3 | I8: -1175.7271 | J8: 1175.7271 | K8: 0.0047915501 | L8: -0.0047915501 | M8: Securities | N8: =SUMIFS(Actuals!$F:$F,Actuals!$A:$A,$A8,Actuals!$D:$D,$D8,Actuals!$B:$B,EDATE($B8,-12)) -> 245954.25 | O8: =AVERAGE(SUMIFS(Actuals!$F:$F,Actuals!$A:$A,$A8,Actuals!$D:$D,$D8,Actuals!$B:$B,EOMONTH(DATE(2025,$C8-1,1),0))/SUMIFS(Actuals!$F:$F,Actuals!$A:$A,$A8,Actuals!$D:$D,$D8,Actuals!$B:$B,EOMONTH(DATE(2024,$C8-1,1),0)), SUMIFS(Actuals!$F:$F,Actuals!$A:$A,$A8,Actuals!$D:$D,$D8,Actuals!$B:$B,EOMONTH(DATE(2025,$C8-2,1),0))/SUMIFS(Actuals!$F:$F,Actuals!$A:$A,$A8,Actuals!$D:$D,$D8,Actuals!$B:$B,EOMONTH(DATE(2024,$C8-2,1),0)), SUMIFS(Actuals!$F:$F,Actuals!$A:$A,$A8,Actuals!$D:$D,$D8,Actuals!$B:$B,EOMONTH(DATE(2025,$C8-3,1),0))/SUMIFS(Actuals!$F:$F,Actuals!$A:$A,$A8,Actuals!$D:$D,$D8,Actuals!$B:$B,EOMONTH(DATE(2024,$C8-3,1),0)) ) -> 1.0184515 | P8: =N8*O8 -> 250492.49 | Q8: =IFERROR(ABS(P8-G8)/ABS(G8),"") -> 0.020855356 | R8: =IF(C8<=8,"1 train date (May-Aug)","2 Test data (Sep-Nov)") -> 1 train date (May-Aug) | S8: =1/(1+AVERAGEIFS($L:$L,$A:$A,$A8,$R:$R,"1 train date (May-Aug)")) -> 1.0018126 | T8: =F8*S8 -> 244642.02 | U8: =IFERROR(ABS(T8-G8)/ABS(G8),"") -> 0.0029876046
A9: 150 | B9: 45900 | C9: 6 | D9: 1 | E9: Forecast | F9: 245513.9 | G9: 245375.1 | H9: 2 | I9: 138.80019 | J9: 138.80019 | K9: 0.00056566533 | L9: 0.00056566533 | M9: Securities | N9: =SUMIFS(Actuals!$F:$F,Actuals!$A:$A,$A9,Actuals!$D:$D,$D9,Actuals!$B:$B,EDATE($B9,-12)) -> 245954.25 | O9: =AVERAGE(SUMIFS(Actuals!$F:$F,Actuals!$A:$A,$A9,Actuals!$D:$D,$D9,Actuals!$B:$B,EOMONTH(DATE(2025,$C9-1,1),0))/SUMIFS(Actuals!$F:$F,Actuals!$A:$A,$A9,Actuals!$D:$D,$D9,Actuals!$B:$B,EOMONTH(DATE(2024,$C9-1,1),0)), SUMIFS(Actuals!$F:$F,Actuals!$A:$A,$A9,Actuals!$D:$D,$D9,Actuals!$B:$B,EOMONTH(DATE(2025,$C9-2,1),0))/SUMIFS(Actuals!$F:$F,Actuals!$A:$A,$A9,Actuals!$D:$D,$D9,Actuals!$B:$B,EOMONTH(DATE(2024,$C9-2,1),0)), SUMIFS(Actuals!$F:$F,Actuals!$A:$A,$A9,Actuals!$D:$D,$D9,Actuals!$B:$B,EOMONTH(DATE(2025,$C9-3,1),0))/SUMIFS(Actuals!$F:$F,Actuals!$A:$A,$A9,Actuals!$D:$D,$D9,Actuals!$B:$B,EOMONTH(DATE(2024,$C9-3,1),0)) ) -> 1.0127007 | P9: =N9*O9 -> 249078.05 | Q9: =IFERROR(ABS(P9-G9)/ABS(G9),"") -> 0.015090976 | R9: =IF(C9<=8,"1 train date (May-Aug)","2 Test data (Sep-Nov)") -> 1 train date (May-Aug) | S9: =1/(1+AVERAGEIFS($L:$L,$A:$A,$A9,$R:$R,"1 train date (May-Aug)")) -> 1.0018126 | T9: =F9*S9 -> 245958.93 | U9: =IFERROR(ABS(T9-G9)/ABS(G9),"") -> 0.0023793214
A10: 150 | B10: 45900 | C10: 7 | D10: 1 | E10: Forecast | F10: 244953.94 | G10: 245375.1 | H10: 1 | I10: -421.16077 | J10: 421.16077 | K10: 0.0017163957 | L10: -0.0017163957 | M10: Securities | N10: =SUMIFS(Actuals!$F:$F,Actuals!$A:$A,$A10,Actuals!$D:$D,$D10,Actuals!$B:$B,EDATE($B10,-12)) -> 245954.25 | O10: =AVERAGE(SUMIFS(Actuals!$F:$F,Actuals!$A:$A,$A10,Actuals!$D:$D,$D10,Actuals!$B:$B,EOMONTH(DATE(2025,$C10-1,1),0))/SUMIFS(Actuals!$F:$F,Actuals!$A:$A,$A10,Actuals!$D:$D,$D10,Actuals!$B:$B,EOMONTH(DATE(2024,$C10-1,1),0)), SUMIFS(Actuals!$F:$F,Actuals!$A:$A,$A10,Actuals!$D:$D,$D10,Actuals!$B:$B,EOMONTH(DATE(2025,$C10-2,1),0))/SUMIFS(Actuals!$F:$F,Actuals!$A:$A,$A10,Actuals!$D:$D,$D10,Actuals!$B:$B,EOMONTH(DATE(2024,$C10-2,1),0)), SUMIFS(Actuals!$F:$F,Actuals!$A:$A,$A10,Actuals!$D:$D,$D10,Actuals!$B:$B,EOMONTH(DATE(2025,$C10-3,1),0))/SUMIFS(Actuals!$F:$F,Actuals!$A:$A,$A10,Actuals!$D:$D,$D10,Actuals!$B:$B,EOMONTH(DATE(2024,$C10-3,1),0)) ) -> 1.0048978 | P10: =N10*O10 -> 247158.89 | Q10: =IFERROR(ABS(P10-G10)/ABS(G10),"") -> 0.0072696282 | R10: =IF(C10<=8,"1 train date (May-Aug)","2 Test data (Sep-Nov)") -> 1 train date (May-Aug) | S10: =1/(1+AVERAGEIFS($L:$L,$A:$A,$A10,$R:$R,"1 train date (May-Aug)")) -> 1.0018126 | T10: =F10*S10 -> 245397.95 | U10: =IFERROR(ABS(T10-G10)/ABS(G10),"") -> 9.3123852e-05
A11: 150 | B11: 45900 | C11: 8 | D11: 1 | E11: Forecast | F11: 243026.95 | G11: 245375.1 | H11: 0 | I11: -2348.1523 | J11: 2348.1523 | K11: 0.0095696439 | L11: -0.0095696439 | M11: Securities | N11: =SUMIFS(Actuals!$F:$F,Actuals!$A:$A,$A11,Actuals!$D:$D,$D11,Actuals!$B:$B,EDATE($B11,-12)) -> 245954.25 | O11: =AVERAGE(SUMIFS(Actuals!$F:$F,Actuals!$A:$A,$A11,Actuals!$D:$D,$D11,Actuals!$B:$B,EOMONTH(DATE(2025,$C11-1,1),0))/SUMIFS(Actuals!$F:$F,Actuals!$A:$A,$A11,Actuals!$D:$D,$D11,Actuals!$B:$B,EOMONTH(DATE(2024,$C11-1,1),0)), SUMIFS(Actuals!$F:$F,Actuals!$A:$A,$A11,Actuals!$D:$D,$D11,Actuals!$B:$B,EOMONTH(DATE(2025,$C11-2,1),0))/SUMIFS(Actuals!$F:$F,Actuals!$A:$A,$A11,Actuals!$D:$D,$D11,Actuals!$B:$B,EOMONTH(DATE(2024,$C11-2,1),0)), SUMIFS(Actuals!$F:$F,Actuals!$A:$A,$A11,Actuals!$D:$D,$D11,Actuals!$B:$B,EOMONTH(DATE(2025,$C11-3,1),0))/SUMIFS(Actuals!$F:$F,Actuals!$A:$A,$A11,Actuals!$D:$D,$D11,Actuals!$B:$B,EOMONTH(DATE(2024,$C11-3,1),0)) ) -> 0.99728666 | P11: =N11*O11 -> 245286.89 | Q11: =IFERROR(ABS(P11-G11)/ABS(G11),"") -> 0.00035947937 | R11: =IF(C11<=8,"1 train date (May-Aug)","2 Test data (Sep-Nov)") -> 1 train date (May-Aug) | S11: =1/(1+AVERAGEIFS($L:$L,$A:$A,$A11,$R:$R,"1 train date (May-Aug)")) -> 1.0018126 | T11: =F11*S11 -> 243467.47 | U11: =IFERROR(ABS(T11-G11)/ABS(G11),"") -> 0.0077743594
A12: 150 | B12: 45930 | C12: 5 | D12: 1 | E12: Forecast | F12: 244082.3 | G12: 245898.9 | H12: 4 | I12: -1816.5971 | J12: 1816.5971 | K12: 0.0073875771 | L12: -0.0073875771 | M12: Securities | N12: =SUMIFS(Actuals!$F:$F,Actuals!$A:$A,$A12,Actuals!$D:$D,$D12,Actuals!$B:$B,EDATE($B12,-12)) -> 244552.95 | O12: =AVERAGE(SUMIFS(Actuals!$F:$F,Actuals!$A:$A,$A12,Actuals!$D:$D,$D12,Actuals!$B:$B,EOMONTH(DATE(2025,$C12-1,1),0))/SUMIFS(Actuals!$F:$F,Actuals!$A:$A,$A12,Actuals!$D:$D,$D12,Actuals!$B:$B,EOMONTH(DATE(2024,$C12-1,1),0)), SUMIFS(Actuals!$F:$F,Actuals!$A:$A,$A12,Actuals!$D:$D,$D12,Actuals!$B:$B,EOMONTH(DATE(2025,$C12-2,1),0))/SUMIFS(Actuals!$F:$F,Actuals!$A:$A,$A12,Actuals!$D:$D,$D12,Actuals!$B:$B,EOMONTH(DATE(2024,$C12-2,1),0)), SUMIFS(Actuals!$F:$F,Actuals!$A:$A,$A12,Actuals!$D:$D,$D12,Actuals!$B:$B,EOMONTH(DATE(2025,$C12-3,1),0))/SUMIFS(Actuals!$F:$F,Actuals!$A:$A,$A12,Actuals!$D:$D,$D12,Actuals!$B:$B,EOMONTH(DATE(2024,$C12-3,1),0)) ) -> 1.0184515 | P12: =N12*O12 -> 249065.33 | Q12: =IFERROR(ABS(P12-G12)/ABS(G12),"") -> 0.012876955 | R12: =IF(C12<=8,"1 train date (May-Aug)","2 Test data (Sep-Nov)") -> 1 train date (May-Aug) | S12: =1/(1+AVERAGEIFS($L:$L,$A:$A,$A12,$R:$R,"1 train date (May-Aug)")) -> 1.0018126 | T12: =F12*S12 -> 244524.73 | U12: =IFERROR(ABS(T12-G12)/ABS(G12),"") -> 0.0055883373
A13: 150 | B13: 45930 | C13: 6 | D13: 1 | E13: Forecast | F13: 245494.29 | G13: 245898.9 | H13: 3 | I13: -404.60636 | J13: 404.60636 | K13: 0.0016454175 | L13: -0.0016454175 | M13: Securities | N13: =SUMIFS(Actuals!$F:$F,Actuals!$A:$A,$A13,Actuals!$D:$D,$D13,Actuals!$B:$B,EDATE($B13,-12)) -> 244552.95 | O13: =AVERAGE(SUMIFS(Actuals!$F:$F,Actuals!$A:$A,$A13,Actuals!$D:$D,$D13,Actuals!$B:$B,EOMONTH(DATE(2025,$C13-1,1),0))/SUMIFS(Actuals!$F:$F,Actuals!$A:$A,$A13,Actuals!$D:$D,$D13,Actuals!$B:$B,EOMONTH(DATE(2024,$C13-1,1),0)), SUMIFS(Actuals!$F:$F,Actuals!$A:$A,$A13,Actuals!$D:$D,$D13,Actuals!$B:$B,EOMONTH(DATE(2025,$C13-2,1),0))/SUMIFS(Actuals!$F:$F,Actuals!$A:$A,$A13,Actuals!$D:$D,$D13,Actuals!$B:$B,EOMONTH(DATE(2024,$C13-2,1),0)), SUMIFS(Actuals!$F:$F,Actuals!$A:$A,$A13,Actuals!$D:$D,$D13,Actuals!$B:$B,EOMONTH(DATE(2025,$C13-3,1),0))/SUMIFS(Actuals!$F:$F,Actuals!$A:$A,$A13,Actuals!$D:$D,$D13,Actuals!$B:$B,EOMONTH(DATE(2024,$C13-3,1),0)) ) -> 1.0127007 | P13: =N13*O13 -> 247658.95 | Q13: =IFERROR(ABS(P13-G13)/ABS(G13),"") -> 0.0071576255 | R13: =IF(C13<=8,"1 train date (May-Aug)","2 Test data (Sep-Nov)") -> 1 train date (May-Aug) | S13: =1/(1+AVERAGEIFS($L:$L,$A:$A,$A13,$R:$R,"1 train date (May-Aug)")) -> 1.0018126 | T13: =F13*S13 -> 245939.28 | U13: =IFERROR(ABS(T13-G13)/ABS(G13),"") -> 0.00016423069
... A2913: 9768 | B2913: 45991 | C2913: 11 | D2913: 42 | E2913: Forecast | F2913: 531908.44 | G2913: 435330 | H2913: 0 | I2913: 96578.435 | J2913: 96578.435 | K2913: 0.22185109 | L2913: 0.22185109 | M2913: Dopix documents | N2913: =SUMIFS(Actuals!$F:$F,Actuals!$A:$A,$A2913,Actuals!$D:$D,$D2913,Actuals!$B:$B,EDATE($B2913,-12)) -> 389248.75 | O2913: =AVERAGE(SUMIFS(Actuals!$F:$F,Actuals!$A:$A,$A2913,Actuals!$D:$D,$D2913,Actuals!$B:$B,EOMONTH(DATE(2025,$C2913-1,1),0))/SUMIFS(Actuals!$F:$F,Actuals!$A:$A,$A2913,Actuals!$D:$D,$D2913,Actuals!$B:$B,EOMONTH(DATE(2024,$C2913-1,1),0)), SUMIFS(Actuals!$F:$F,Actuals!$A:$A,$A2913,Actuals!$D:$D,$D2913,Actuals!$B:$B,EOMONTH(DATE(2025,$C2913-2,1),0))/SUMIFS(Actuals!$F:$F,Actuals!$A:$A,$A2913,Actuals!$D:$D,$D2913,Actuals!$B:$B,EOMONTH(DATE(2024,$C2913-2,1),0)), SUMIFS(Actuals!$F:$F,Actuals!$A:$A,$A2913,Actuals!$D:$D,$D2913,Actuals!$B:$B,EOMONTH(DATE(2025,$C2913-3,1),0))/SUMIFS(Actuals!$F:$F,Actuals!$A:$A,$A2913,Actuals!$D:$D,$D2913,Actuals!$B:$B,EOMONTH(DATE(2024,$C2913-3,1),0)) ) -> 1.0011376 | P2913: =N2913*O2913 -> 389691.56 | Q2913: =IFERROR(ABS(P2913-G2913)/ABS(G2913),"") -> 0.10483641 | R2913: =IF(C2913<=8,"1 train date (May-Aug)","2 Test data (Sep-Nov)") -> 2 Test data (Sep-Nov) | S2913: =1/(1+AVERAGEIFS($L:$L,$A:$A,$A2913,$R:$R,"1 train date (May-Aug)")) -> 0.98764874 | T2913: =F2913*S2913 -> 525338.7 | U2913: =IFERROR(ABS(T2913-G2913)/ABS(G2913),"") -> 0.20675969
A2914: 150 | B2914: 46022 | C2914: 5 | D2914: 1 | E2914: Forecast | F2914: 243715.48 | H2914: 7 | M2914: Securities | N2914: =SUMIFS(Actuals!$F:$F,Actuals!$A:$A,$A2914,Actuals!$D:$D,$D2914,Actuals!$B:$B,EDATE($B2914,-12)) -> 242329.95 | O2914: =AVERAGE(SUMIFS(Actuals!$F:$F,Actuals!$A:$A,$A2914,Actuals!$D:$D,$D2914,Actuals!$B:$B,EOMONTH(DATE(2025,$C2914-1,1),0))/SUMIFS(Actuals!$F:$F,Actuals!$A:$A,$A2914,Actuals!$D:$D,$D2914,Actuals!$B:$B,EOMONTH(DATE(2024,$C2914-1,1),0)), SUMIFS(Actuals!$F:$F,Actuals!$A:$A,$A2914,Actuals!$D:$D,$D2914,Actuals!$B:$B,EOMONTH(DATE(2025,$C2914-2,1),0))/SUMIFS(Actuals!$F:$F,Actuals!$A:$A,$A2914,Actuals!$D:$D,$D2914,Actuals!$B:$B,EOMONTH(DATE(2024,$C2914-2,1),0)), SUMIFS(Actuals!$F:$F,Actuals!$A:$A,$A2914,Actuals!$D:$D,$D2914,Actuals!$B:$B,EOMONTH(DATE(2025,$C2914-3,1),0))/SUMIFS(Actuals!$F:$F,Actuals!$A:$A,$A2914,Actuals!$D:$D,$D2914,Actuals!$B:$B,EOMONTH(DATE(2024,$C2914-3,1),0)) ) -> 1.0184515 | P2914: =N2914*O2914 -> 246801.31 | Q2914: =IFERROR(ABS(P2914-G2914)/ABS(G2914),"") | R2914: =IF(C2914<=8,"1 train date (May-Aug)","2 Test data (Sep-Nov)") -> 1 train date (May-Aug) | S2914: =1/(1+AVERAGEIFS($L:$L,$A:$A,$A2914,$R:$R,"1 train date (May-Aug)")) -> 1.0018126 | T2914: =F2914*S2914 -> 244157.25 | U2914: =IFERROR(ABS(T2914-G2914)/ABS(G2914),"")
A2915: 150 | B2915: 46022 | C2915: 6 | D2915: 1 | E2915: Forecast | F2915: 245432.86 | H2915: 6 | M2915: Securities | N2915: =SUMIFS(Actuals!$F:$F,Actuals!$A:$A,$A2915,Actuals!$D:$D,$D2915,Actuals!$B:$B,EDATE($B2915,-12)) -> 242329.95 | O2915: =AVERAGE(SUMIFS(Actuals!$F:$F,Actuals!$A:$A,$A2915,Actuals!$D:$D,$D2915,Actuals!$B:$B,EOMONTH(DATE(2025,$C2915-1,1),0))/SUMIFS(Actuals!$F:$F,Actuals!$A:$A,$A2915,Actuals!$D:$D,$D2915,Actuals!$B:$B,EOMONTH(DATE(2024,$C2915-1,1),0)), SUMIFS(Actuals!$F:$F,Actuals!$A:$A,$A2915,Actuals!$D:$D,$D2915,Actuals!$B:$B,EOMONTH(DATE(2025,$C2915-2,1),0))/SUMIFS(Actuals!$F:$F,Actuals!$A:$A,$A2915,Actuals!$D:$D,$D2915,Actuals!$B:$B,EOMONTH(DATE(2024,$C2915-2,1),0)), SUMIFS(Actuals!$F:$F,Actuals!$A:$A,$A2915,Actuals!$D:$D,$D2915,Actuals!$B:$B,EOMONTH(DATE(2025,$C2915-3,1),0))/SUMIFS(Actuals!$F:$F,Actuals!$A:$A,$A2915,Actuals!$D:$D,$D2915,Actuals!$B:$B,EOMONTH(DATE(2024,$C2915-3,1),0)) ) -> 1.0127007 | P2915: =N2915*O2915 -> 245407.72 | Q2915: =IFERROR(ABS(P2915-G2915)/ABS(G2915),"") | R2915: =IF(C2915<=8,"1 train date (May-Aug)","2 Test data (Sep-Nov)") -> 1 train date (May-Aug) | S2915: =1/(1+AVERAGEIFS($L:$L,$A:$A,$A2915,$R:$R,"1 train date (May-Aug)")) -> 1.0018126 | T2915: =F2915*S2915 -> 245877.74 | U2915: =IFERROR(ABS(T2915-G2915)/ABS(G2915),"")
A2916: 150 | B2916: 46022 | C2916: 7 | D2916: 1 | E2916: Forecast | F2916: 244690 | H2916: 5 | M2916: Securities | N2916: =SUMIFS(Actuals!$F:$F,Actuals!$A:$A,$A2916,Actuals!$D:$D,$D2916,Actuals!$B:$B,EDATE($B2916,-12)) -> 242329.95 | O2916: =AVERAGE(SUMIFS(Actuals!$F:$F,Actuals!$A:$A,$A2916,Actuals!$D:$D,$D2916,Actuals!$B:$B,EOMONTH(DATE(2025,$C2916-1,1),0))/SUMIFS(Actuals!$F:$F,Actuals!$A:$A,$A2916,Actuals!$D:$D,$D2916,Actuals!$B:$B,EOMONTH(DATE(2024,$C2916-1,1),0)), SUMIFS(Actuals!$F:$F,Actuals!$A:$A,$A2916,Actuals!$D:$D,$D2916,Actuals!$B:$B,EOMONTH(DATE(2025,$C2916-2,1),0))/SUMIFS(Actuals!$F:$F,Actuals!$A:$A,$A2916,Actuals!$D:$D,$D2916,Actuals!$B:$B,EOMONTH(DATE(2024,$C2916-2,1),0)), SUMIFS(Actuals!$F:$F,Actuals!$A:$A,$A2916,Actuals!$D:$D,$D2916,Actuals!$B:$B,EOMONTH(DATE(2025,$C2916-3,1),0))/SUMIFS(Actuals!$F:$F,Actuals!$A:$A,$A2916,Actuals!$D:$D,$D2916,Actuals!$B:$B,EOMONTH(DATE(2024,$C2916-3,1),0)) ) -> 1.0048978 | P2916: =N2916*O2916 -> 243516.83 | Q2916: =IFERROR(ABS(P2916-G2916)/ABS(G2916),"") | R2916: =IF(C2916<=8,"1 train date (May-Aug)","2 Test data (Sep-Nov)") -> 1 train date (May-Aug) | S2916: =1/(1+AVERAGEIFS($L:$L,$A:$A,$A2916,$R:$R,"1 train date (May-Aug)")) -> 1.0018126 | T2916: =F2916*S2916 -> 245133.54 | U2916: =IFERROR(ABS(T2916-G2916)/ABS(G2916),"")
A2917: 150 | B2917: 46022 | C2917: 8 | D2917: 1 | E2917: Forecast | F2917: 241650 | H2917: 4 | M2917: Securities | N2917: =SUMIFS(Actuals!$F:$F,Actuals!$A:$A,$A2917,Actuals!$D:$D,$D2917,Actuals!$B:$B,EDATE($B2917,-12)) -> 242329.95 | O2917: =AVERAGE(SUMIFS(Actuals!$F:$F,Actuals!$A:$A,$A2917,Actuals!$D:$D,$D2917,Actuals!$B:$B,EOMONTH(DATE(2025,$C2917-1,1),0))/SUMIFS(Actuals!$F:$F,Actuals!$A:$A,$A2917,Actuals!$D:$D,$D2917,Actuals!$B:$B,EOMONTH(DATE(2024,$C2917-1,1),0)), SUMIFS(Actuals!$F:$F,Actuals!$A:$A,$A2917,Actuals!$D:$D,$D2917,Actuals!$B:$B,EOMONTH(DATE(2025,$C2917-2,1),0))/SUMIFS(Actuals!$F:$F,Actuals!$A:$A,$A2917,Actuals!$D:$D,$D2917,Actuals!$B:$B,EOMONTH(DATE(2024,$C2917-2,1),0)), SUMIFS(Actuals!$F:$F,Actuals!$A:$A,$A2917,Actuals!$D:$D,$D2917,Actuals!$B:$B,EOMONTH(DATE(2025,$C2917-3,1),0))/SUMIFS(Actuals!$F:$F,Actuals!$A:$A,$A2917,Actuals!$D:$D,$D2917,Actuals!$B:$B,EOMONTH(DATE(2024,$C2917-3,1),0)) ) -> 0.99728666 | P2917: =N2917*O2917 -> 241672.43 | Q2917: =IFERROR(ABS(P2917-G2917)/ABS(G2917),"") | R2917: =IF(C2917<=8,"1 train date (May-Aug)","2 Test data (Sep-Nov)") -> 1 train date (May-Aug) | S2917: =1/(1+AVERAGEIFS($L:$L,$A:$A,$A2917,$R:$R,"1 train date (May-Aug)")) -> 1.0018126 | T2917: =F2917*S2917 -> 242088.02 | U2917: =IFERROR(ABS(T2917-G2917)/ABS(G2917),"")
A2918: 150 | B2918: 46022 | C2918: 9 | D2918: 1 | E2918: Forecast | F2918: 244752.75 | H2918: 3 | M2918: Securities | N2918: =SUMIFS(Actuals!$F:$F,Actuals!$A:$A,$A2918,Actuals!$D:$D,$D2918,Actuals!$B:$B,EDATE($B2918,-12)) -> 242329.95 | O2918: =AVERAGE(SUMIFS(Actuals!$F:$F,Actuals!$A:$A,$A2918,Actuals!$D:$D,$D2918,Actuals!$B:$B,EOMONTH(DATE(2025,$C2918-1,1),0))/SUMIFS(Actuals!$F:$F,Actuals!$A:$A,$A2918,Actuals!$D:$D,$D2918,Actuals!$B:$B,EOMONTH(DATE(2024,$C2918-1,1),0)), SUMIFS(Actuals!$F:$F,Actuals!$A:$A,$A2918,Actuals!$D:$D,$D2918,Actuals!$B:$B,EOMONTH(DATE(2025,$C2918-2,1),0))/SUMIFS(Actuals!$F:$F,Actuals!$A:$A,$A2918,Actuals!$D:$D,$D2918,Actuals!$B:$B,EOMONTH(DATE(2024,$C2918-2,1),0)), SUMIFS(Actuals!$F:$F,Actuals!$A:$A,$A2918,Actuals!$D:$D,$D2918,Actuals!$B:$B,EOMONTH(DATE(2025,$C2918-3,1),0))/SUMIFS(Actuals!$F:$F,Actuals!$A:$A,$A2918,Actuals!$D:$D,$D2918,Actuals!$B:$B,EOMONTH(DATE(2024,$C2918-3,1),0)) ) -> 0.99602036 | P2918: =N2918*O2918 -> 241365.56 | Q2918: =IFERROR(ABS(P2918-G2918)/ABS(G2918),"") | R2918: =IF(C2918<=8,"1 train date (May-Aug)","2 Test data (Sep-Nov)") -> 2 Test data (Sep-Nov) | S2918: =1/(1+AVERAGEIFS($L:$L,$A:$A,$A2918,$R:$R,"1 train date (May-Aug)")) -> 1.0018126 | T2918: =F2918*S2918 -> 245196.4 | U2918: =IFERROR(ABS(T2918-G2918)/ABS(G2918),"")
A2919: 150 | B2919: 46022 | C2919: 10 | D2919: 1 | E2919: Forecast | F2919: 245898.9 | H2919: 2 | M2919: Securities | N2919: =SUMIFS(Actuals!$F:$F,Actuals!$A:$A,$A2919,Actuals!$D:$D,$D2919,Actuals!$B:$B,EDATE($B2919,-12)) -> 242329.95 | O2919: =AVERAGE(SUMIFS(Actuals!$F:$F,Actuals!$A:$A,$A2919,Actuals!$D:$D,$D2919,Actuals!$B:$B,EOMONTH(DATE(2025,$C2919-1,1),0))/SUMIFS(Actuals!$F:$F,Actuals!$A:$A,$A2919,Actuals!$D:$D,$D2919,Actuals!$B:$B,EOMONTH(DATE(2024,$C2919-1,1),0)), SUMIFS(Actuals!$F:$F,Actuals!$A:$A,$A2919,Actuals!$D:$D,$D2919,Actuals!$B:$B,EOMONTH(DATE(2025,$C2919-2,1),0))/SUMIFS(Actuals!$F:$F,Actuals!$A:$A,$A2919,Actuals!$D:$D,$D2919,Actuals!$B:$B,EOMONTH(DATE(2024,$C2919-2,1),0)), SUMIFS(Actuals!$F:$F,Actuals!$A:$A,$A2919,Actuals!$D:$D,$D2919,Actuals!$B:$B,EOMONTH(DATE(2025,$C2919-3,1),0))/SUMIFS(Actuals!$F:$F,Actuals!$A:$A,$A2919,Actuals!$D:$D,$D2919,Actuals!$B:$B,EOMONTH(DATE(2024,$C2919-3,1),0)) ) -> 0.99892255 | P2919: =N2919*O2919 -> 242068.85 | Q2919: =IFERROR(ABS(P2919-G2919)/ABS(G2919),"") | R2919: =IF(C2919<=8,"1 train date (May-Aug)","2 Test data (Sep-Nov)") -> 2 Test data (Sep-Nov) | S2919: =1/(1+AVERAGEIFS($L:$L,$A:$A,$A2919,$R:$R,"1 train date (May-Aug)")) -> 1.0018126 | T2919: =F2919*S2919 -> 246344.62 | U2919: =IFERROR(ABS(T2919-G2919)/ABS(G2919),"")
A2920: 150 | B2920: 46022 | C2920: 11 | D2920: 1 | E2920: Forecast | F2920: 246397.6 | H2920: 1 | M2920: Securities | N2920: =SUMIFS(Actuals!$F:$F,Actuals!$A:$A,$A2920,Actuals!$D:$D,$D2920,Actuals!$B:$B,EDATE($B2920,-12)) -> 242329.95 | O2920: =AVERAGE(SUMIFS(Actuals!$F:$F,Actuals!$A:$A,$A2920,Actuals!$D:$D,$D2920,Actuals!$B:$B,EOMONTH(DATE(2025,$C2920-1,1),0))/SUMIFS(Actuals!$F:$F,Actuals!$A:$A,$A2920,Actuals!$D:$D,$D2920,Actuals!$B:$B,EOMONTH(DATE(2024,$C2920-1,1),0)), SUMIFS(Actuals!$F:$F,Actuals!$A:$A,$A2920,Actuals!$D:$D,$D2920,Actuals!$B:$B,EOMONTH(DATE(2025,$C2920-2,1),0))/SUMIFS(Actuals!$F:$F,Actuals!$A:$A,$A2920,Actuals!$D:$D,$D2920,Actuals!$B:$B,EOMONTH(DATE(2024,$C2920-2,1),0)), SUMIFS(Actuals!$F:$F,Actuals!$A:$A,$A2920,Actuals!$D:$D,$D2920,Actuals!$B:$B,EOMONTH(DATE(2025,$C2920-3,1),0))/SUMIFS(Actuals!$F:$F,Actuals!$A:$A,$A2920,Actuals!$D:$D,$D2920,Actuals!$B:$B,EOMONTH(DATE(2024,$C2920-3,1),0)) ) -> 1.006801 | P2920: =N2920*O2920 -> 243978.03 | Q2920: =IFERROR(ABS(P2920-G2920)/ABS(G2920),"") | R2920: =IF(C2920<=8,"1 train date (May-Aug)","2 Test data (Sep-Nov)") -> 2 Test data (Sep-Nov) | S2920: =1/(1+AVERAGEIFS($L:$L,$A:$A,$A2920,$R:$R,"1 train date (May-Aug)")) -> 1.0018126 | T2920: =F2920*S2920 -> 246844.23 | U2920: =IFERROR(ABS(T2920-G2920)/ABS(G2920),"")
A2921: 2370 | B2921: 46022 | C2921: 5 | D2921: 1 | E2921: Forecast | F2921: 15698.794 | H2921: 7 | M2921: Foreign Securities | N2921: =SUMIFS(Actuals!$F:$F,Actuals!$A:$A,$A2921,Actuals!$D:$D,$D2921,Actuals!$B:$B,EDATE($B2921,-12)) -> 16240.95 | O2921: =AVERAGE(SUMIFS(Actuals!$F:$F,Actuals!$A:$A,$A2921,Actuals!$D:$D,$D2921,Actuals!$B:$B,EOMONTH(DATE(2025,$C2921-1,1),0))/SUMIFS(Actuals!$F:$F,Actuals!$A:$A,$A2921,Actuals!$D:$D,$D2921,Actuals!$B:$B,EOMONTH(DATE(2024,$C2921-1,1),0)), SUMIFS(Actuals!$F:$F,Actuals!$A:$A,$A2921,Actuals!$D:$D,$D2921,Actuals!$B:$B,EOMONTH(DATE(2025,$C2921-2,1),0))/SUMIFS(Actuals!$F:$F,Actuals!$A:$A,$A2921,Actuals!$D:$D,$D2921,Actuals!$B:$B,EOMONTH(DATE(2024,$C2921-2,1),0)), SUMIFS(Actuals!$F:$F,Actuals!$A:$A,$A2921,Actuals!$D:$D,$D2921,Actuals!$B:$B,EOMONTH(DATE(2025,$C2921-3,1),0))/SUMIFS(Actuals!$F:$F,Actuals!$A:$A,$A2921,Actuals!$D:$D,$D2921,Actuals!$B:$B,EOMONTH(DATE(2024,$C2921-3,1),0)) ) -> 1.1725813 | P2921: =N2921*O2921 -> 19043.835 | Q2921: =IFERROR(ABS(P2921-G2921)/ABS(G2921),"") | R2921: =IF(C2921<=8,"1 train date (May-Aug)","2 Test data (Sep-Nov)") -> 1 train date (May-Aug) | S2921: =1/(1+AVERAGEIFS($L:$L,$A:$A,$A2921,$R:$R,"1 train date (May-Aug)")) -> 1.1836764 | T2921: =F2921*S2921 -> 18582.292 | U2921: =IFERROR(ABS(T2921-G2921)/ABS(G2921),"")
A2922: 2370 | B2922: 46022 | C2922: 6 | D2922: 1 | E2922: Forecast | F2922: 15698.794 | H2922: 6 | M2922: Foreign Securities | N2922: =SUMIFS(Actuals!$F:$F,Actuals!$A:$A,$A2922,Actuals!$D:$D,$D2922,Actuals!$B:$B,EDATE($B2922,-12)) -> 16240.95 | O2922: =AVERAGE(SUMIFS(Actuals!$F:$F,Actuals!$A:$A,$A2922,Actuals!$D:$D,$D2922,Actuals!$B:$B,EOMONTH(DATE(2025,$C2922-1,1),0))/SUMIFS(Actuals!$F:$F,Actuals!$A:$A,$A2922,Actuals!$D:$D,$D2922,Actuals!$B:$B,EOMONTH(DATE(2024,$C2922-1,1),0)), SUMIFS(Actuals!$F:$F,Actuals!$A:$A,$A2922,Actuals!$D:$D,$D2922,Actuals!$B:$B,EOMONTH(DATE(2025,$C2922-2,1),0))/SUMIFS(Actuals!$F:$F,Actuals!$A:$A,$A2922,Actuals!$D:$D,$D2922,Actuals!$B:$B,EOMONTH(DATE(2024,$C2922-2,1),0)), SUMIFS(Actuals!$F:$F,Actuals!$A:$A,$A2922,Actuals!$D:$D,$D2922,Actuals!$B:$B,EOMONTH(DATE(2025,$C2922-3,1),0))/SUMIFS(Actuals!$F:$F,Actuals!$A:$A,$A2922,Actuals!$D:$D,$D2922,Actuals!$B:$B,EOMONTH(DATE(2024,$C2922-3,1),0)) ) -> 1.1325937 | P2922: =N2922*O2922 -> 18394.397 | Q2922: =IFERROR(ABS(P2922-G2922)/ABS(G2922),"") | R2922: =IF(C2922<=8,"1 train date (May-Aug)","2 Test data (Sep-Nov)") -> 1 train date (May-Aug) | S2922: =1/(1+AVERAGEIFS($L:$L,$A:$A,$A2922,$R:$R,"1 train date (May-Aug)")) -> 1.1836764 | T2922: =F2922*S2922 -> 18582.292 | U2922: =IFERROR(ABS(T2922-G2922)/ABS(G2922),"")
A2923: 2370 | B2923: 46022 | C2923: 7 | D2923: 1 | E2923: Forecast | F2923: 16397.148 | H2923: 5 | M2923: Foreign Securities | N2923: =SUMIFS(Actuals!$F:$F,Actuals!$A:$A,$A2923,Actuals!$D:$D,$D2923,Actuals!$B:$B,EDATE($B2923,-12)) -> 16240.95 | O2923: =AVERAGE(SUMIFS(Actuals!$F:$F,Actuals!$A:$A,$A2923,Actuals!$D:$D,$D2923,Actuals!$B:$B,EOMONTH(DATE(2025,$C2923-1,1),0))/SUMIFS(Actuals!$F:$F,Actuals!$A:$A,$A2923,Actuals!$D:$D,$D2923,Actuals!$B:$B,EOMONTH(DATE(2024,$C2923-1,1),0)), SUMIFS(Actuals!$F:$F,Actuals!$A:$A,$A2923,Actuals!$D:$D,$D2923,Actuals!$B:$B,EOMONTH(DATE(2025,$C2923-2,1),0))/SUMIFS(Actuals!$F:$F,Actuals!$A:$A,$A2923,Actuals!$D:$D,$D2923,Actuals!$B:$B,EOMONTH(DATE(2024,$C2923-2,1),0)), SUMIFS(Actuals!$F:$F,Actuals!$A:$A,$A2923,Actuals!$D:$D,$D2923,Actuals!$B:$B,EOMONTH(DATE(2025,$C2923-3,1),0))/SUMIFS(Actuals!$F:$F,Actuals!$A:$A,$A2923,Actuals!$D:$D,$D2923,Actuals!$B:$B,EOMONTH(DATE(2024,$C2923-3,1),0)) ) -> 1.0448705 | P2923: =N2923*O2923 -> 16969.69 | Q2923: =IFERROR(ABS(P2923-G2923)/ABS(G2923),"") | R2923: =IF(C2923<=8,"1 train date (May-Aug)","2 Test data (Sep-Nov)") -> 1 train date (May-Aug) | S2923: =1/(1+AVERAGEIFS($L:$L,$A:$A,$A2923,$R:$R,"1 train date (May-Aug)")) -> 1.1836764 | T2923: =F2923*S2923 -> 19408.917 | U2923: =IFERROR(ABS(T2923-G2923)/ABS(G2923),"")
A2924: 2370 | B2924: 46022 | C2924: 8 | D2924: 1 | E2924: Forecast | F2924: 15075 | H2924: 4 | M2924: Foreign Securities | N2924: =SUMIFS(Actuals!$F:$F,Actuals!$A:$A,$A2924,Actuals!$D:$D,$D2924,Actuals!$B:$B,EDATE($B2924,-12)) -> 16240.95 | O2924: =AVERAGE(SUMIFS(Actuals!$F:$F,Actuals!$A:$A,$A2924,Actuals!$D:$D,$D2924,Actuals!$B:$B,EOMONTH(DATE(2025,$C2924-1,1),0))/SUMIFS(Actuals!$F:$F,Actuals!$A:$A,$A2924,Actuals!$D:$D,$D2924,Actuals!$B:$B,EOMONTH(DATE(2024,$C2924-1,1),0)), SUMIFS(Actuals!$F:$F,Actuals!$A:$A,$A2924,Actuals!$D:$D,$D2924,Actuals!$B:$B,EOMONTH(DATE(2025,$C2924-2,1),0))/SUMIFS(Actuals!$F:$F,Actuals!$A:$A,$A2924,Actuals!$D:$D,$D2924,Actuals!$B:$B,EOMONTH(DATE(2024,$C2924-2,1),0)), SUMIFS(Actuals!$F:$F,Actuals!$A:$A,$A2924,Actuals!$D:$D,$D2924,Actuals!$B:$B,EOMONTH(DATE(2025,$C2924-3,1),0))/SUMIFS(Actuals!$F:$F,Actuals!$A:$A,$A2924,Actuals!$D:$D,$D2924,Actuals!$B:$B,EOMONTH(DATE(2024,$C2924-3,1),0)) ) -> 0.97250847 | P2924: =N2924*O2924 -> 15794.461 | Q2924: =IFERROR(ABS(P2924-G2924)/ABS(G2924),"") | R2924: =IF(C2924<=8,"1 train date (May-Aug)","2 Test data (Sep-Nov)") -> 1 train date (May-Aug) | S2924: =1/(1+AVERAGEIFS($L:$L,$A:$A,$A2924,$R:$R,"1 train date (May-Aug)")) -> 1.1836764 | T2924: =F2924*S2924 -> 17843.922 | U2924: =IFERROR(ABS(T2924-G2924)/ABS(G2924),"")
A2925: 2370 | B2925: 46022 | C2925: 9 | D2925: 1 | E2925: Forecast | F2925: 15761.571 | H2925: 3 | M2925: Foreign Securities | N2925: =SUMIFS(Actuals!$F:$F,Actuals!$A:$A,$A2925,Actuals!$D:$D,$D2925,Actuals!$B:$B,EDATE($B2925,-12)) -> 16240.95 | O2925: =AVERAGE(SUMIFS(Actuals!$F:$F,Actuals!$A:$A,$A2925,Actuals!$D:$D,$D2925,Actuals!$B:$B,EOMONTH(DATE(2025,$C2925-1,1),0))/SUMIFS(Actuals!$F:$F,Actuals!$A:$A,$A2925,Actuals!$D:$D,$D2925,Actuals!$B:$B,EOMONTH(DATE(2024,$C2925-1,1),0)), SUMIFS(Actuals!$F:$F,Actuals!$A:$A,$A2925,Actuals!$D:$D,$D2925,Actuals!$B:$B,EOMONTH(DATE(2025,$C2925-2,1),0))/SUMIFS(Actuals!$F:$F,Actuals!$A:$A,$A2925,Actuals!$D:$D,$D2925,Actuals!$B:$B,EOMONTH(DATE(2024,$C2925-2,1),0)), SUMIFS(Actuals!$F:$F,Actuals!$A:$A,$A2925,Actuals!$D:$D,$D2925,Actuals!$B:$B,EOMONTH(DATE(2025,$C2925-3,1),0))/SUMIFS(Actuals!$F:$F,Actuals!$A:$A,$A2925,Actuals!$D:$D,$D2925,Actuals!$B:$B,EOMONTH(DATE(2024,$C2925-3,1),0)) ) -> 1.0250893 | P2925: =N2925*O2925 -> 16648.424 | Q2925: =IFERROR(ABS(P2925-G2925)/ABS(G2925),"") | R2925: =IF(C2925<=8,"1 train date (May-Aug)","2 Test data (Sep-Nov)") -> 2 Test data (Sep-Nov) | S2925: =1/(1+AVERAGEIFS($L:$L,$A:$A,$A2925,$R:$R,"1 train date (May-Aug)")) -> 1.1836764 | T2925: =F2925*S2925 -> 18656.6 | U2925: =IFERROR(ABS(T2925-G2925)/ABS(G2925),"")
